Workbook
Name \0: #REF!
Name \C: #REF!
Name \E: #REF!
Name \F: #REF!
Name \I: #REF!
Name \J: #REF!
Name \M: #REF!
Name \N: #REF!
Name \p: #N/A
Name \pp: #REF!
Name \S: #REF!
Name \T: #REF!
Name \X: #REF!
Name \Z: #REF!
Name __material_he_tubes_alternative: #REF!
Name __sf400: #REF!
Name __sf404: #REF!
Name _1: #REF!
Name _1000A01: #N/A
Name _2: #REF!
Name _6: #REF!
Name _8: #REF!
Name _APP1: #REF!
Name _APP2: #REF!
Name _APP3: #REF!
Name _APP4: #REF!
Name _bal11: #REF!
Name _bal12: #REF!
Name _bal6: #REF!
Name _BTM150: #REF!
Name _BTM200: #REF!
Name _BTM50: #REF!
Name _BYE1: #REF!
Name _BYE2: #REF!
Name _BYE3: #REF!
Name _BYE4: #REF!
Name _C: #REF!
Name _CAL1: #REF!
Name _CAL2: #REF!
Name _CAL3: #REF!
Name _CAL4: #REF!
Name _CHK1: #REF!
Name _CHK2: #REF!
Name _CHK3: #REF!
Name _CHK4: #REF!
Name _CON1: #REF!
Name _CON2: #REF!
Name _cs805: #REF!
Name _DAT1: #REF!
Name _DAT2: #REF!
Name _DAT3: #REF!
Name _DAT4: #REF!
Name _DCS1: #REF!
Name _DCS2: #REF!
Name _ddn400: #REF!
Name _ddn600: #REF!
Name _DESIGN_MAT_SHELL: #REF!
Name _DESIGN_MAT_TUBES: #REF!
Name _DESIGN_TEMP_MAX_1: #REF!
Name _DESIGN_TEMP_MAX_2: #REF!

Sheet Chart1

Sheet MDR-Detailed Design-A10
B2: ENGINEERING, PROCUREMENT, CONSTRUCTION, AND INSTALLATION OF WELLHEAD PLATFORMS, ASSOCIATED PIPELINES AND BROWNFIELD MODIFICATIONS FOR ZAWTIKA DEVELOPMENT PROJECT PHASE 1F
B3: MASTER DOCUMENT REGISTER
C4: COMPANY: | D4: PTTEPI | AI4: Document No:
C5: CONTRACT NO.: | D5: MM25-5001 | AI5: Date:
C6: Project Field | D6: ZTK | AI6: Rev.: | BB6: PLAN | FT6: PLAN | KL6: PLAN
C7: Phase Code | D7: 1F | AP7: MM-ZTK-1F-GEN-PJM-MDR-0001 | AV7: =AZ7-7 -> 46269 | AZ7: 46276 | BB7: 2026 | CW7: 2027 | EX7: 2028 | FT7: 2026 | HO7: 2027 | JP7: 2028 | KL7: 2026 | MG7: 2027 | OH7: 2028
AP8: Updated on : | AR8: =AZ7 -> 46276 | AU8: Progress | BB8: =TEXT(BB10,"mmmm")&"-"&TEXT(BB10,"YYYY") -> February-2026 | BF8: =TEXT(BF10,"mmmm")&"-"&TEXT(BF10,"YYYY") -> March-2026 | BJ8: =TEXT(BK10,"mmmm")&"-"&TEXT(BK10,"YYYY") -> April-2026 | BN8: =TEXT(BO10,"mmmm")&"-"&TEXT(BO10,"YYYY") -> May-2026 | BS8: =TEXT(BT10,"mmmm")&"-"&TEXT(BT10,"YYYY") -> June-2026 | BW8: =TEXT(BX10,"mmmm")&"-"&TEXT(BX10,"YYYY") -> July-2026 | CB8: =TEXT(CB10,"mmmm")&"-"&TEXT(CB10,"YYYY") -> August-2026 | CF8: =TEXT(CG10,"mmmm")&"-"&TEXT(CG10,"YYYY") -> September-2026 | CJ8: =TEXT(CK10,"mmmm")&"-"&TEXT(CK10,"YYYY") -> October-2026 | CO8: =TEXT(CO10,"mmmm")&"-"&TEXT(CO10,"YYYY") -> November-2026 | CS8: =TEXT(CT10,"mmmm")&"-"&TEXT(CT10,"YYYY") -> December-2026 | CW8: =TEXT(CX10,"mmmm")&"-"&TEXT(CX10,"YYYY") -> January-2027 | DB8: =TEXT(DC10,"mmmm")&"-"&TEXT(DC10,"YYYY") -> February-2027 | DF8: =TEXT(DG10,"mmmm")&"-"&TEXT(DG10,"YYYY") -> March-2027 | DJ8: =TEXT(DK10,"mmmm")&"-"&TEXT(DK10,"YYYY") -> April-2027 | DO8: =TEXT(DO10,"mmmm")&"-"&TEXT(DO10,"YYYY") -> May-2027 | DS8: =TEXT(DT10,"mmmm")&"-"&TEXT(DT10,"YYYY") -> June-2027 | DW8: =TEXT(DX10,"mmmm")&"-"&TEXT(DX10,"YYYY") -> July-2027 | EB8: =TEXT(EB10,"mmmm")&"-"&TEXT(EB10,"YYYY") -> August-2027 | EF8: =TEXT(EG10,"mmmm")&"-"&TEXT(EG10,"YYYY") -> September-2027 | EJ8: =TEXT(EK10,"mmmm")&"-"&TEXT(EK10,"YYYY") -> October-2027 | EO8: =TEXT(EP10,"mmmm")&"-"&TEXT(EP10,"YYYY") -> November-2027 | ES8: =TEXT(ET10,"mmmm")&"-"&TEXT(ET10,"YYYY") -> December-2027 | EX8: =TEXT(EX10,"mmmm")&"-"&TEXT(EX10,"YYYY") -> January-2028 | FB8: =TEXT(FC10,"mmmm")&"-"&TEXT(FC10,"YYYY") -> February-2028 | FF8: =TEXT(FG10,"mmmm")&"-"&TEXT(FG10,"YYYY") -> March-2028 | FK8: =TEXT(FK10,"mmmm")&"-"&TEXT(FK10,"YYYY") -> April-2028 | FO8: =TEXT(FP10,"mmmm")&"-"&TEXT(FP10,"YYYY") -> May-2028 | FT8: =TEXT(FT10,"mmmm")&"-"&TEXT(FT10,"YYYY") -> February-2026 | FX8: =TEXT(FX10,"mmmm")&"-"&TEXT(FX10,"YYYY") -> March-2026 | GB8: =TEXT(GC10,"mmmm")&"-"&TEXT(GC10,"YYYY") -> April-2026 | GF8: =TEXT(GG10,"mmmm")&"-"&TEXT(GG10,"YYYY") -> May-2026 | GK8: =TEXT(GL10,"mmmm")&"-"&TEXT(GL10,"YYYY") -> June-2026 | GO8: =TEXT(GP10,"mmmm")&"-"&TEXT(GP10,"YYYY") -> July-2026 | GT8: =TEXT(GT10,"mmmm")&"-"&TEXT(GT10,"YYYY") -> August-2026 | GX8: =TEXT(GY10,"mmmm")&"-"&TEXT(GY10,"YYYY") -> September-2026 | HB8: =TEXT(HC10,"mmmm")&"-"&TEXT(HC10,"YYYY") -> October-2026 | HG8: =TEXT(HG10,"mmmm")&"-"&TEXT(HG10,"YYYY") -> November-2026 | HK8: =TEXT(HL10,"mmmm")&"-"&TEXT(HL10,"YYYY") -> December-2026 | HO8: =TEXT(HP10,"mmmm")&"-"&TEXT(HP10,"YYYY") -> January-2027 | HT8: =TEXT(HU10,"mmmm")&"-"&TEXT(HU10,"YYYY") -> February-2027 | HX8: =TEXT(HY10,"mmmm")&"-"&TEXT(HY10,"YYYY") -> March-2027 | IB8: =TEXT(IC10,"mmmm")&"-"&TEXT(IC10,"YYYY") -> April-2027 | IG8: =TEXT(IG10,"mmmm")&"-"&TEXT(IG10,"YYYY") -> May-2027 | IK8: =TEXT(IL10,"mmmm")&"-"&TEXT(IL10,"YYYY") -> June-2027 | IO8: =TEXT(IP10,"mmmm")&"-"&TEXT(IP10,"YYYY") -> July-2027 | IT8: =TEXT(IT10,"mmmm")&"-"&TEXT(IT10,"YYYY") -> August-2027 | IX8: =TEXT(IY10,"mmmm")&"-"&TEXT(IY10,"YYYY") -> September-2027 | JB8: =TEXT(JC10,"mmmm")&"-"&TEXT(JC10,"YYYY") -> October-2027 | JG8: =TEXT(JH10,"mmmm")&"-"&TEXT(JH10,"YYYY") -> November-2027 | JK8: =TEXT(JL10,"mmmm")&"-"&TEXT(JL10,"YYYY") -> December-2027 | JP8: =TEXT(JP10,"mmmm")&"-"&TEXT(JP10,"YYYY") -> January-2028 | JT8: =TEXT(JU10,"mmmm")&"-"&TEXT(JU10,"YYYY") -> February-2028 | JX8: =TEXT(JY10,"mmmm")&"-"&TEXT(JY10,"YYYY") -> March-2028 | KC8: =TEXT(KC10,"mmmm")&"-"&TEXT(KC10,"YYYY") -> April-2028 | KG8: =TEXT(KH10,"mmmm")&"-"&TEXT(KH10,"YYYY") -> May-2028 | KL8: =TEXT(KL10,"mmmm")&"-"&TEXT(KL10,"YYYY") -> February-2026 | KP8: =TEXT(KP10,"mmmm")&"-"&TEXT(KP10,"YYYY") -> March-2026 | KT8: =TEXT(KU10,"mmmm")&"-"&TEXT(KU10,"YYYY") -> April-2026 | KX8: =TEXT(KY10,"mmmm")&"-"&TEXT(KY10,"YYYY") -> May-2026 | LC8: =TEXT(LD10,"mmmm")&"-"&TEXT(LD10,"YYYY") -> June-2026 | LG8: =TEXT(LH10,"mmmm")&"-"&TEXT(LH10,"YYYY") -> July-2026 | LL8: =TEXT(LL10,"mmmm")&"-"&TEXT(LL10,"YYYY") -> August-2026 | LP8: =TEXT(LQ10,"mmmm")&"-"&TEXT(LQ10,"YYYY") -> September-2026 | LT8: =TEXT(LU10,"mmmm")&"-"&TEXT(LU10,"YYYY") -> October-2026 | LY8: =TEXT(LY10,"mmmm")&"-"&TEXT(LY10,"YYYY") -> November-2026 | MC8: =TEXT(MD10,"mmmm")&"-"&TEXT(MD10,"YYYY") -> December-2026 | MG8: =TEXT(MH10,"mmmm")&"-"&TEXT(MH10,"YYYY") -> January-2027 | ML8: =TEXT(MM10,"mmmm")&"-"&TEXT(MM10,"YYYY") -> February-2027 | MP8: =TEXT(MQ10,"mmmm")&"-"&TEXT(MQ10,"YYYY") -> March-2027 | MT8: =TEXT(MU10,"mmmm")&"-"&TEXT(MU10,"YYYY") -> April-2027 | MY8: =TEXT(MY10,"mmmm")&"-"&TEXT(MY10,"YYYY") -> May-2027 | NC8: =TEXT(ND10,"mmmm")&"-"&TEXT(ND10,"YYYY") -> June-2027 | NG8: =TEXT(NH10,"mmmm")&"-"&TEXT(NH10,"YYYY") -> July-2027 | NL8: =TEXT(NL10,"mmmm")&"-"&TEXT(NL10,"YYYY") -> August-2027 | NP8: =TEXT(NQ10,"mmmm")&"-"&TEXT(NQ10,"YYYY") -> September-2027 | NT8: =TEXT(NU10,"mmmm")&"-"&TEXT(NU10,"YYYY") -> October-2027 | NY8: =TEXT(NZ10,"mmmm")&"-"&TEXT(NZ10,"YYYY") -> November-2027 | OC8: =TEXT(OD10,"mmmm")&"-"&TEXT(OD10,"YYYY") -> December-2027 | OH8: =TEXT(OH10,"mmmm")&"-"&TEXT(OH10,"YYYY") -> January-2028 | OL8: =TEXT(OM10,"mmmm")&"-"&TEXT(OM10,"YYYY") -> February-2028 | OP8: =TEXT(OQ10,"mmmm")&"-"&TEXT(OQ10,"YYYY") -> March-2028 | OU8: =TEXT(OU10,"mmmm")&"-"&TEXT(OU10,"YYYY") -> April-2028 | OY8: =TEXT(OZ10,"mmmm")&"-"&TEXT(OZ10,"YYYY") -> May-2028
M9: IDC | Q9: IFR | Z9: IFA | AI9: AFC | AP9: AP | AS9: Qty | AT9: % | AU9: Cummulative Last Week | AX9: Cummulative This Week | BB9: =TEXT(BB10,"dd") -> 06 | BC9: =TEXT(BC10,"dd") -> 13 | BD9: =TEXT(BD10,"dd") -> 20 | BE9: =TEXT(BE10,"dd") -> 27 | BF9: =TEXT(BF10,"dd") -> 06 | BG9: =TEXT(BG10,"dd") -> 13 | BH9: =TEXT(BH10,"dd") -> 20 | BI9: =TEXT(BI10,"dd") -> 27 | ... FR9: =TEXT(FR10,"dd") -> 26 | FT9: =TEXT(FT10,"dd") -> 06 | FU9: =TEXT(FU10,"dd") -> 13 | FV9: =TEXT(FV10,"dd") -> 20 | FW9: =TEXT(FW10,"dd") -> 27 | FX9: =TEXT(FX10,"dd") -> 06 | FY9: =TEXT(FY10,"dd") -> 13 | FZ9: =TEXT(FZ10,"dd") -> 20 | GA9: =TEXT(GA10,"dd") -> 27 | ... KJ9: =TEXT(KJ10,"dd") -> 26 | KL9: =TEXT(KL10,"dd") -> 06 | KM9: =TEXT(KM10,"dd") -> 13 | KN9: =TEXT(KN10,"dd") -> 20 | KO9: =TEXT(KO10,"dd") -> 27 | KP9: =TEXT(KP10,"dd") -> 06 | KQ9: =TEXT(KQ10,"dd") -> 13 | KR9: =TEXT(KR10,"dd") -> 20 | KS9: =TEXT(KS10,"dd") -> 27 | ... PB9: =TEXT(PB10,"dd") -> 26
B10: No. | C10: Area | D10: Disc | E10: Type | F10: Seq.no | G10: Format | I10: Document No. | J10: Document Title | K10: Class | L10: Remarks | M10: REV | N10: Issue To TJE | O10: TJE Return Comment | P10: CRS submission Date | Q10: REV | R10: Issue To TJE | S10: TJE Return Comment | T10: Re-Issue To TJE | U10: PLAN | V10: ACTUAL | W10: Forecast | X10: PTTEPI Return Comment | Y10: CRS submission Date | Z10: REV | AA10: Issue To TJE | AB10: TJE Return Comment | AC10: Re-Issue To TJE | AD10: PLAN | AE10: ACTUAL | AF10: Forecast | AG10: PTTEPI Return Comment | AH10: CRS submission Date | AI10: REV | AJ10: Issue To TJE | AK10: PLAN | AL10: ACTUAL | AM10: PTTEPI return | AN10: Forecast | AO10: Forecast | AP10: PLAN | AQ10: ACTUAL | AR10: Forecast | AU10: Plan | AV10: Actual | AW10: Deviation | AX10: Plan | AY10: Actual | AZ10: Deviation | BB10: 46059 | BC10: =BB10+7 -> 46066 | BD10: =BC10+7 -> 46073 | BE10: =BD10+7 -> 46080 | BF10: =BE10+7 -> 46087 | BG10: =BF10+7 -> 46094 | BH10: =BG10+7 -> 46101 | BI10: =BH10+7 -> 46108 | BJ10: =BI10+7 -> 46115 | ... FR10: =FQ10+7 -> 46899 | FT10: 46059 | FU10: =FT10+7 -> 46066 | FV10: =FU10+7 -> 46073 | FW10: =FV10+7 -> 46080 | FX10: =FW10+7 -> 46087 | FY10: =FX10+7 -> 46094 | FZ10: =FY10+7 -> 46101 | GA10: =FZ10+7 -> 46108 | GB10: =GA10+7 -> 46115 | ... KJ10: =KI10+7 -> 46899 | KL10: 46059 | KM10: =KL10+7 -> 46066 | KN10: =KM10+7 -> 46073 | KO10: =KN10+7 -> 46080 | KP10: =KO10+7 -> 46087 | KQ10: =KP10+7 -> 46094 | KR10: =KQ10+7 -> 46101 | KS10: =KR10+7 -> 46108 | KT10: =KS10+7 -> 46115 | ... PB10: =PA10+7 -> 46899 | PD10: IFR | PF10: IFA | PH10: IFC | PJ10: APP
A11: 1 | B11: Engineering - Pipeline Detailed Design | U11: 0.5 | AD11: 0.2 | AK11: 0.1 | AP11: 0.2 | AS11: =SUM(AS12:AS213) -> 122
A12: 2 | B12: General
A13: 3 | B13: Basis of Design
A14: 4 | B14: 1 | C14: IPX | D14: PLR | E14: BOD | F14: 9001 | G14: docx | I14: =CONCATENATE("MM-",$D$6,"-",$D$7,"-",C14,"-",D14,"-",E14,"-",F14) -> MM-ZTK-1F-IPX-PLR-BOD-9001 | J14: Pipeline and Riser Design Basis and Design Criteria | M14: R1 | N14: =VLOOKUP(I14,'MS Project'!$B$6:$F$189,5,FALSE) -> 46123 | O14: =N14+7 -> 46130 | P14: =O14+3 -> 46133 | Q14: A1 | R14: =P14+2 -> 46135 | S14: =R14+2 -> 46137 | T14: =S14+3 -> 46140 | U14: =T14+1 -> 46141 | V14: 46141 | W14: =V14 -> 46141 | X14: =U14+14 -> 46155 | Y14: =X14+2 -> 46157 | Z14: B1 | AA14: =Y14+4 -> 46161 | AB14: =AA14+3 -> 46164 | AC14: =AB14+4 -> 46168 | AD14: =AC14+1 -> 46169 | AE14: 46192 | AF14: =AE14 -> 46192 | AG14: =AD14+14 -> 46183 | AH14: =AG14+2 -> 46185 | AI14: C1 | AJ14: =AH14+4 -> 46189 | AK14: =AJ14+1 -> 46190 | AL14: 46223 | AM14: =AK14+14 -> 46204 | AO14: =AF14+14 -> 46206 | AP14: =AM14 -> 46204 | AR14: =AP14 -> 46204 | AS14: 1 | AT14: =AS14/$AS$11 -> 0.0081967213 | AU14: =IF($U14>0,IF($U14<=$AV$7,$AT14*$U$11,0))+IF($AD14>0,IF($AD14<=$AV$7,$AT14*$AD$11,0))+IF($AK14>0,IF($AK14<=$AV$7,$AT14*$AK$11,0))+IF($AP14>0,IF($AP14<=$AV$7,$AT14*$AP$11,0)) -> 0.0081967213 | AV14: =IF($V14>0,IF($V14<=$AV$7,$AT14*$U$11,0))+IF($AE14>0,IF($AE14<=$AV$7,$AT14*$AD$11,0))+IF($AL14>0,IF($AL14<=$AV$7,$AT14*$AK$11,0))+IF($AQ14>0,IF($AQ14<=$AV$7,$AT14*$AP$11,0)) -> 0.006557377 | AW14: =AV14-AU14 -> -0.0016393443 | AX14: =IF($U14>0,IF($U14<=$AZ$7,$AT14*$U$11,0))+IF($AD14>0,IF($AD14<=$AZ$7,$AT14*$AD$11,0))+IF($AK14>0,IF($AK14<=$AZ$7,$AT14*$AK$11,0))+IF($AP14>0,IF($AP14<=$AZ$7,$AT14*$AP$11,0)) -> 0.0081967213 | AY14: =IF($V14>0,IF($V14<=$AZ$7,$AT14*$U$11,0))+IF($AE14>0,IF($AE14<=$AZ$7,$AT14*$AD$11,0))+IF($AL14>0,IF($AL14<=$AZ$7,$AT14*$AK$11,0))+IF($AQ14>0,IF($AQ14<=$AZ$7,$AT14*$AP$11,0)) -> 0.006557377 | AZ14: =AY14-AX14 -> -0.0016393443 | BB14: =IF(AND($U14>BA$10,$U14<=BB$10),$AT14*$U$11,0)+IF(AND($AD14>BA$10,$AD14<=BB$10),$AT14*$AD$11,0)+IF(AND($AK14>BA$10,$AK14<=BB$10),$AT14*$AK$11,0)+IF(AND($AP14>BA$10,$AP14<=BB$10),$AT14*$AP$11,0) -> 0 | BC14: =IF(AND($U14>BB$10,$U14<=BC$10),$AT14*$U$11,0)+IF(AND($AD14>BB$10,$AD14<=BC$10),$AT14*$AD$11,0)+IF(AND($AK14>BB$10,$AK14<=BC$10),$AT14*$AK$11,0)+IF(AND($AP14>BB$10,$AP14<=BC$10),$AT14*$AP$11,0) -> 0 | BD14: =IF(AND($U14>BC$10,$U14<=BD$10),$AT14*$U$11,0)+IF(AND($AD14>BC$10,$AD14<=BD$10),$AT14*$AD$11,0)+IF(AND($AK14>BC$10,$AK14<=BD$10),$AT14*$AK$11,0)+IF(AND($AP14>BC$10,$AP14<=BD$10),$AT14*$AP$11,0) -> 0 | BE14: =IF(AND($U14>BD$10,$U14<=BE$10),$AT14*$U$11,0)+IF(AND($AD14>BD$10,$AD14<=BE$10),$AT14*$AD$11,0)+IF(AND($AK14>BD$10,$AK14<=BE$10),$AT14*$AK$11,0)+IF(AND($AP14>BD$10,$AP14<=BE$10),$AT14*$AP$11,0) -> 0 | BF14: =IF(AND($U14>BE$10,$U14<=BF$10),$AT14*$U$11,0)+IF(AND($AD14>BE$10,$AD14<=BF$10),$AT14*$AD$11,0)+IF(AND($AK14>BE$10,$AK14<=BF$10),$AT14*$AK$11,0)+IF(AND($AP14>BE$10,$AP14<=BF$10),$AT14*$AP$11,0) -> 0 | BG14: =IF(AND($U14>BF$10,$U14<=BG$10),$AT14*$U$11,0)+IF(AND($AD14>BF$10,$AD14<=BG$10),$AT14*$AD$11,0)+IF(AND($AK14>BF$10,$AK14<=BG$10),$AT14*$AK$11,0)+IF(AND($AP14>BF$10,$AP14<=BG$10),$AT14*$AP$11,0) -> 0 | BH14: =IF(AND($U14>BG$10,$U14<=BH$10),$AT14*$U$11,0)+IF(AND($AD14>BG$10,$AD14<=BH$10),$AT14*$AD$11,0)+IF(AND($AK14>BG$10,$AK14<=BH$10),$AT14*$AK$11,0)+IF(AND($AP14>BG$10,$AP14<=BH$10),$AT14*$AP$11,0) -> 0 | BI14: =IF(AND($U14>BH$10,$U14<=BI$10),$AT14*$U$11,0)+IF(AND($AD14>BH$10,$AD14<=BI$10),$AT14*$AD$11,0)+IF(AND($AK14>BH$10,$AK14<=BI$10),$AT14*$AK$11,0)+IF(AND($AP14>BH$10,$AP14<=BI$10),$AT14*$AP$11,0) -> 0 | ... FR14: =IF(AND($U14>FQ$10,$U14<=FR$10),$AT14*$U$11,0)+IF(AND($AD14>FQ$10,$AD14<=FR$10),$AT14*$AD$11,0)+IF(AND($AK14>FQ$10,$AK14<=FR$10),$AT14*$AK$11,0)+IF(AND($AP14>FQ$10,$AP14<=FR$10),$AT14*$AP$11,0) -> 0 | FT14: =IF(AND($V14>FS$10,$V14<=FT$10),$AT14*$U$11,0)+IF(AND($AE14>FS$10,$AE14<=FT$10),$AT14*$AD$11,0)+IF(AND($AL14>FS$10,$AL14<=FT$10),$AT14*$AK$11,0)+IF(AND($AQ14>FS$10,$AQ14<=FT$10),$AT14*$AP$11,0) -> 0 | FU14: =IF(AND($V14>FT$10,$V14<=FU$10),$AT14*$U$11,0)+IF(AND($AE14>FT$10,$AE14<=FU$10),$AT14*$AD$11,0)+IF(AND($AL14>FT$10,$AL14<=FU$10),$AT14*$AK$11,0)+IF(AND($AQ14>FT$10,$AQ14<=FU$10),$AT14*$AP$11,0) -> 0 | FV14: =IF(AND($V14>FU$10,$V14<=FV$10),$AT14*$U$11,0)+IF(AND($AE14>FU$10,$AE14<=FV$10),$AT14*$AD$11,0)+IF(AND($AL14>FU$10,$AL14<=FV$10),$AT14*$AK$11,0)+IF(AND($AQ14>FU$10,$AQ14<=FV$10),$AT14*$AP$11,0) -> 0 | FW14: =IF(AND($V14>FV$10,$V14<=FW$10),$AT14*$U$11,0)+IF(AND($AE14>FV$10,$AE14<=FW$10),$AT14*$AD$11,0)+IF(AND($AL14>FV$10,$AL14<=FW$10),$AT14*$AK$11,0)+IF(AND($AQ14>FV$10,$AQ14<=FW$10),$AT14*$AP$11,0) -> 0 | FX14: =IF(AND($V14>FW$10,$V14<=FX$10),$AT14*$U$11,0)+IF(AND($AE14>FW$10,$AE14<=FX$10),$AT14*$AD$11,0)+IF(AND($AL14>FW$10,$AL14<=FX$10),$AT14*$AK$11,0)+IF(AND($AQ14>FW$10,$AQ14<=FX$10),$AT14*$AP$11,0) -> 0 | FY14: =IF(AND($V14>FX$10,$V14<=FY$10),$AT14*$U$11,0)+IF(AND($AE14>FX$10,$AE14<=FY$10),$AT14*$AD$11,0)+IF(AND($AL14>FX$10,$AL14<=FY$10),$AT14*$AK$11,0)+IF(AND($AQ14>FX$10,$AQ14<=FY$10),$AT14*$AP$11,0) -> 0 | FZ14: =IF(AND($V14>FY$10,$V14<=FZ$10),$AT14*$U$11,0)+IF(AND($AE14>FY$10,$AE14<=FZ$10),$AT14*$AD$11,0)+IF(AND($AL14>FY$10,$AL14<=FZ$10),$AT14*$AK$11,0)+IF(AND($AQ14>FY$10,$AQ14<=FZ$10),$AT14*$AP$11,0) -> 0 | GA14: =IF(AND($V14>FZ$10,$V14<=GA$10),$AT14*$U$11,0)+IF(AND($AE14>FZ$10,$AE14<=GA$10),$AT14*$AD$11,0)+IF(AND($AL14>FZ$10,$AL14<=GA$10),$AT14*$AK$11,0)+IF(AND($AQ14>FZ$10,$AQ14<=GA$10),$AT14*$AP$11,0) -> 0 | ... KB14: =IF(AND($V14>KA$10,$V14<=KB$10),$AT14*$U$11,0)+IF(AND($AE14>KA$10,$AE14<=KB$10),$AT14*$AD$11,0)+IF(AND($AL14>KA$10,$AL14<=KB$10),$AT14*$AK$11,0)+IF(AND($AQ14>KA$10,$AQ14<=KB$10),$AT14*$AP$11,0) -> 0 | KC14: =IF(AND($U14>KB$10,$U14<=KC$10),$AT14*$U$11,0)+IF(AND($AD14>KB$10,$AD14<=KC$10),$AT14*$AD$11,0)+IF(AND($AK14>KB$10,$AK14<=KC$10),$AT14*$AK$11,0)+IF(AND($AP14>KB$10,$AP14<=KC$10),$AT14*$AP$11,0) -> 0 | KD14: =IF(AND($U14>KC$10,$U14<=KD$10),$AT14*$U$11,0)+IF(AND($AD14>KC$10,$AD14<=KD$10),$AT14*$AD$11,0)+IF(AND($AK14>KC$10,$AK14<=KD$10),$AT14*$AK$11,0)+IF(AND($AP14>KC$10,$AP14<=KD$10),$AT14*$AP$11,0) -> 0 | KE14: =IF(AND($U14>KD$10,$U14<=KE$10),$AT14*$U$11,0)+IF(AND($AD14>KD$10,$AD14<=KE$10),$AT14*$AD$11,0)+IF(AND($AK14>KD$10,$AK14<=KE$10),$AT14*$AK$11,0)+IF(AND($AP14>KD$10,$AP14<=KE$10),$AT14*$AP$11,0) -> 0 | KF14: =IF(AND($U14>KE$10,$U14<=KF$10),$AT14*$U$11,0)+IF(AND($AD14>KE$10,$AD14<=KF$10),$AT14*$AD$11,0)+IF(AND($AK14>KE$10,$AK14<=KF$10),$AT14*$AK$11,0)+IF(AND($AP14>KE$10,$AP14<=KF$10),$AT14*$AP$11,0) -> 0 | KG14: =IF(AND($U14>KF$10,$U14<=KG$10),$AT14*$U$11,0)+IF(AND($AD14>KF$10,$AD14<=KG$10),$AT14*$AD$11,0)+IF(AND($AK14>KF$10,$AK14<=KG$10),$AT14*$AK$11,0)+IF(AND($AP14>KF$10,$AP14<=KG$10),$AT14*$AP$11,0) -> 0 | KH14: =IF(AND($U14>KG$10,$U14<=KH$10),$AT14*$U$11,0)+IF(AND($AD14>KG$10,$AD14<=KH$10),$AT14*$AD$11,0)+IF(AND($AK14>KG$10,$AK14<=KH$10),$AT14*$AK$11,0)+IF(AND($AP14>KG$10,$AP14<=KH$10),$AT14*$AP$11,0) -> 0 | KI14: =IF(AND($U14>KH$10,$U14<=KI$10),$AT14*$U$11,0)+IF(AND($AD14>KH$10,$AD14<=KI$10),$AT14*$AD$11,0)+IF(AND($AK14>KH$10,$AK14<=KI$10),$AT14*$AK$11,0)+IF(AND($AP14>KH$10,$AP14<=KI$10),$AT14*$AP$11,0) -> 0 | KJ14: =IF(AND($U14>KI$10,$U14<=KJ$10),$AT14*$U$11,0)+IF(AND($AD14>KI$10,$AD14<=KJ$10),$AT14*$AD$11,0)+IF(AND($AK14>KI$10,$AK14<=KJ$10),$AT14*$AK$11,0)+IF(AND($AP14>KI$10,$AP14<=KJ$10),$AT14*$AP$11,0) -> 0 | KL14: =IF(AND($W14>KK$10,$W14<=KL$10),$AT14*$U$11,0)+IF(AND($AF14>KK$10,$AF14<=KL$10),$AT14*$AD$11,0)+IF(AND($AO14>KK$10,$AO14<=KL$10),$AT14*$AK$11,0)+IF(AND($AR14>KK$10,$AR14<=KL$10),$AT14*$AP$11,0) -> 0 | KM14: =IF(AND($W14>KL$10,$W14<=KM$10),$AT14*$U$11,0)+IF(AND($AF14>KL$10,$AF14<=KM$10),$AT14*$AD$11,0)+IF(AND($AO14>KL$10,$AO14<=KM$10),$AT14*$AK$11,0)+IF(AND($AR14>KL$10,$AR14<=KM$10),$AT14*$AP$11,0) -> 0 | KN14: =IF(AND($W14>KM$10,$W14<=KN$10),$AT14*$U$11,0)+IF(AND($AF14>KM$10,$AF14<=KN$10),$AT14*$AD$11,0)+IF(AND($AO14>KM$10,$AO14<=KN$10),$AT14*$AK$11,0)+IF(AND($AR14>KM$10,$AR14<=KN$10),$AT14*$AP$11,0) -> 0 | KO14: =IF(AND($W14>KN$10,$W14<=KO$10),$AT14*$U$11,0)+IF(AND($AF14>KN$10,$AF14<=KO$10),$AT14*$AD$11,0)+IF(AND($AO14>KN$10,$AO14<=KO$10),$AT14*$AK$11,0)+IF(AND($AR14>KN$10,$AR14<=KO$10),$AT14*$AP$11,0) -> 0 | KP14: =IF(AND($W14>KO$10,$W14<=KP$10),$AT14*$U$11,0)+IF(AND($AF14>KO$10,$AF14<=KP$10),$AT14*$AD$11,0)+IF(AND($AO14>KO$10,$AO14<=KP$10),$AT14*$AK$11,0)+IF(AND($AR14>KO$10,$AR14<=KP$10),$AT14*$AP$11,0) -> 0 | KQ14: =IF(AND($W14>KP$10,$W14<=KQ$10),$AT14*$U$11,0)+IF(AND($AF14>KP$10,$AF14<=KQ$10),$AT14*$AD$11,0)+IF(AND($AO14>KP$10,$AO14<=KQ$10),$AT14*$AK$11,0)+IF(AND($AR14>KP$10,$AR14<=KQ$10),$AT14*$AP$11,0) -> 0 | KR14: =IF(AND($W14>KQ$10,$W14<=KR$10),$AT14*$U$11,0)+IF(AND($AF14>KQ$10,$AF14<=KR$10),$AT14*$AD$11,0)+IF(AND($AO14>KQ$10,$AO14<=KR$10),$AT14*$AK$11,0)+IF(AND($AR14>KQ$10,$AR14<=KR$10),$AT14*$AP$11,0) -> 0 | KS14: =IF(AND($W14>KR$10,$W14<=KS$10),$AT14*$U$11,0)+IF(AND($AF14>KR$10,$AF14<=KS$10),$AT14*$AD$11,0)+IF(AND($AO14>KR$10,$AO14<=KS$10),$AT14*$AK$11,0)+IF(AND($AR14>KR$10,$AR14<=KS$10),$AT14*$AP$11,0) -> 0 | ... PB14: =IF(AND($W14>PA$10,$W14<=PB$10),$AT14*$U$11,0)+IF(AND($AF14>PA$10,$AF14<=PB$10),$AT14*$AD$11,0)+IF(AND($AO14>PA$10,$AO14<=PB$10),$AT14*$AK$11,0)+IF(AND($AR14>PA$10,$AR14<=PB$10),$AT14*$AP$11,0) -> 0 | PD14: =VLOOKUP($I14,[1]IFR!$B$10:$AQ$1616,1,0) -> MM-ZTK-1F-IPX-PLR-BOD-9001 | PE14: =INT(VLOOKUP($I14,[1]IFR!$B$10:$AQ$1616,20,0)) -> 46141 | PF14: =VLOOKUP($I14,[1]IFA!$B$10:$AQ$694,1,0) -> MM-ZTK-1F-IPX-PLR-BOD-9001 | PG14: =INT(VLOOKUP($I14,[1]IFA!$B$10:$AQ$694,20,0)) -> 46192 | PH14: =VLOOKUP($I14,[1]IFC!$B$10:$AQ$702,1,0) -> MM-ZTK-1F-IPX-PLR-BOD-9001 | PI14: =INT(VLOOKUP($I14,[1]IFC!$B$10:$AQ$702,20,0)) -> 46223 | PJ14: =VLOOKUP($I14,[1]IFC!$B$10:$AQ$702,17,0) -> AFC | PK14: =VLOOKUP($I14,[1]IFC!$B$10:$AQ$702,33,0) -> Approved with Comment | PL14: =VLOOKUP($I14,[1]IFC!$B$10:$AQ$702,32,0) -> AWC | PM14: =INT(VLOOKUP($I14,[1]IFC!$B$10:$AQ$702,37,0)) -> 46230
A15: 5 | B15: =B14+1 -> 2 | C15: IPX | D15: PLR | E15: BOD | F15: 9002 | G15: docx | I15: =CONCATENATE("MM-",$D$6,"-",$D$7,"-",C15,"-",D15,"-",E15,"-",F15) -> MM-ZTK-1F-IPX-PLR-BOD-9002 | J15: Seismic Consideration for Subsea Pipeline in Seismic Hazardous Area | M15: R1 | N15: =VLOOKUP(I15,'MS Project'!$B$6:$F$189,5,FALSE) -> 46123 | O15: =N15+7 -> 46130 | P15: =O15+3 -> 46133 | Q15: A1 | R15: =P15+2 -> 46135 | S15: =R15+2 -> 46137 | T15: =S15+3 -> 46140 | U15: =T15+1 -> 46141 | V15: 46141 | W15: =V15 -> 46141 | X15: =U15+14 -> 46155 | Y15: =X15+2 -> 46157 | Z15: B1 | AA15: =Y15+4 -> 46161 | AB15: =AA15+3 -> 46164 | AC15: =AB15+4 -> 46168 | AD15: =AC15+1 -> 46169 | AE15: 46199 | AF15: =AE15 -> 46199 | AG15: =AD15+14 -> 46183 | AH15: =AG15+2 -> 46185 | AI15: C1 | AJ15: =AH15+4 -> 46189 | AK15: =AJ15+1 -> 46190 | AL15: 46226 | AM15: =AK15+14 -> 46204 | AO15: =AF15+14 -> 46213 | AP15: =AM15 -> 46204 | AQ15: 46227 | AR15: =AP15 -> 46204 | AS15: 1 | AT15: =AS15/$AS$11 -> 0.0081967213 | AU15: =IF($U15>0,IF($U15<=$AV$7,$AT15*$U$11,0))+IF($AD15>0,IF($AD15<=$AV$7,$AT15*$AD$11,0))+IF($AK15>0,IF($AK15<=$AV$7,$AT15*$AK$11,0))+IF($AP15>0,IF($AP15<=$AV$7,$AT15*$AP$11,0)) -> 0.0081967213 | AV15: =IF($V15>0,IF($V15<=$AV$7,$AT15*$U$11,0))+IF($AE15>0,IF($AE15<=$AV$7,$AT15*$AD$11,0))+IF($AL15>0,IF($AL15<=$AV$7,$AT15*$AK$11,0))+IF($AQ15>0,IF($AQ15<=$AV$7,$AT15*$AP$11,0)) -> 0.0081967213 | AW15: =AV15-AU15 -> 0 | AX15: =IF($U15>0,IF($U15<=$AZ$7,$AT15*$U$11,0))+IF($AD15>0,IF($AD15<=$AZ$7,$AT15*$AD$11,0))+IF($AK15>0,IF($AK15<=$AZ$7,$AT15*$AK$11,0))+IF($AP15>0,IF($AP15<=$AZ$7,$AT15*$AP$11,0)) -> 0.0081967213 | AY15: =IF($V15>0,IF($V15<=$AZ$7,$AT15*$U$11,0))+IF($AE15>0,IF($AE15<=$AZ$7,$AT15*$AD$11,0))+IF($AL15>0,IF($AL15<=$AZ$7,$AT15*$AK$11,0))+IF($AQ15>0,IF($AQ15<=$AZ$7,$AT15*$AP$11,0)) -> 0.0081967213 | AZ15: =AY15-AX15 -> 0 | BB15: =IF(AND($U15>BA$10,$U15<=BB$10),$AT15*$U$11,0)+IF(AND($AD15>BA$10,$AD15<=BB$10),$AT15*$AD$11,0)+IF(AND($AK15>BA$10,$AK15<=BB$10),$AT15*$AK$11,0)+IF(AND($AP15>BA$10,$AP15<=BB$10),$AT15*$AP$11,0) -> 0 | BC15: =IF(AND($U15>BB$10,$U15<=BC$10),$AT15*$U$11,0)+IF(AND($AD15>BB$10,$AD15<=BC$10),$AT15*$AD$11,0)+IF(AND($AK15>BB$10,$AK15<=BC$10),$AT15*$AK$11,0)+IF(AND($AP15>BB$10,$AP15<=BC$10),$AT15*$AP$11,0) -> 0 | BD15: =IF(AND($U15>BC$10,$U15<=BD$10),$AT15*$U$11,0)+IF(AND($AD15>BC$10,$AD15<=BD$10),$AT15*$AD$11,0)+IF(AND($AK15>BC$10,$AK15<=BD$10),$AT15*$AK$11,0)+IF(AND($AP15>BC$10,$AP15<=BD$10),$AT15*$AP$11,0) -> 0 | BE15: =IF(AND($U15>BD$10,$U15<=BE$10),$AT15*$U$11,0)+IF(AND($AD15>BD$10,$AD15<=BE$10),$AT15*$AD$11,0)+IF(AND($AK15>BD$10,$AK15<=BE$10),$AT15*$AK$11,0)+IF(AND($AP15>BD$10,$AP15<=BE$10),$AT15*$AP$11,0) -> 0 | BF15: =IF(AND($U15>BE$10,$U15<=BF$10),$AT15*$U$11,0)+IF(AND($AD15>BE$10,$AD15<=BF$10),$AT15*$AD$11,0)+IF(AND($AK15>BE$10,$AK15<=BF$10),$AT15*$AK$11,0)+IF(AND($AP15>BE$10,$AP15<=BF$10),$AT15*$AP$11,0) -> 0 | BG15: =IF(AND($U15>BF$10,$U15<=BG$10),$AT15*$U$11,0)+IF(AND($AD15>BF$10,$AD15<=BG$10),$AT15*$AD$11,0)+IF(AND($AK15>BF$10,$AK15<=BG$10),$AT15*$AK$11,0)+IF(AND($AP15>BF$10,$AP15<=BG$10),$AT15*$AP$11,0) -> 0 | BH15: =IF(AND($U15>BG$10,$U15<=BH$10),$AT15*$U$11,0)+IF(AND($AD15>BG$10,$AD15<=BH$10),$AT15*$AD$11,0)+IF(AND($AK15>BG$10,$AK15<=BH$10),$AT15*$AK$11,0)+IF(AND($AP15>BG$10,$AP15<=BH$10),$AT15*$AP$11,0) -> 0 | BI15: =IF(AND($U15>BH$10,$U15<=BI$10),$AT15*$U$11,0)+IF(AND($AD15>BH$10,$AD15<=BI$10),$AT15*$AD$11,0)+IF(AND($AK15>BH$10,$AK15<=BI$10),$AT15*$AK$11,0)+IF(AND($AP15>BH$10,$AP15<=BI$10),$AT15*$AP$11,0) -> 0 | ... FR15: =IF(AND($U15>FQ$10,$U15<=FR$10),$AT15*$U$11,0)+IF(AND($AD15>FQ$10,$AD15<=FR$10),$AT15*$AD$11,0)+IF(AND($AK15>FQ$10,$AK15<=FR$10),$AT15*$AK$11,0)+IF(AND($AP15>FQ$10,$AP15<=FR$10),$AT15*$AP$11,0) -> 0 | FT15: =IF(AND($V15>FS$10,$V15<=FT$10),$AT15*$U$11,0)+IF(AND($AE15>FS$10,$AE15<=FT$10),$AT15*$AD$11,0)+IF(AND($AL15>FS$10,$AL15<=FT$10),$AT15*$AK$11,0)+IF(AND($AQ15>FS$10,$AQ15<=FT$10),$AT15*$AP$11,0) -> 0 | FU15: =IF(AND($V15>FT$10,$V15<=FU$10),$AT15*$U$11,0)+IF(AND($AE15>FT$10,$AE15<=FU$10),$AT15*$AD$11,0)+IF(AND($AL15>FT$10,$AL15<=FU$10),$AT15*$AK$11,0)+IF(AND($AQ15>FT$10,$AQ15<=FU$10),$AT15*$AP$11,0) -> 0 | FV15: =IF(AND($V15>FU$10,$V15<=FV$10),$AT15*$U$11,0)+IF(AND($AE15>FU$10,$AE15<=FV$10),$AT15*$AD$11,0)+IF(AND($AL15>FU$10,$AL15<=FV$10),$AT15*$AK$11,0)+IF(AND($AQ15>FU$10,$AQ15<=FV$10),$AT15*$AP$11,0) -> 0 | FW15: =IF(AND($V15>FV$10,$V15<=FW$10),$AT15*$U$11,0)+IF(AND($AE15>FV$10,$AE15<=FW$10),$AT15*$AD$11,0)+IF(AND($AL15>FV$10,$AL15<=FW$10),$AT15*$AK$11,0)+IF(AND($AQ15>FV$10,$AQ15<=FW$10),$AT15*$AP$11,0) -> 0 | FX15: =IF(AND($V15>FW$10,$V15<=FX$10),$AT15*$U$11,0)+IF(AND($AE15>FW$10,$AE15<=FX$10),$AT15*$AD$11,0)+IF(AND($AL15>FW$10,$AL15<=FX$10),$AT15*$AK$11,0)+IF(AND($AQ15>FW$10,$AQ15<=FX$10),$AT15*$AP$11,0) -> 0 | FY15: =IF(AND($V15>FX$10,$V15<=FY$10),$AT15*$U$11,0)+IF(AND($AE15>FX$10,$AE15<=FY$10),$AT15*$AD$11,0)+IF(AND($AL15>FX$10,$AL15<=FY$10),$AT15*$AK$11,0)+IF(AND($AQ15>FX$10,$AQ15<=FY$10),$AT15*$AP$11,0) -> 0 | FZ15: =IF(AND($V15>FY$10,$V15<=FZ$10),$AT15*$U$11,0)+IF(AND($AE15>FY$10,$AE15<=FZ$10),$AT15*$AD$11,0)+IF(AND($AL15>FY$10,$AL15<=FZ$10),$AT15*$AK$11,0)+IF(AND($AQ15>FY$10,$AQ15<=FZ$10),$AT15*$AP$11,0) -> 0 | GA15: =IF(AND($V15>FZ$10,$V15<=GA$10),$AT15*$U$11,0)+IF(AND($AE15>FZ$10,$AE15<=GA$10),$AT15*$AD$11,0)+IF(AND($AL15>FZ$10,$AL15<=GA$10),$AT15*$AK$11,0)+IF(AND($AQ15>FZ$10,$AQ15<=GA$10),$AT15*$AP$11,0) -> 0 | ... KB15: =IF(AND($V15>KA$10,$V15<=KB$10),$AT15*$U$11,0)+IF(AND($AE15>KA$10,$AE15<=KB$10),$AT15*$AD$11,0)+IF(AND($AL15>KA$10,$AL15<=KB$10),$AT15*$AK$11,0)+IF(AND($AQ15>KA$10,$AQ15<=KB$10),$AT15*$AP$11,0) -> 0 | KC15: =IF(AND($U15>KB$10,$U15<=KC$10),$AT15*$U$11,0)+IF(AND($AD15>KB$10,$AD15<=KC$10),$AT15*$AD$11,0)+IF(AND($AK15>KB$10,$AK15<=KC$10),$AT15*$AK$11,0)+IF(AND($AP15>KB$10,$AP15<=KC$10),$AT15*$AP$11,0) -> 0 | KD15: =IF(AND($U15>KC$10,$U15<=KD$10),$AT15*$U$11,0)+IF(AND($AD15>KC$10,$AD15<=KD$10),$AT15*$AD$11,0)+IF(AND($AK15>KC$10,$AK15<=KD$10),$AT15*$AK$11,0)+IF(AND($AP15>KC$10,$AP15<=KD$10),$AT15*$AP$11,0) -> 0 | KE15: =IF(AND($U15>KD$10,$U15<=KE$10),$AT15*$U$11,0)+IF(AND($AD15>KD$10,$AD15<=KE$10),$AT15*$AD$11,0)+IF(AND($AK15>KD$10,$AK15<=KE$10),$AT15*$AK$11,0)+IF(AND($AP15>KD$10,$AP15<=KE$10),$AT15*$AP$11,0) -> 0 | KF15: =IF(AND($U15>KE$10,$U15<=KF$10),$AT15*$U$11,0)+IF(AND($AD15>KE$10,$AD15<=KF$10),$AT15*$AD$11,0)+IF(AND($AK15>KE$10,$AK15<=KF$10),$AT15*$AK$11,0)+IF(AND($AP15>KE$10,$AP15<=KF$10),$AT15*$AP$11,0) -> 0 | KG15: =IF(AND($U15>KF$10,$U15<=KG$10),$AT15*$U$11,0)+IF(AND($AD15>KF$10,$AD15<=KG$10),$AT15*$AD$11,0)+IF(AND($AK15>KF$10,$AK15<=KG$10),$AT15*$AK$11,0)+IF(AND($AP15>KF$10,$AP15<=KG$10),$AT15*$AP$11,0) -> 0 | KH15: =IF(AND($U15>KG$10,$U15<=KH$10),$AT15*$U$11,0)+IF(AND($AD15>KG$10,$AD15<=KH$10),$AT15*$AD$11,0)+IF(AND($AK15>KG$10,$AK15<=KH$10),$AT15*$AK$11,0)+IF(AND($AP15>KG$10,$AP15<=KH$10),$AT15*$AP$11,0) -> 0 | KI15: =IF(AND($U15>KH$10,$U15<=KI$10),$AT15*$U$11,0)+IF(AND($AD15>KH$10,$AD15<=KI$10),$AT15*$AD$11,0)+IF(AND($AK15>KH$10,$AK15<=KI$10),$AT15*$AK$11,0)+IF(AND($AP15>KH$10,$AP15<=KI$10),$AT15*$AP$11,0) -> 0 | KJ15: =IF(AND($U15>KI$10,$U15<=KJ$10),$AT15*$U$11,0)+IF(AND($AD15>KI$10,$AD15<=KJ$10),$AT15*$AD$11,0)+IF(AND($AK15>KI$10,$AK15<=KJ$10),$AT15*$AK$11,0)+IF(AND($AP15>KI$10,$AP15<=KJ$10),$AT15*$AP$11,0) -> 0 | KL15: =IF(AND($W15>KK$10,$W15<=KL$10),$AT15*$U$11,0)+IF(AND($AF15>KK$10,$AF15<=KL$10),$AT15*$AD$11,0)+IF(AND($AO15>KK$10,$AO15<=KL$10),$AT15*$AK$11,0)+IF(AND($AR15>KK$10,$AR15<=KL$10),$AT15*$AP$11,0) -> 0 | KM15: =IF(AND($W15>KL$10,$W15<=KM$10),$AT15*$U$11,0)+IF(AND($AF15>KL$10,$AF15<=KM$10),$AT15*$AD$11,0)+IF(AND($AO15>KL$10,$AO15<=KM$10),$AT15*$AK$11,0)+IF(AND($AR15>KL$10,$AR15<=KM$10),$AT15*$AP$11,0) -> 0 | KN15: =IF(AND($W15>KM$10,$W15<=KN$10),$AT15*$U$11,0)+IF(AND($AF15>KM$10,$AF15<=KN$10),$AT15*$AD$11,0)+IF(AND($AO15>KM$10,$AO15<=KN$10),$AT15*$AK$11,0)+IF(AND($AR15>KM$10,$AR15<=KN$10),$AT15*$AP$11,0) -> 0 | KO15: =IF(AND($W15>KN$10,$W15<=KO$10),$AT15*$U$11,0)+IF(AND($AF15>KN$10,$AF15<=KO$10),$AT15*$AD$11,0)+IF(AND($AO15>KN$10,$AO15<=KO$10),$AT15*$AK$11,0)+IF(AND($AR15>KN$10,$AR15<=KO$10),$AT15*$AP$11,0) -> 0 | KP15: =IF(AND($W15>KO$10,$W15<=KP$10),$AT15*$U$11,0)+IF(AND($AF15>KO$10,$AF15<=KP$10),$AT15*$AD$11,0)+IF(AND($AO15>KO$10,$AO15<=KP$10),$AT15*$AK$11,0)+IF(AND($AR15>KO$10,$AR15<=KP$10),$AT15*$AP$11,0) -> 0 | KQ15: =IF(AND($W15>KP$10,$W15<=KQ$10),$AT15*$U$11,0)+IF(AND($AF15>KP$10,$AF15<=KQ$10),$AT15*$AD$11,0)+IF(AND($AO15>KP$10,$AO15<=KQ$10),$AT15*$AK$11,0)+IF(AND($AR15>KP$10,$AR15<=KQ$10),$AT15*$AP$11,0) -> 0 | KR15: =IF(AND($W15>KQ$10,$W15<=KR$10),$AT15*$U$11,0)+IF(AND($AF15>KQ$10,$AF15<=KR$10),$AT15*$AD$11,0)+IF(AND($AO15>KQ$10,$AO15<=KR$10),$AT15*$AK$11,0)+IF(AND($AR15>KQ$10,$AR15<=KR$10),$AT15*$AP$11,0) -> 0 | KS15: =IF(AND($W15>KR$10,$W15<=KS$10),$AT15*$U$11,0)+IF(AND($AF15>KR$10,$AF15<=KS$10),$AT15*$AD$11,0)+IF(AND($AO15>KR$10,$AO15<=KS$10),$AT15*$AK$11,0)+IF(AND($AR15>KR$10,$AR15<=KS$10),$AT15*$AP$11,0) -> 0 | ... PB15: =IF(AND($W15>PA$10,$W15<=PB$10),$AT15*$U$11,0)+IF(AND($AF15>PA$10,$AF15<=PB$10),$AT15*$AD$11,0)+IF(AND($AO15>PA$10,$AO15<=PB$10),$AT15*$AK$11,0)+IF(AND($AR15>PA$10,$AR15<=PB$10),$AT15*$AP$11,0) -> 0 | PD15: =VLOOKUP($I15,[1]IFR!$B$10:$AQ$1616,1,0) -> MM-ZTK-1F-IPX-PLR-BOD-9002 | PE15: =INT(VLOOKUP($I15,[1]IFR!$B$10:$AQ$1616,20,0)) -> 46141 | PF15: =VLOOKUP($I15,[1]IFA!$B$10:$AQ$694,1,0) -> MM-ZTK-1F-IPX-PLR-BOD-9002 | PG15: =INT(VLOOKUP($I15,[1]IFA!$B$10:$AQ$694,20,0)) -> 46202 | PH15: =VLOOKUP($I15,[1]IFC!$B$10:$AQ$702,1,0) -> MM-ZTK-1F-IPX-PLR-BOD-9002 | PI15: =INT(VLOOKUP($I15,[1]IFC!$B$10:$AQ$702,20,0)) -> 46226 | PJ15: =VLOOKUP($I15,[1]IFC!$B$10:$AQ$702,17,0) -> AFC | PK15: =VLOOKUP($I15,[1]IFC!$B$10:$AQ$702,33,0) -> Approved with Comment | PL15: =VLOOKUP($I15,[1]IFC!$B$10:$AQ$702,32,0) -> AWC | PM15: =INT(VLOOKUP($I15,[1]IFC!$B$10:$AQ$702,37,0)) -> 46233
A16: 6 | B16: =B15+1 -> 3 | C16: IPX | D16: PRO | E16: BOD | F16: 9001 | G16: docx | I16: =CONCATENATE("MM-",$D$6,"-",$D$7,"-",C16,"-",D16,"-",E16,"-",F16) -> MM-ZTK-1F-IPX-PRO-BOD-9001 | J16: Design Basis for Pipeline and Riser Flow Assurance Studies | M16: R1 | N16: =VLOOKUP(I16,'MS Project'!$B$6:$F$189,5,FALSE)+7 -> 46153 | O16: =N16+7 -> 46160 | P16: =O16+3 -> 46163 | Q16: A1 | R16: =P16+2 -> 46165 | S16: =R16+2 -> 46167 | T16: =S16+3 -> 46170 | U16: =T16+1 -> 46171 | V16: 46164 | W16: =V16 -> 46164 | X16: =U16+14 -> 46185 | Y16: =X16+2 -> 46187 | Z16: B1 | AA16: =Y16+4 -> 46191 | AB16: =AA16+3 -> 46194 | AC16: =AB16+4 -> 46198 | AD16: =AC16+1 -> 46199 | AE16: 46198 | AF16: =AE16 -> 46198 | AG16: =AD16+14 -> 46213 | AH16: =AG16+2 -> 46215 | AI16: C1 | AJ16: =AH16+4 -> 46219 | AK16: =AJ16+1 -> 46220 | AL16: 46220 | AM16: =AK16+14 -> 46234 | AO16: =AK16 -> 46220 | AP16: =AM16 -> 46234 | AQ16: 46227 | AR16: =AP16 -> 46234 | AS16: 1 | AT16: =AS16/$AS$11 -> 0.0081967213 | AU16: =IF($U16>0,IF($U16<=$AV$7,$AT16*$U$11,0))+IF($AD16>0,IF($AD16<=$AV$7,$AT16*$AD$11,0))+IF($AK16>0,IF($AK16<=$AV$7,$AT16*$AK$11,0))+IF($AP16>0,IF($AP16<=$AV$7,$AT16*$AP$11,0)) -> 0.0081967213 | AV16: =IF($V16>0,IF($V16<=$AV$7,$AT16*$U$11,0))+IF($AE16>0,IF($AE16<=$AV$7,$AT16*$AD$11,0))+IF($AL16>0,IF($AL16<=$AV$7,$AT16*$AK$11,0))+IF($AQ16>0,IF($AQ16<=$AV$7,$AT16*$AP$11,0)) -> 0.0081967213 | AW16: =AV16-AU16 -> 0 | AX16: =IF($U16>0,IF($U16<=$AZ$7,$AT16*$U$11,0))+IF($AD16>0,IF($AD16<=$AZ$7,$AT16*$AD$11,0))+IF($AK16>0,IF($AK16<=$AZ$7,$AT16*$AK$11,0))+IF($AP16>0,IF($AP16<=$AZ$7,$AT16*$AP$11,0)) -> 0.0081967213 | AY16: =IF($V16>0,IF($V16<=$AZ$7,$AT16*$U$11,0))+IF($AE16>0,IF($AE16<=$AZ$7,$AT16*$AD$11,0))+IF($AL16>0,IF($AL16<=$AZ$7,$AT16*$AK$11,0))+IF($AQ16>0,IF($AQ16<=$AZ$7,$AT16*$AP$11,0)) -> 0.0081967213 | AZ16: =AY16-AX16 -> 0 | BB16: =IF(AND($U16>BA$10,$U16<=BB$10),$AT16*$U$11,0)+IF(AND($AD16>BA$10,$AD16<=BB$10),$AT16*$AD$11,0)+IF(AND($AK16>BA$10,$AK16<=BB$10),$AT16*$AK$11,0)+IF(AND($AP16>BA$10,$AP16<=BB$10),$AT16*$AP$11,0) -> 0 | BC16: =IF(AND($U16>BB$10,$U16<=BC$10),$AT16*$U$11,0)+IF(AND($AD16>BB$10,$AD16<=BC$10),$AT16*$AD$11,0)+IF(AND($AK16>BB$10,$AK16<=BC$10),$AT16*$AK$11,0)+IF(AND($AP16>BB$10,$AP16<=BC$10),$AT16*$AP$11,0) -> 0 | BD16: =IF(AND($U16>BC$10,$U16<=BD$10),$AT16*$U$11,0)+IF(AND($AD16>BC$10,$AD16<=BD$10),$AT16*$AD$11,0)+IF(AND($AK16>BC$10,$AK16<=BD$10),$AT16*$AK$11,0)+IF(AND($AP16>BC$10,$AP16<=BD$10),$AT16*$AP$11,0) -> 0 | BE16: =IF(AND($U16>BD$10,$U16<=BE$10),$AT16*$U$11,0)+IF(AND($AD16>BD$10,$AD16<=BE$10),$AT16*$AD$11,0)+IF(AND($AK16>BD$10,$AK16<=BE$10),$AT16*$AK$11,0)+IF(AND($AP16>BD$10,$AP16<=BE$10),$AT16*$AP$11,0) -> 0 | BF16: =IF(AND($U16>BE$10,$U16<=BF$10),$AT16*$U$11,0)+IF(AND($AD16>BE$10,$AD16<=BF$10),$AT16*$AD$11,0)+IF(AND($AK16>BE$10,$AK16<=BF$10),$AT16*$AK$11,0)+IF(AND($AP16>BE$10,$AP16<=BF$10),$AT16*$AP$11,0) -> 0 | BG16: =IF(AND($U16>BF$10,$U16<=BG$10),$AT16*$U$11,0)+IF(AND($AD16>BF$10,$AD16<=BG$10),$AT16*$AD$11,0)+IF(AND($AK16>BF$10,$AK16<=BG$10),$AT16*$AK$11,0)+IF(AND($AP16>BF$10,$AP16<=BG$10),$AT16*$AP$11,0) -> 0 | BH16: =IF(AND($U16>BG$10,$U16<=BH$10),$AT16*$U$11,0)+IF(AND($AD16>BG$10,$AD16<=BH$10),$AT16*$AD$11,0)+IF(AND($AK16>BG$10,$AK16<=BH$10),$AT16*$AK$11,0)+IF(AND($AP16>BG$10,$AP16<=BH$10),$AT16*$AP$11,0) -> 0 | BI16: =IF(AND($U16>BH$10,$U16<=BI$10),$AT16*$U$11,0)+IF(AND($AD16>BH$10,$AD16<=BI$10),$AT16*$AD$11,0)+IF(AND($AK16>BH$10,$AK16<=BI$10),$AT16*$AK$11,0)+IF(AND($AP16>BH$10,$AP16<=BI$10),$AT16*$AP$11,0) -> 0 | ... FR16: =IF(AND($U16>FQ$10,$U16<=FR$10),$AT16*$U$11,0)+IF(AND($AD16>FQ$10,$AD16<=FR$10),$AT16*$AD$11,0)+IF(AND($AK16>FQ$10,$AK16<=FR$10),$AT16*$AK$11,0)+IF(AND($AP16>FQ$10,$AP16<=FR$10),$AT16*$AP$11,0) -> 0 | FT16: =IF(AND($V16>FS$10,$V16<=FT$10),$AT16*$U$11,0)+IF(AND($AE16>FS$10,$AE16<=FT$10),$AT16*$AD$11,0)+IF(AND($AL16>FS$10,$AL16<=FT$10),$AT16*$AK$11,0)+IF(AND($AQ16>FS$10,$AQ16<=FT$10),$AT16*$AP$11,0) -> 0 | FU16: =IF(AND($V16>FT$10,$V16<=FU$10),$AT16*$U$11,0)+IF(AND($AE16>FT$10,$AE16<=FU$10),$AT16*$AD$11,0)+IF(AND($AL16>FT$10,$AL16<=FU$10),$AT16*$AK$11,0)+IF(AND($AQ16>FT$10,$AQ16<=FU$10),$AT16*$AP$11,0) -> 0 | FV16: =IF(AND($V16>FU$10,$V16<=FV$10),$AT16*$U$11,0)+IF(AND($AE16>FU$10,$AE16<=FV$10),$AT16*$AD$11,0)+IF(AND($AL16>FU$10,$AL16<=FV$10),$AT16*$AK$11,0)+IF(AND($AQ16>FU$10,$AQ16<=FV$10),$AT16*$AP$11,0) -> 0 | FW16: =IF(AND($V16>FV$10,$V16<=FW$10),$AT16*$U$11,0)+IF(AND($AE16>FV$10,$AE16<=FW$10),$AT16*$AD$11,0)+IF(AND($AL16>FV$10,$AL16<=FW$10),$AT16*$AK$11,0)+IF(AND($AQ16>FV$10,$AQ16<=FW$10),$AT16*$AP$11,0) -> 0 | FX16: =IF(AND($V16>FW$10,$V16<=FX$10),$AT16*$U$11,0)+IF(AND($AE16>FW$10,$AE16<=FX$10),$AT16*$AD$11,0)+IF(AND($AL16>FW$10,$AL16<=FX$10),$AT16*$AK$11,0)+IF(AND($AQ16>FW$10,$AQ16<=FX$10),$AT16*$AP$11,0) -> 0 | FY16: =IF(AND($V16>FX$10,$V16<=FY$10),$AT16*$U$11,0)+IF(AND($AE16>FX$10,$AE16<=FY$10),$AT16*$AD$11,0)+IF(AND($AL16>FX$10,$AL16<=FY$10),$AT16*$AK$11,0)+IF(AND($AQ16>FX$10,$AQ16<=FY$10),$AT16*$AP$11,0) -> 0 | FZ16: =IF(AND($V16>FY$10,$V16<=FZ$10),$AT16*$U$11,0)+IF(AND($AE16>FY$10,$AE16<=FZ$10),$AT16*$AD$11,0)+IF(AND($AL16>FY$10,$AL16<=FZ$10),$AT16*$AK$11,0)+IF(AND($AQ16>FY$10,$AQ16<=FZ$10),$AT16*$AP$11,0) -> 0 | GA16: =IF(AND($V16>FZ$10,$V16<=GA$10),$AT16*$U$11,0)+IF(AND($AE16>FZ$10,$AE16<=GA$10),$AT16*$AD$11,0)+IF(AND($AL16>FZ$10,$AL16<=GA$10),$AT16*$AK$11,0)+IF(AND($AQ16>FZ$10,$AQ16<=GA$10),$AT16*$AP$11,0) -> 0 | ... KB16: =IF(AND($V16>KA$10,$V16<=KB$10),$AT16*$U$11,0)+IF(AND($AE16>KA$10,$AE16<=KB$10),$AT16*$AD$11,0)+IF(AND($AL16>KA$10,$AL16<=KB$10),$AT16*$AK$11,0)+IF(AND($AQ16>KA$10,$AQ16<=KB$10),$AT16*$AP$11,0) -> 0 | KC16: =IF(AND($U16>KB$10,$U16<=KC$10),$AT16*$U$11,0)+IF(AND($AD16>KB$10,$AD16<=KC$10),$AT16*$AD$11,0)+IF(AND($AK16>KB$10,$AK16<=KC$10),$AT16*$AK$11,0)+IF(AND($AP16>KB$10,$AP16<=KC$10),$AT16*$AP$11,0) -> 0 | KD16: =IF(AND($U16>KC$10,$U16<=KD$10),$AT16*$U$11,0)+IF(AND($AD16>KC$10,$AD16<=KD$10),$AT16*$AD$11,0)+IF(AND($AK16>KC$10,$AK16<=KD$10),$AT16*$AK$11,0)+IF(AND($AP16>KC$10,$AP16<=KD$10),$AT16*$AP$11,0) -> 0 | KE16: =IF(AND($U16>KD$10,$U16<=KE$10),$AT16*$U$11,0)+IF(AND($AD16>KD$10,$AD16<=KE$10),$AT16*$AD$11,0)+IF(AND($AK16>KD$10,$AK16<=KE$10),$AT16*$AK$11,0)+IF(AND($AP16>KD$10,$AP16<=KE$10),$AT16*$AP$11,0) -> 0 | KF16: =IF(AND($U16>KE$10,$U16<=KF$10),$AT16*$U$11,0)+IF(AND($AD16>KE$10,$AD16<=KF$10),$AT16*$AD$11,0)+IF(AND($AK16>KE$10,$AK16<=KF$10),$AT16*$AK$11,0)+IF(AND($AP16>KE$10,$AP16<=KF$10),$AT16*$AP$11,0) -> 0 | KG16: =IF(AND($U16>KF$10,$U16<=KG$10),$AT16*$U$11,0)+IF(AND($AD16>KF$10,$AD16<=KG$10),$AT16*$AD$11,0)+IF(AND($AK16>KF$10,$AK16<=KG$10),$AT16*$AK$11,0)+IF(AND($AP16>KF$10,$AP16<=KG$10),$AT16*$AP$11,0) -> 0 | KH16: =IF(AND($U16>KG$10,$U16<=KH$10),$AT16*$U$11,0)+IF(AND($AD16>KG$10,$AD16<=KH$10),$AT16*$AD$11,0)+IF(AND($AK16>KG$10,$AK16<=KH$10),$AT16*$AK$11,0)+IF(AND($AP16>KG$10,$AP16<=KH$10),$AT16*$AP$11,0) -> 0 | KI16: =IF(AND($U16>KH$10,$U16<=KI$10),$AT16*$U$11,0)+IF(AND($AD16>KH$10,$AD16<=KI$10),$AT16*$AD$11,0)+IF(AND($AK16>KH$10,$AK16<=KI$10),$AT16*$AK$11,0)+IF(AND($AP16>KH$10,$AP16<=KI$10),$AT16*$AP$11,0) -> 0 | KJ16: =IF(AND($U16>KI$10,$U16<=KJ$10),$AT16*$U$11,0)+IF(AND($AD16>KI$10,$AD16<=KJ$10),$AT16*$AD$11,0)+IF(AND($AK16>KI$10,$AK16<=KJ$10),$AT16*$AK$11,0)+IF(AND($AP16>KI$10,$AP16<=KJ$10),$AT16*$AP$11,0) -> 0 | KL16: =IF(AND($W16>KK$10,$W16<=KL$10),$AT16*$U$11,0)+IF(AND($AF16>KK$10,$AF16<=KL$10),$AT16*$AD$11,0)+IF(AND($AO16>KK$10,$AO16<=KL$10),$AT16*$AK$11,0)+IF(AND($AR16>KK$10,$AR16<=KL$10),$AT16*$AP$11,0) -> 0 | KM16: =IF(AND($W16>KL$10,$W16<=KM$10),$AT16*$U$11,0)+IF(AND($AF16>KL$10,$AF16<=KM$10),$AT16*$AD$11,0)+IF(AND($AO16>KL$10,$AO16<=KM$10),$AT16*$AK$11,0)+IF(AND($AR16>KL$10,$AR16<=KM$10),$AT16*$AP$11,0) -> 0 | KN16: =IF(AND($W16>KM$10,$W16<=KN$10),$AT16*$U$11,0)+IF(AND($AF16>KM$10,$AF16<=KN$10),$AT16*$AD$11,0)+IF(AND($AO16>KM$10,$AO16<=KN$10),$AT16*$AK$11,0)+IF(AND($AR16>KM$10,$AR16<=KN$10),$AT16*$AP$11,0) -> 0 | KO16: =IF(AND($W16>KN$10,$W16<=KO$10),$AT16*$U$11,0)+IF(AND($AF16>KN$10,$AF16<=KO$10),$AT16*$AD$11,0)+IF(AND($AO16>KN$10,$AO16<=KO$10),$AT16*$AK$11,0)+IF(AND($AR16>KN$10,$AR16<=KO$10),$AT16*$AP$11,0) -> 0 | KP16: =IF(AND($W16>KO$10,$W16<=KP$10),$AT16*$U$11,0)+IF(AND($AF16>KO$10,$AF16<=KP$10),$AT16*$AD$11,0)+IF(AND($AO16>KO$10,$AO16<=KP$10),$AT16*$AK$11,0)+IF(AND($AR16>KO$10,$AR16<=KP$10),$AT16*$AP$11,0) -> 0 | KQ16: =IF(AND($W16>KP$10,$W16<=KQ$10),$AT16*$U$11,0)+IF(AND($AF16>KP$10,$AF16<=KQ$10),$AT16*$AD$11,0)+IF(AND($AO16>KP$10,$AO16<=KQ$10),$AT16*$AK$11,0)+IF(AND($AR16>KP$10,$AR16<=KQ$10),$AT16*$AP$11,0) -> 0 | KR16: =IF(AND($W16>KQ$10,$W16<=KR$10),$AT16*$U$11,0)+IF(AND($AF16>KQ$10,$AF16<=KR$10),$AT16*$AD$11,0)+IF(AND($AO16>KQ$10,$AO16<=KR$10),$AT16*$AK$11,0)+IF(AND($AR16>KQ$10,$AR16<=KR$10),$AT16*$AP$11,0) -> 0 | KS16: =IF(AND($W16>KR$10,$W16<=KS$10),$AT16*$U$11,0)+IF(AND($AF16>KR$10,$AF16<=KS$10),$AT16*$AD$11,0)+IF(AND($AO16>KR$10,$AO16<=KS$10),$AT16*$AK$11,0)+IF(AND($AR16>KR$10,$AR16<=KS$10),$AT16*$AP$11,0) -> 0 | ... PB16: =IF(AND($W16>PA$10,$W16<=PB$10),$AT16*$U$11,0)+IF(AND($AF16>PA$10,$AF16<=PB$10),$AT16*$AD$11,0)+IF(AND($AO16>PA$10,$AO16<=PB$10),$AT16*$AK$11,0)+IF(AND($AR16>PA$10,$AR16<=PB$10),$AT16*$AP$11,0) -> 0 | PD16: =VLOOKUP($I16,[1]IFR!$B$10:$AQ$1616,1,0) -> MM-ZTK-1F-IPX-PRO-BOD-9001 | PE16: =INT(VLOOKUP($I16,[1]IFR!$B$10:$AQ$1616,20,0)) -> 46164 | PF16: =VLOOKUP($I16,[1]IFA!$B$10:$AQ$694,1,0) -> MM-ZTK-1F-IPX-PRO-BOD-9001 | PG16: =INT(VLOOKUP($I16,[1]IFA!$B$10:$AQ$694,20,0)) -> 46198 | PH16: =VLOOKUP($I16,[1]IFC!$B$10:$AQ$702,1,0) -> MM-ZTK-1F-IPX-PRO-BOD-9001 | PI16: =INT(VLOOKUP($I16,[1]IFC!$B$10:$AQ$702,20,0)) -> 46219 | PJ16: =VLOOKUP($I16,[1]IFC!$B$10:$AQ$702,17,0) -> AFC | PK16: =VLOOKUP($I16,[1]IFC!$B$10:$AQ$702,33,0) -> Approved | PL16: =VLOOKUP($I16,[1]IFC!$B$10:$AQ$702,32,0) -> APPR | PM16: =INT(VLOOKUP($I16,[1]IFC!$B$10:$AQ$702,37,0)) -> 46230
A17: 7 | AT17: =AS17/$AS$11 -> 0 | AU17: =IF($U17>0,IF($U17<=$AV$7,$AT17*$U$11,0))+IF($AD17>0,IF($AD17<=$AV$7,$AT17*$AD$11,0))+IF($AK17>0,IF($AK17<=$AV$7,$AT17*$AK$11,0))+IF($AP17>0,IF($AP17<=$AV$7,$AT17*$AP$11,0)) -> 0 | AV17: =IF($V17>0,IF($V17<=$AV$7,$AT17*$U$11,0))+IF($AE17>0,IF($AE17<=$AV$7,$AT17*$AD$11,0))+IF($AL17>0,IF($AL17<=$AV$7,$AT17*$AK$11,0))+IF($AQ17>0,IF($AQ17<=$AV$7,$AT17*$AP$11,0)) -> 0 | AW17: =AV17-AU17 -> 0 | AX17: =IF($U17>0,IF($U17<=$AZ$7,$AT17*$U$11,0))+IF($AD17>0,IF($AD17<=$AZ$7,$AT17*$AD$11,0))+IF($AK17>0,IF($AK17<=$AZ$7,$AT17*$AK$11,0))+IF($AP17>0,IF($AP17<=$AZ$7,$AT17*$AP$11,0)) -> 0 | AY17: =IF($V17>0,IF($V17<=$AZ$7,$AT17*$U$11,0))+IF($AE17>0,IF($AE17<=$AZ$7,$AT17*$AD$11,0))+IF($AL17>0,IF($AL17<=$AZ$7,$AT17*$AK$11,0))+IF($AQ17>0,IF($AQ17<=$AZ$7,$AT17*$AP$11,0)) -> 0 | AZ17: =AY17-AX17 -> 0 | BB17: =IF(AND($U17>BA$10,$U17<=BB$10),$AT17*$U$11,0)+IF(AND($AD17>BA$10,$AD17<=BB$10),$AT17*$AD$11,0)+IF(AND($AK17>BA$10,$AK17<=BB$10),$AT17*$AK$11,0)+IF(AND($AP17>BA$10,$AP17<=BB$10),$AT17*$AP$11,0) -> 0 | BC17: =IF(AND($U17>BB$10,$U17<=BC$10),$AT17*$U$11,0)+IF(AND($AD17>BB$10,$AD17<=BC$10),$AT17*$AD$11,0)+IF(AND($AK17>BB$10,$AK17<=BC$10),$AT17*$AK$11,0)+IF(AND($AP17>BB$10,$AP17<=BC$10),$AT17*$AP$11,0) -> 0 | BD17: =IF(AND($U17>BC$10,$U17<=BD$10),$AT17*$U$11,0)+IF(AND($AD17>BC$10,$AD17<=BD$10),$AT17*$AD$11,0)+IF(AND($AK17>BC$10,$AK17<=BD$10),$AT17*$AK$11,0)+IF(AND($AP17>BC$10,$AP17<=BD$10),$AT17*$AP$11,0) -> 0 | BE17: =IF(AND($U17>BD$10,$U17<=BE$10),$AT17*$U$11,0)+IF(AND($AD17>BD$10,$AD17<=BE$10),$AT17*$AD$11,0)+IF(AND($AK17>BD$10,$AK17<=BE$10),$AT17*$AK$11,0)+IF(AND($AP17>BD$10,$AP17<=BE$10),$AT17*$AP$11,0) -> 0 | BF17: =IF(AND($U17>BE$10,$U17<=BF$10),$AT17*$U$11,0)+IF(AND($AD17>BE$10,$AD17<=BF$10),$AT17*$AD$11,0)+IF(AND($AK17>BE$10,$AK17<=BF$10),$AT17*$AK$11,0)+IF(AND($AP17>BE$10,$AP17<=BF$10),$AT17*$AP$11,0) -> 0 | BG17: =IF(AND($U17>BF$10,$U17<=BG$10),$AT17*$U$11,0)+IF(AND($AD17>BF$10,$AD17<=BG$10),$AT17*$AD$11,0)+IF(AND($AK17>BF$10,$AK17<=BG$10),$AT17*$AK$11,0)+IF(AND($AP17>BF$10,$AP17<=BG$10),$AT17*$AP$11,0) -> 0 | BH17: =IF(AND($U17>BG$10,$U17<=BH$10),$AT17*$U$11,0)+IF(AND($AD17>BG$10,$AD17<=BH$10),$AT17*$AD$11,0)+IF(AND($AK17>BG$10,$AK17<=BH$10),$AT17*$AK$11,0)+IF(AND($AP17>BG$10,$AP17<=BH$10),$AT17*$AP$11,0) -> 0 | BI17: =IF(AND($U17>BH$10,$U17<=BI$10),$AT17*$U$11,0)+IF(AND($AD17>BH$10,$AD17<=BI$10),$AT17*$AD$11,0)+IF(AND($AK17>BH$10,$AK17<=BI$10),$AT17*$AK$11,0)+IF(AND($AP17>BH$10,$AP17<=BI$10),$AT17*$AP$11,0) -> 0 | ... FR17: =IF(AND($U17>FQ$10,$U17<=FR$10),$AT17*$U$11,0)+IF(AND($AD17>FQ$10,$AD17<=FR$10),$AT17*$AD$11,0)+IF(AND($AK17>FQ$10,$AK17<=FR$10),$AT17*$AK$11,0)+IF(AND($AP17>FQ$10,$AP17<=FR$10),$AT17*$AP$11,0) -> 0 | FT17: =IF(AND($V17>FS$10,$V17<=FT$10),$AT17*$U$11,0)+IF(AND($AE17>FS$10,$AE17<=FT$10),$AT17*$AD$11,0)+IF(AND($AL17>FS$10,$AL17<=FT$10),$AT17*$AK$11,0)+IF(AND($AQ17>FS$10,$AQ17<=FT$10),$AT17*$AP$11,0) -> 0 | FU17: =IF(AND($V17>FT$10,$V17<=FU$10),$AT17*$U$11,0)+IF(AND($AE17>FT$10,$AE17<=FU$10),$AT17*$AD$11,0)+IF(AND($AL17>FT$10,$AL17<=FU$10),$AT17*$AK$11,0)+IF(AND($AQ17>FT$10,$AQ17<=FU$10),$AT17*$AP$11,0) -> 0 | FV17: =IF(AND($V17>FU$10,$V17<=FV$10),$AT17*$U$11,0)+IF(AND($AE17>FU$10,$AE17<=FV$10),$AT17*$AD$11,0)+IF(AND($AL17>FU$10,$AL17<=FV$10),$AT17*$AK$11,0)+IF(AND($AQ17>FU$10,$AQ17<=FV$10),$AT17*$AP$11,0) -> 0 | FW17: =IF(AND($V17>FV$10,$V17<=FW$10),$AT17*$U$11,0)+IF(AND($AE17>FV$10,$AE17<=FW$10),$AT17*$AD$11,0)+IF(AND($AL17>FV$10,$AL17<=FW$10),$AT17*$AK$11,0)+IF(AND($AQ17>FV$10,$AQ17<=FW$10),$AT17*$AP$11,0) -> 0 | FX17: =IF(AND($V17>FW$10,$V17<=FX$10),$AT17*$U$11,0)+IF(AND($AE17>FW$10,$AE17<=FX$10),$AT17*$AD$11,0)+IF(AND($AL17>FW$10,$AL17<=FX$10),$AT17*$AK$11,0)+IF(AND($AQ17>FW$10,$AQ17<=FX$10),$AT17*$AP$11,0) -> 0 | FY17: =IF(AND($V17>FX$10,$V17<=FY$10),$AT17*$U$11,0)+IF(AND($AE17>FX$10,$AE17<=FY$10),$AT17*$AD$11,0)+IF(AND($AL17>FX$10,$AL17<=FY$10),$AT17*$AK$11,0)+IF(AND($AQ17>FX$10,$AQ17<=FY$10),$AT17*$AP$11,0) -> 0 | FZ17: =IF(AND($V17>FY$10,$V17<=FZ$10),$AT17*$U$11,0)+IF(AND($AE17>FY$10,$AE17<=FZ$10),$AT17*$AD$11,0)+IF(AND($AL17>FY$10,$AL17<=FZ$10),$AT17*$AK$11,0)+IF(AND($AQ17>FY$10,$AQ17<=FZ$10),$AT17*$AP$11,0) -> 0 | GA17: =IF(AND($V17>FZ$10,$V17<=GA$10),$AT17*$U$11,0)+IF(AND($AE17>FZ$10,$AE17<=GA$10),$AT17*$AD$11,0)+IF(AND($AL17>FZ$10,$AL17<=GA$10),$AT17*$AK$11,0)+IF(AND($AQ17>FZ$10,$AQ17<=GA$10),$AT17*$AP$11,0) -> 0 | ... KB17: =IF(AND($V17>KA$10,$V17<=KB$10),$AT17*$U$11,0)+IF(AND($AE17>KA$10,$AE17<=KB$10),$AT17*$AD$11,0)+IF(AND($AL17>KA$10,$AL17<=KB$10),$AT17*$AK$11,0)+IF(AND($AQ17>KA$10,$AQ17<=KB$10),$AT17*$AP$11,0) -> 0 | KC17: =IF(AND($U17>KB$10,$U17<=KC$10),$AT17*$U$11,0)+IF(AND($AD17>KB$10,$AD17<=KC$10),$AT17*$AD$11,0)+IF(AND($AK17>KB$10,$AK17<=KC$10),$AT17*$AK$11,0)+IF(AND($AP17>KB$10,$AP17<=KC$10),$AT17*$AP$11,0) -> 0 | KD17: =IF(AND($U17>KC$10,$U17<=KD$10),$AT17*$U$11,0)+IF(AND($AD17>KC$10,$AD17<=KD$10),$AT17*$AD$11,0)+IF(AND($AK17>KC$10,$AK17<=KD$10),$AT17*$AK$11,0)+IF(AND($AP17>KC$10,$AP17<=KD$10),$AT17*$AP$11,0) -> 0 | KE17: =IF(AND($U17>KD$10,$U17<=KE$10),$AT17*$U$11,0)+IF(AND($AD17>KD$10,$AD17<=KE$10),$AT17*$AD$11,0)+IF(AND($AK17>KD$10,$AK17<=KE$10),$AT17*$AK$11,0)+IF(AND($AP17>KD$10,$AP17<=KE$10),$AT17*$AP$11,0) -> 0 | KF17: =IF(AND($U17>KE$10,$U17<=KF$10),$AT17*$U$11,0)+IF(AND($AD17>KE$10,$AD17<=KF$10),$AT17*$AD$11,0)+IF(AND($AK17>KE$10,$AK17<=KF$10),$AT17*$AK$11,0)+IF(AND($AP17>KE$10,$AP17<=KF$10),$AT17*$AP$11,0) -> 0 | KG17: =IF(AND($U17>KF$10,$U17<=KG$10),$AT17*$U$11,0)+IF(AND($AD17>KF$10,$AD17<=KG$10),$AT17*$AD$11,0)+IF(AND($AK17>KF$10,$AK17<=KG$10),$AT17*$AK$11,0)+IF(AND($AP17>KF$10,$AP17<=KG$10),$AT17*$AP$11,0) -> 0 | KH17: =IF(AND($U17>KG$10,$U17<=KH$10),$AT17*$U$11,0)+IF(AND($AD17>KG$10,$AD17<=KH$10),$AT17*$AD$11,0)+IF(AND($AK17>KG$10,$AK17<=KH$10),$AT17*$AK$11,0)+IF(AND($AP17>KG$10,$AP17<=KH$10),$AT17*$AP$11,0) -> 0 | KI17: =IF(AND($U17>KH$10,$U17<=KI$10),$AT17*$U$11,0)+IF(AND($AD17>KH$10,$AD17<=KI$10),$AT17*$AD$11,0)+IF(AND($AK17>KH$10,$AK17<=KI$10),$AT17*$AK$11,0)+IF(AND($AP17>KH$10,$AP17<=KI$10),$AT17*$AP$11,0) -> 0 | KJ17: =IF(AND($U17>KI$10,$U17<=KJ$10),$AT17*$U$11,0)+IF(AND($AD17>KI$10,$AD17<=KJ$10),$AT17*$AD$11,0)+IF(AND($AK17>KI$10,$AK17<=KJ$10),$AT17*$AK$11,0)+IF(AND($AP17>KI$10,$AP17<=KJ$10),$AT17*$AP$11,0) -> 0 | KL17: =IF(AND($W17>KK$10,$W17<=KL$10),$AT17*$U$11,0)+IF(AND($AF17>KK$10,$AF17<=KL$10),$AT17*$AD$11,0)+IF(AND($AO17>KK$10,$AO17<=KL$10),$AT17*$AK$11,0)+IF(AND($AR17>KK$10,$AR17<=KL$10),$AT17*$AP$11,0) -> 0 | KM17: =IF(AND($W17>KL$10,$W17<=KM$10),$AT17*$U$11,0)+IF(AND($AF17>KL$10,$AF17<=KM$10),$AT17*$AD$11,0)+IF(AND($AO17>KL$10,$AO17<=KM$10),$AT17*$AK$11,0)+IF(AND($AR17>KL$10,$AR17<=KM$10),$AT17*$AP$11,0) -> 0 | KN17: =IF(AND($W17>KM$10,$W17<=KN$10),$AT17*$U$11,0)+IF(AND($AF17>KM$10,$AF17<=KN$10),$AT17*$AD$11,0)+IF(AND($AO17>KM$10,$AO17<=KN$10),$AT17*$AK$11,0)+IF(AND($AR17>KM$10,$AR17<=KN$10),$AT17*$AP$11,0) -> 0 | KO17: =IF(AND($W17>KN$10,$W17<=KO$10),$AT17*$U$11,0)+IF(AND($AF17>KN$10,$AF17<=KO$10),$AT17*$AD$11,0)+IF(AND($AO17>KN$10,$AO17<=KO$10),$AT17*$AK$11,0)+IF(AND($AR17>KN$10,$AR17<=KO$10),$AT17*$AP$11,0) -> 0 | KP17: =IF(AND($W17>KO$10,$W17<=KP$10),$AT17*$U$11,0)+IF(AND($AF17>KO$10,$AF17<=KP$10),$AT17*$AD$11,0)+IF(AND($AO17>KO$10,$AO17<=KP$10),$AT17*$AK$11,0)+IF(AND($AR17>KO$10,$AR17<=KP$10),$AT17*$AP$11,0) -> 0 | KQ17: =IF(AND($W17>KP$10,$W17<=KQ$10),$AT17*$U$11,0)+IF(AND($AF17>KP$10,$AF17<=KQ$10),$AT17*$AD$11,0)+IF(AND($AO17>KP$10,$AO17<=KQ$10),$AT17*$AK$11,0)+IF(AND($AR17>KP$10,$AR17<=KQ$10),$AT17*$AP$11,0) -> 0 | KR17: =IF(AND($W17>KQ$10,$W17<=KR$10),$AT17*$U$11,0)+IF(AND($AF17>KQ$10,$AF17<=KR$10),$AT17*$AD$11,0)+IF(AND($AO17>KQ$10,$AO17<=KR$10),$AT17*$AK$11,0)+IF(AND($AR17>KQ$10,$AR17<=KR$10),$AT17*$AP$11,0) -> 0 | KS17: =IF(AND($W17>KR$10,$W17<=KS$10),$AT17*$U$11,0)+IF(AND($AF17>KR$10,$AF17<=KS$10),$AT17*$AD$11,0)+IF(AND($AO17>KR$10,$AO17<=KS$10),$AT17*$AK$11,0)+IF(AND($AR17>KR$10,$AR17<=KS$10),$AT17*$AP$11,0) -> 0 | ... PB17: =IF(AND($W17>PA$10,$W17<=PB$10),$AT17*$U$11,0)+IF(AND($AF17>PA$10,$AF17<=PB$10),$AT17*$AD$11,0)+IF(AND($AO17>PA$10,$AO17<=PB$10),$AT17*$AK$11,0)+IF(AND($AR17>PA$10,$AR17<=PB$10),$AT17*$AP$11,0) -> 0 | PD17: =VLOOKUP($I17,[1]IFR!$B$10:$AQ$1616,1,0) -> #N/A | PE17: =INT(VLOOKUP($I17,[1]IFR!$B$10:$AQ$1616,20,0)) -> #N/A | PF17: =VLOOKUP($I17,[1]IFA!$B$10:$AQ$694,1,0) -> #N/A | PG17: =INT(VLOOKUP($I17,[1]IFA!$B$10:$AQ$694,20,0)) -> #N/A | PH17: =VLOOKUP($I17,[1]IFC!$B$10:$AQ$702,1,0) -> #N/A | PI17: =INT(VLOOKUP($I17,[1]IFC!$B$10:$AQ$702,20,0)) -> #N/A | PJ17: =VLOOKUP($I17,[1]IFC!$B$10:$AQ$702,17,0) -> #N/A | PK17: =VLOOKUP($I17,[1]IFC!$B$10:$AQ$702,33,0) -> #N/A | PL17: =VLOOKUP($I17,[1]IFC!$B$10:$AQ$702,32,0) -> #N/A | PM17: =INT(VLOOKUP($I17,[1]IFC!$B$10:$AQ$702,37,0)) -> #N/A
A18: 8 | B18: General Reports | J18: =B18 -> General Reports | BB18: =IF(AND($U18>BA$10,$U18<=BB$10),$AT18*$U$11,0)+IF(AND($AD18>BA$10,$AD18<=BB$10),$AT18*$AD$11,0)+IF(AND($AK18>BA$10,$AK18<=BB$10),$AT18*$AK$11,0)+IF(AND($AP18>BA$10,$AP18<=BB$10),$AT18*$AP$11,0) -> 0 | BC18: =IF(AND($U18>BB$10,$U18<=BC$10),$AT18*$U$11,0)+IF(AND($AD18>BB$10,$AD18<=BC$10),$AT18*$AD$11,0)+IF(AND($AK18>BB$10,$AK18<=BC$10),$AT18*$AK$11,0)+IF(AND($AP18>BB$10,$AP18<=BC$10),$AT18*$AP$11,0) -> 0 | BD18: =IF(AND($U18>BC$10,$U18<=BD$10),$AT18*$U$11,0)+IF(AND($AD18>BC$10,$AD18<=BD$10),$AT18*$AD$11,0)+IF(AND($AK18>BC$10,$AK18<=BD$10),$AT18*$AK$11,0)+IF(AND($AP18>BC$10,$AP18<=BD$10),$AT18*$AP$11,0) -> 0 | BE18: =IF(AND($U18>BD$10,$U18<=BE$10),$AT18*$U$11,0)+IF(AND($AD18>BD$10,$AD18<=BE$10),$AT18*$AD$11,0)+IF(AND($AK18>BD$10,$AK18<=BE$10),$AT18*$AK$11,0)+IF(AND($AP18>BD$10,$AP18<=BE$10),$AT18*$AP$11,0) -> 0 | BF18: =IF(AND($U18>BE$10,$U18<=BF$10),$AT18*$U$11,0)+IF(AND($AD18>BE$10,$AD18<=BF$10),$AT18*$AD$11,0)+IF(AND($AK18>BE$10,$AK18<=BF$10),$AT18*$AK$11,0)+IF(AND($AP18>BE$10,$AP18<=BF$10),$AT18*$AP$11,0) -> 0 | BG18: =IF(AND($U18>BF$10,$U18<=BG$10),$AT18*$U$11,0)+IF(AND($AD18>BF$10,$AD18<=BG$10),$AT18*$AD$11,0)+IF(AND($AK18>BF$10,$AK18<=BG$10),$AT18*$AK$11,0)+IF(AND($AP18>BF$10,$AP18<=BG$10),$AT18*$AP$11,0) -> 0 | BH18: =IF(AND($U18>BG$10,$U18<=BH$10),$AT18*$U$11,0)+IF(AND($AD18>BG$10,$AD18<=BH$10),$AT18*$AD$11,0)+IF(AND($AK18>BG$10,$AK18<=BH$10),$AT18*$AK$11,0)+IF(AND($AP18>BG$10,$AP18<=BH$10),$AT18*$AP$11,0) -> 0 | BI18: =IF(AND($U18>BH$10,$U18<=BI$10),$AT18*$U$11,0)+IF(AND($AD18>BH$10,$AD18<=BI$10),$AT18*$AD$11,0)+IF(AND($AK18>BH$10,$AK18<=BI$10),$AT18*$AK$11,0)+IF(AND($AP18>BH$10,$AP18<=BI$10),$AT18*$AP$11,0) -> 0 | ... FR18: =IF(AND($U18>FQ$10,$U18<=FR$10),$AT18*$U$11,0)+IF(AND($AD18>FQ$10,$AD18<=FR$10),$AT18*$AD$11,0)+IF(AND($AK18>FQ$10,$AK18<=FR$10),$AT18*$AK$11,0)+IF(AND($AP18>FQ$10,$AP18<=FR$10),$AT18*$AP$11,0) -> 0 | FT18: =IF(AND($V18>FS$10,$V18<=FT$10),$AT18*$U$11,0)+IF(AND($AE18>FS$10,$AE18<=FT$10),$AT18*$AD$11,0)+IF(AND($AL18>FS$10,$AL18<=FT$10),$AT18*$AK$11,0)+IF(AND($AQ18>FS$10,$AQ18<=FT$10),$AT18*$AP$11,0) -> 0 | FU18: =IF(AND($V18>FT$10,$V18<=FU$10),$AT18*$U$11,0)+IF(AND($AE18>FT$10,$AE18<=FU$10),$AT18*$AD$11,0)+IF(AND($AL18>FT$10,$AL18<=FU$10),$AT18*$AK$11,0)+IF(AND($AQ18>FT$10,$AQ18<=FU$10),$AT18*$AP$11,0) -> 0 | FV18: =IF(AND($V18>FU$10,$V18<=FV$10),$AT18*$U$11,0)+IF(AND($AE18>FU$10,$AE18<=FV$10),$AT18*$AD$11,0)+IF(AND($AL18>FU$10,$AL18<=FV$10),$AT18*$AK$11,0)+IF(AND($AQ18>FU$10,$AQ18<=FV$10),$AT18*$AP$11,0) -> 0 | FW18: =IF(AND($V18>FV$10,$V18<=FW$10),$AT18*$U$11,0)+IF(AND($AE18>FV$10,$AE18<=FW$10),$AT18*$AD$11,0)+IF(AND($AL18>FV$10,$AL18<=FW$10),$AT18*$AK$11,0)+IF(AND($AQ18>FV$10,$AQ18<=FW$10),$AT18*$AP$11,0) -> 0 | FX18: =IF(AND($V18>FW$10,$V18<=FX$10),$AT18*$U$11,0)+IF(AND($AE18>FW$10,$AE18<=FX$10),$AT18*$AD$11,0)+IF(AND($AL18>FW$10,$AL18<=FX$10),$AT18*$AK$11,0)+IF(AND($AQ18>FW$10,$AQ18<=FX$10),$AT18*$AP$11,0) -> 0 | FY18: =IF(AND($V18>FX$10,$V18<=FY$10),$AT18*$U$11,0)+IF(AND($AE18>FX$10,$AE18<=FY$10),$AT18*$AD$11,0)+IF(AND($AL18>FX$10,$AL18<=FY$10),$AT18*$AK$11,0)+IF(AND($AQ18>FX$10,$AQ18<=FY$10),$AT18*$AP$11,0) -> 0 | FZ18: =IF(AND($V18>FY$10,$V18<=FZ$10),$AT18*$U$11,0)+IF(AND($AE18>FY$10,$AE18<=FZ$10),$AT18*$AD$11,0)+IF(AND($AL18>FY$10,$AL18<=FZ$10),$AT18*$AK$11,0)+IF(AND($AQ18>FY$10,$AQ18<=FZ$10),$AT18*$AP$11,0) -> 0 | GA18: =IF(AND($V18>FZ$10,$V18<=GA$10),$AT18*$U$11,0)+IF(AND($AE18>FZ$10,$AE18<=GA$10),$AT18*$AD$11,0)+IF(AND($AL18>FZ$10,$AL18<=GA$10),$AT18*$AK$11,0)+IF(AND($AQ18>FZ$10,$AQ18<=GA$10),$AT18*$AP$11,0) -> 0 | ... KB18: =IF(AND($V18>KA$10,$V18<=KB$10),$AT18*$U$11,0)+IF(AND($AE18>KA$10,$AE18<=KB$10),$AT18*$AD$11,0)+IF(AND($AL18>KA$10,$AL18<=KB$10),$AT18*$AK$11,0)+IF(AND($AQ18>KA$10,$AQ18<=KB$10),$AT18*$AP$11,0) -> 0 | KC18: =IF(AND($U18>KB$10,$U18<=KC$10),$AT18*$U$11,0)+IF(AND($AD18>KB$10,$AD18<=KC$10),$AT18*$AD$11,0)+IF(AND($AK18>KB$10,$AK18<=KC$10),$AT18*$AK$11,0)+IF(AND($AP18>KB$10,$AP18<=KC$10),$AT18*$AP$11,0) -> 0 | KD18: =IF(AND($U18>KC$10,$U18<=KD$10),$AT18*$U$11,0)+IF(AND($AD18>KC$10,$AD18<=KD$10),$AT18*$AD$11,0)+IF(AND($AK18>KC$10,$AK18<=KD$10),$AT18*$AK$11,0)+IF(AND($AP18>KC$10,$AP18<=KD$10),$AT18*$AP$11,0) -> 0 | KE18: =IF(AND($U18>KD$10,$U18<=KE$10),$AT18*$U$11,0)+IF(AND($AD18>KD$10,$AD18<=KE$10),$AT18*$AD$11,0)+IF(AND($AK18>KD$10,$AK18<=KE$10),$AT18*$AK$11,0)+IF(AND($AP18>KD$10,$AP18<=KE$10),$AT18*$AP$11,0) -> 0 | KF18: =IF(AND($U18>KE$10,$U18<=KF$10),$AT18*$U$11,0)+IF(AND($AD18>KE$10,$AD18<=KF$10),$AT18*$AD$11,0)+IF(AND($AK18>KE$10,$AK18<=KF$10),$AT18*$AK$11,0)+IF(AND($AP18>KE$10,$AP18<=KF$10),$AT18*$AP$11,0) -> 0 | KG18: =IF(AND($U18>KF$10,$U18<=KG$10),$AT18*$U$11,0)+IF(AND($AD18>KF$10,$AD18<=KG$10),$AT18*$AD$11,0)+IF(AND($AK18>KF$10,$AK18<=KG$10),$AT18*$AK$11,0)+IF(AND($AP18>KF$10,$AP18<=KG$10),$AT18*$AP$11,0) -> 0 | KH18: =IF(AND($U18>KG$10,$U18<=KH$10),$AT18*$U$11,0)+IF(AND($AD18>KG$10,$AD18<=KH$10),$AT18*$AD$11,0)+IF(AND($AK18>KG$10,$AK18<=KH$10),$AT18*$AK$11,0)+IF(AND($AP18>KG$10,$AP18<=KH$10),$AT18*$AP$11,0) -> 0 | KI18: =IF(AND($U18>KH$10,$U18<=KI$10),$AT18*$U$11,0)+IF(AND($AD18>KH$10,$AD18<=KI$10),$AT18*$AD$11,0)+IF(AND($AK18>KH$10,$AK18<=KI$10),$AT18*$AK$11,0)+IF(AND($AP18>KH$10,$AP18<=KI$10),$AT18*$AP$11,0) -> 0 | KJ18: =IF(AND($U18>KI$10,$U18<=KJ$10),$AT18*$U$11,0)+IF(AND($AD18>KI$10,$AD18<=KJ$10),$AT18*$AD$11,0)+IF(AND($AK18>KI$10,$AK18<=KJ$10),$AT18*$AK$11,0)+IF(AND($AP18>KI$10,$AP18<=KJ$10),$AT18*$AP$11,0) -> 0 | KL18: =IF(AND($W18>KK$10,$W18<=KL$10),$AT18*$U$11,0)+IF(AND($AF18>KK$10,$AF18<=KL$10),$AT18*$AD$11,0)+IF(AND($AO18>KK$10,$AO18<=KL$10),$AT18*$AK$11,0)+IF(AND($AR18>KK$10,$AR18<=KL$10),$AT18*$AP$11,0) -> 0 | KM18: =IF(AND($W18>KL$10,$W18<=KM$10),$AT18*$U$11,0)+IF(AND($AF18>KL$10,$AF18<=KM$10),$AT18*$AD$11,0)+IF(AND($AO18>KL$10,$AO18<=KM$10),$AT18*$AK$11,0)+IF(AND($AR18>KL$10,$AR18<=KM$10),$AT18*$AP$11,0) -> 0 | KN18: =IF(AND($W18>KM$10,$W18<=KN$10),$AT18*$U$11,0)+IF(AND($AF18>KM$10,$AF18<=KN$10),$AT18*$AD$11,0)+IF(AND($AO18>KM$10,$AO18<=KN$10),$AT18*$AK$11,0)+IF(AND($AR18>KM$10,$AR18<=KN$10),$AT18*$AP$11,0) -> 0 | KO18: =IF(AND($W18>KN$10,$W18<=KO$10),$AT18*$U$11,0)+IF(AND($AF18>KN$10,$AF18<=KO$10),$AT18*$AD$11,0)+IF(AND($AO18>KN$10,$AO18<=KO$10),$AT18*$AK$11,0)+IF(AND($AR18>KN$10,$AR18<=KO$10),$AT18*$AP$11,0) -> 0 | KP18: =IF(AND($W18>KO$10,$W18<=KP$10),$AT18*$U$11,0)+IF(AND($AF18>KO$10,$AF18<=KP$10),$AT18*$AD$11,0)+IF(AND($AO18>KO$10,$AO18<=KP$10),$AT18*$AK$11,0)+IF(AND($AR18>KO$10,$AR18<=KP$10),$AT18*$AP$11,0) -> 0 | KQ18: =IF(AND($W18>KP$10,$W18<=KQ$10),$AT18*$U$11,0)+IF(AND($AF18>KP$10,$AF18<=KQ$10),$AT18*$AD$11,0)+IF(AND($AO18>KP$10,$AO18<=KQ$10),$AT18*$AK$11,0)+IF(AND($AR18>KP$10,$AR18<=KQ$10),$AT18*$AP$11,0) -> 0 | KR18: =IF(AND($W18>KQ$10,$W18<=KR$10),$AT18*$U$11,0)+IF(AND($AF18>KQ$10,$AF18<=KR$10),$AT18*$AD$11,0)+IF(AND($AO18>KQ$10,$AO18<=KR$10),$AT18*$AK$11,0)+IF(AND($AR18>KQ$10,$AR18<=KR$10),$AT18*$AP$11,0) -> 0 | KS18: =IF(AND($W18>KR$10,$W18<=KS$10),$AT18*$U$11,0)+IF(AND($AF18>KR$10,$AF18<=KS$10),$AT18*$AD$11,0)+IF(AND($AO18>KR$10,$AO18<=KS$10),$AT18*$AK$11,0)+IF(AND($AR18>KR$10,$AR18<=KS$10),$AT18*$AP$11,0) -> 0 | ... PB18: =IF(AND($W18>PA$10,$W18<=PB$10),$AT18*$U$11,0)+IF(AND($AF18>PA$10,$AF18<=PB$10),$AT18*$AD$11,0)+IF(AND($AO18>PA$10,$AO18<=PB$10),$AT18*$AK$11,0)+IF(AND($AR18>PA$10,$AR18<=PB$10),$AT18*$AP$11,0) -> 0 | PD18: =VLOOKUP($I18,[1]IFR!$B$10:$AQ$1616,1,0) -> #N/A | PE18: =INT(VLOOKUP($I18,[1]IFR!$B$10:$AQ$1616,20,0)) -> #N/A | PF18: =VLOOKUP($I18,[1]IFA!$B$10:$AQ$694,1,0) -> #N/A | PG18: =INT(VLOOKUP($I18,[1]IFA!$B$10:$AQ$694,20,0)) -> #N/A | PH18: =VLOOKUP($I18,[1]IFC!$B$10:$AQ$702,1,0) -> #N/A | PI18: =INT(VLOOKUP($I18,[1]IFC!$B$10:$AQ$702,20,0)) -> #N/A | PJ18: =VLOOKUP($I18,[1]IFC!$B$10:$AQ$702,17,0) -> #N/A | PK18: =VLOOKUP($I18,[1]IFC!$B$10:$AQ$702,33,0) -> #N/A | PL18: =VLOOKUP($I18,[1]IFC!$B$10:$AQ$702,32,0) -> #N/A | PM18: =INT(VLOOKUP($I18,[1]IFC!$B$10:$AQ$702,37,0)) -> #N/A
