Workbook
Name B: #REF!
Name Cutoff_Date: HLOOKUP(#REF!,#REF!,2,FALSE)
Name Cutoff_Date: HLOOKUP(#REF!,#REF!,2,FALSE)
Name Cutoff_Date: HLOOKUP(#REF!,#REF!,2,FALSE)
Name G: #REF!
Name Graph_Select: 'Overall S-Curves DDE Only'!$A$7&" | "&'Overall S-Curves DDE Only'!$A$8&IF('Overall S-Curves DDE Only'!$A$7="Structural Engineering"," | "&'Overall S-Curves DDE Only'!$A$11,"")
Name Graph_Select: 'S-Curves'!$A$7&" | "&'S-Curves'!$A$8&IF('S-Curves'!$A$7="Structural Engineering"," | "&'S-Curves'!$A$11,"")
Name Graph_Select: #REF!&" | "&#REF!&IF(#REF!="Structural Engineering"," | "&#REF!,"")
Name H: #REF!
Name I: #REF!

Sheet Cut_Off
B2: 46101 | E2: ZAWTIKA Z1F TS | F2: ='Progress%'!A7 -> 7
B3: =B2+7 -> 46108
B4: =B3+7 -> 46115
B5: =B4+7 -> 46122
B6: =B5+7 -> 46129
B7: =B6+7 -> 46136
B8: =B7+7 -> 46143
B9: =B8+7 -> 46150
B10: =B9+7 -> 46157
B11: =B10+7 -> 46164
B12: =B11+7 -> 46171
B13: =B12+7 -> 46178
B14: =B13+7 -> 46185
... B115: =B114+7 -> 46892

Sheet Progress Summary
F1: =N1-1 -> 25 | G1: =O1-1 -> 25 | H1: =P1-1 -> 25 | I1: =Q1-1 -> 25 | N1: =_xlfn.XLOOKUP(D3,'Progress%'!6:6,'Progress%'!1:1,0) -> 26 | O1: =_xlfn.XLOOKUP(D3,'Progress%'!6:6,'Progress%'!1:1,0) -> 26 | P1: =N1 -> 26 | Q1: =P1 -> 26
D2: Cut_Off Date
D3: 46241
D5: Topsides DDE Progress by Platform
D6: Descriptions | E6: % WT | F6: Last Week Cumulative (%) | J6: This Week Period (%) | N6: Cumulative up to this week (%)
F7: Plan [A] | G7: Forecast [B] | H7: Actual [C] | I7: Var. [C-A] | J7: Plan [A] | K7: Forecast [B] | L7: Actual [C] | M7: Var. [C-A] | N7: Plan [A] | O7: Forecast [B] | P7: Actual [C] | Q7: Var. [C-A]
A8: ='Progress%'!A7 -> 7 | B8: =A8+1 -> 8 | C8: =B8+1 -> 9 | D8: Overall Topsides | E8: 1 | F8: {=INDEX('Progress%'!$A$1:$DG$10,'Progress Summary'!$A8,'Progress Summary'!F$1)} -> 0.6242 | G8: {=INDEX('Progress%'!$A$1:$DG$10,'Progress Summary'!$A8,'Progress Summary'!G$1)} -> 0.6242 | H8: {=INDEX('Progress%'!$A$1:$DG$10,'Progress Summary'!$C8,'Progress Summary'!H$1)} -> 0.6246 | I8: =H8-F8 -> 0.0004 | J8: =N8-F8 -> 0.03535 | K8: =O8-G8 -> 0.03535 | L8: =P8-H8 -> 0.02625 | M8: =Q8-I8 -> -0.0091 | N8: {=INDEX('Progress%'!$A$1:$DG$10,'Progress Summary'!$A8,'Progress Summary'!N$1)} -> 0.65955 | O8: {=INDEX('Progress%'!$A$1:$DG$10,'Progress Summary'!$B8,'Progress Summary'!O$1)} -> 0.65955 | P8: {=INDEX('Progress%'!$A$1:$DG$10,'Progress Summary'!$C8,'Progress Summary'!P$1)} -> 0.65085 | Q8: =P8-N8 -> -0.0087

Sheet Progress%
A1: 1 | B1: 2 | C1: 3 | D1: 4 | E1: 5 | F1: 6 | G1: 7 | H1: 8 | I1: 9 | J1: 10 | K1: 11 | L1: 12 | M1: 13 | N1: 14 | O1: 15 | P1: 16 | Q1: 17 | R1: 18 | S1: 19 | T1: 20 | U1: 21 | V1: 22 | W1: 23 | X1: 24 | Y1: 25 | Z1: 26 | AA1: 27 | AB1: 28 | AC1: 29 | AD1: 30 | AE1: 31 | AF1: 32 | AG1: 33 | AH1: 34 | AI1: 35 | AJ1: 36 | AK1: 37 | AL1: 38 | AM1: 39 | AN1: 40 | AO1: 41 | AP1: 42 | AQ1: 43 | AR1: 44 | AS1: 45 | AT1: 46 | AU1: 47 | AV1: 48 | AW1: 49 | AX1: 50 | AY1: 51 | AZ1: 52 | BA1: 53 | BB1: 54 | BC1: 55 | BD1: 56 | BE1: 57 | BF1: 58 | BG1: 59 | BH1: 60 | BI1: 61 | BJ1: 62 | BK1: 63 | BL1: 64 | BM1: 65 | BN1: 66 | BO1: 67 | BP1: 68 | BQ1: 69 | BR1: 70 | BS1: 71 | BT1: 72 | BU1: 73 | BV1: 74 | BW1: 75 | BX1: 76 | BY1: 77 | BZ1: 78 | CA1: 79 | CB1: 80 | CC1: 81 | CD1: 82 | CE1: 83 | CF1: 84 | CG1: 85 | CH1: 86 | CI1: 87 | CJ1: 88 | CK1: 89 | CL1: 90 | CM1: 91 | CN1: 92 | CO1: 93 | CP1: 94 | CQ1: 95 | CR1: 96 | CS1: 97 | CT1: 98 | CU1: 99 | CV1: 100 | CW1: 101 | CX1: 102 | CY1: 103 | CZ1: 104 | DA1: 105 | DB1: 106 | DC1: 107 | DD1: 108 | DE1: 109 | DF1: 110 | DG1: 111 | DH1: 112 | DI1: 113 | DJ1: 114 | DK1: 115 | DL1: 116 | DM1: 117
A2: 2 | D2: Cut_Off
A3: 3 | D3: ='Progress Summary'!D3 -> 46241
A4: 4
A5: 5 | B5: Scope | C5: Total WF | D5: WF% | E5: ZWP-18 Topsides
A6: 6 | F6: 46101 | G6: =F6+7 -> 46108 | H6: =G6+7 -> 46115 | I6: =H6+7 -> 46122 | J6: =I6+7 -> 46129 | K6: =J6+7 -> 46136 | L6: =K6+7 -> 46143 | M6: =L6+7 -> 46150 | N6: =M6+7 -> 46157 | ... DM6: =DL6+7 -> 46878
A7: 7 | B7: ZAWTIKA Z1F TS | C7: 100 | D7: 1 | E7: Plan | F7: =IF($C7>0,SUMIFS(EDSR!$J:$J,EDSR!$A:$A,'Progress%'!$B7,EDSR!$K:$K,"<="&F$6)*0.5+SUMIFS(EDSR!$J:$J,EDSR!$A:$A,'Progress%'!$B7,EDSR!$N:$N,"<="&F$6)*0.2+SUMIFS(EDSR!$J:$J,EDSR!$A:$A,'Progress%'!$B7,EDSR!$Q:$Q,"<="&F$6)*0.1+SUMIFS(EDSR!$J:$J,EDSR!$A:$A,'Progress%'!$B7,EDSR!$T:$T,"<="&F$6)*0.2)/$C7 -> 0 | G7: =IF($C7>0,SUMIFS(EDSR!$J:$J,EDSR!$A:$A,'Progress%'!$B7,EDSR!$K:$K,"<="&G$6)*0.5+SUMIFS(EDSR!$J:$J,EDSR!$A:$A,'Progress%'!$B7,EDSR!$N:$N,"<="&G$6)*0.2+SUMIFS(EDSR!$J:$J,EDSR!$A:$A,'Progress%'!$B7,EDSR!$Q:$Q,"<="&G$6)*0.1+SUMIFS(EDSR!$J:$J,EDSR!$A:$A,'Progress%'!$B7,EDSR!$T:$T,"<="&G$6)*0.2)/$C7 -> 0 | H7: =IF($C7>0,SUMIFS(EDSR!$J:$J,EDSR!$A:$A,'Progress%'!$B7,EDSR!$K:$K,"<="&H$6)*0.5+SUMIFS(EDSR!$J:$J,EDSR!$A:$A,'Progress%'!$B7,EDSR!$N:$N,"<="&H$6)*0.2+SUMIFS(EDSR!$J:$J,EDSR!$A:$A,'Progress%'!$B7,EDSR!$Q:$Q,"<="&H$6)*0.1+SUMIFS(EDSR!$J:$J,EDSR!$A:$A,'Progress%'!$B7,EDSR!$T:$T,"<="&H$6)*0.2)/$C7 -> 0.005 | I7: =IF($C7>0,SUMIFS(EDSR!$J:$J,EDSR!$A:$A,'Progress%'!$B7,EDSR!$K:$K,"<="&I$6)*0.5+SUMIFS(EDSR!$J:$J,EDSR!$A:$A,'Progress%'!$B7,EDSR!$N:$N,"<="&I$6)*0.2+SUMIFS(EDSR!$J:$J,EDSR!$A:$A,'Progress%'!$B7,EDSR!$Q:$Q,"<="&I$6)*0.1+SUMIFS(EDSR!$J:$J,EDSR!$A:$A,'Progress%'!$B7,EDSR!$T:$T,"<="&I$6)*0.2)/$C7 -> 0.07 | J7: =IF($C7>0,SUMIFS(EDSR!$J:$J,EDSR!$A:$A,'Progress%'!$B7,EDSR!$K:$K,"<="&J$6)*0.5+SUMIFS(EDSR!$J:$J,EDSR!$A:$A,'Progress%'!$B7,EDSR!$N:$N,"<="&J$6)*0.2+SUMIFS(EDSR!$J:$J,EDSR!$A:$A,'Progress%'!$B7,EDSR!$Q:$Q,"<="&J$6)*0.1+SUMIFS(EDSR!$J:$J,EDSR!$A:$A,'Progress%'!$B7,EDSR!$T:$T,"<="&J$6)*0.2)/$C7 -> 0.07 | K7: =IF($C7>0,SUMIFS(EDSR!$J:$J,EDSR!$A:$A,'Progress%'!$B7,EDSR!$K:$K,"<="&K$6)*0.5+SUMIFS(EDSR!$J:$J,EDSR!$A:$A,'Progress%'!$B7,EDSR!$N:$N,"<="&K$6)*0.2+SUMIFS(EDSR!$J:$J,EDSR!$A:$A,'Progress%'!$B7,EDSR!$Q:$Q,"<="&K$6)*0.1+SUMIFS(EDSR!$J:$J,EDSR!$A:$A,'Progress%'!$B7,EDSR!$T:$T,"<="&K$6)*0.2)/$C7 -> 0.0975 | L7: =IF($C7>0,SUMIFS(EDSR!$J:$J,EDSR!$A:$A,'Progress%'!$B7,EDSR!$K:$K,"<="&L$6)*0.5+SUMIFS(EDSR!$J:$J,EDSR!$A:$A,'Progress%'!$B7,EDSR!$N:$N,"<="&L$6)*0.2+SUMIFS(EDSR!$J:$J,EDSR!$A:$A,'Progress%'!$B7,EDSR!$Q:$Q,"<="&L$6)*0.1+SUMIFS(EDSR!$J:$J,EDSR!$A:$A,'Progress%'!$B7,EDSR!$T:$T,"<="&L$6)*0.2)/$C7 -> 0.13 | M7: =IF($C7>0,SUMIFS(EDSR!$J:$J,EDSR!$A:$A,'Progress%'!$B7,EDSR!$K:$K,"<="&M$6)*0.5+SUMIFS(EDSR!$J:$J,EDSR!$A:$A,'Progress%'!$B7,EDSR!$N:$N,"<="&M$6)*0.2+SUMIFS(EDSR!$J:$J,EDSR!$A:$A,'Progress%'!$B7,EDSR!$Q:$Q,"<="&M$6)*0.1+SUMIFS(EDSR!$J:$J,EDSR!$A:$A,'Progress%'!$B7,EDSR!$T:$T,"<="&M$6)*0.2)/$C7 -> 0.14 | ... DM7: =IF($C7>0,SUMIFS(EDSR!$J:$J,EDSR!$A:$A,'Progress%'!$B7,EDSR!$K:$K,"<="&DM$6)*0.5+SUMIFS(EDSR!$J:$J,EDSR!$A:$A,'Progress%'!$B7,EDSR!$N:$N,"<="&DM$6)*0.2+SUMIFS(EDSR!$J:$J,EDSR!$A:$A,'Progress%'!$B7,EDSR!$Q:$Q,"<="&DM$6)*0.1+SUMIFS(EDSR!$J:$J,EDSR!$A:$A,'Progress%'!$B7,EDSR!$T:$T,"<="&DM$6)*0.2)/$C7 -> 0.9
A8: 8 | B8: ZAWTIKA Z1F TS | C8: 100 | D8: 1 | E8: Forecast | F8: =IF($C7>0,SUMIFS(EDSR!$J:$J,EDSR!$A:$A,'Progress%'!$B7,EDSR!$L:$L,"<="&F$6)*0.5+SUMIFS(EDSR!$J:$J,EDSR!$A:$A,'Progress%'!$B7,EDSR!$O:$O,"<="&F$6)*0.2+SUMIFS(EDSR!$J:$J,EDSR!$A:$A,'Progress%'!$B7,EDSR!$R:$R,"<="&F$6)*0.1+SUMIFS(EDSR!$J:$J,EDSR!$A:$A,'Progress%'!$B7,EDSR!$U:$U,"<="&F$6)*0.2)/$C7 -> 0 | G8: =IF($C7>0,SUMIFS(EDSR!$J:$J,EDSR!$A:$A,'Progress%'!$B7,EDSR!$L:$L,"<="&G$6)*0.5+SUMIFS(EDSR!$J:$J,EDSR!$A:$A,'Progress%'!$B7,EDSR!$O:$O,"<="&G$6)*0.2+SUMIFS(EDSR!$J:$J,EDSR!$A:$A,'Progress%'!$B7,EDSR!$R:$R,"<="&G$6)*0.1+SUMIFS(EDSR!$J:$J,EDSR!$A:$A,'Progress%'!$B7,EDSR!$U:$U,"<="&G$6)*0.2)/$C7 -> 0 | H8: =IF($C7>0,SUMIFS(EDSR!$J:$J,EDSR!$A:$A,'Progress%'!$B7,EDSR!$L:$L,"<="&H$6)*0.5+SUMIFS(EDSR!$J:$J,EDSR!$A:$A,'Progress%'!$B7,EDSR!$O:$O,"<="&H$6)*0.2+SUMIFS(EDSR!$J:$J,EDSR!$A:$A,'Progress%'!$B7,EDSR!$R:$R,"<="&H$6)*0.1+SUMIFS(EDSR!$J:$J,EDSR!$A:$A,'Progress%'!$B7,EDSR!$U:$U,"<="&H$6)*0.2)/$C7 -> 0.005 | I8: =IF($C7>0,SUMIFS(EDSR!$J:$J,EDSR!$A:$A,'Progress%'!$B7,EDSR!$L:$L,"<="&I$6)*0.5+SUMIFS(EDSR!$J:$J,EDSR!$A:$A,'Progress%'!$B7,EDSR!$O:$O,"<="&I$6)*0.2+SUMIFS(EDSR!$J:$J,EDSR!$A:$A,'Progress%'!$B7,EDSR!$R:$R,"<="&I$6)*0.1+SUMIFS(EDSR!$J:$J,EDSR!$A:$A,'Progress%'!$B7,EDSR!$U:$U,"<="&I$6)*0.2)/$C7 -> 0.07 | J8: =IF($C7>0,SUMIFS(EDSR!$J:$J,EDSR!$A:$A,'Progress%'!$B7,EDSR!$L:$L,"<="&J$6)*0.5+SUMIFS(EDSR!$J:$J,EDSR!$A:$A,'Progress%'!$B7,EDSR!$O:$O,"<="&J$6)*0.2+SUMIFS(EDSR!$J:$J,EDSR!$A:$A,'Progress%'!$B7,EDSR!$R:$R,"<="&J$6)*0.1+SUMIFS(EDSR!$J:$J,EDSR!$A:$A,'Progress%'!$B7,EDSR!$U:$U,"<="&J$6)*0.2)/$C7 -> 0.07 | K8: =IF($C7>0,SUMIFS(EDSR!$J:$J,EDSR!$A:$A,'Progress%'!$B7,EDSR!$L:$L,"<="&K$6)*0.5+SUMIFS(EDSR!$J:$J,EDSR!$A:$A,'Progress%'!$B7,EDSR!$O:$O,"<="&K$6)*0.2+SUMIFS(EDSR!$J:$J,EDSR!$A:$A,'Progress%'!$B7,EDSR!$R:$R,"<="&K$6)*0.1+SUMIFS(EDSR!$J:$J,EDSR!$A:$A,'Progress%'!$B7,EDSR!$U:$U,"<="&K$6)*0.2)/$C7 -> 0.0975 | L8: =IF($C7>0,SUMIFS(EDSR!$J:$J,EDSR!$A:$A,'Progress%'!$B7,EDSR!$L:$L,"<="&L$6)*0.5+SUMIFS(EDSR!$J:$J,EDSR!$A:$A,'Progress%'!$B7,EDSR!$O:$O,"<="&L$6)*0.2+SUMIFS(EDSR!$J:$J,EDSR!$A:$A,'Progress%'!$B7,EDSR!$R:$R,"<="&L$6)*0.1+SUMIFS(EDSR!$J:$J,EDSR!$A:$A,'Progress%'!$B7,EDSR!$U:$U,"<="&L$6)*0.2)/$C7 -> 0.13 | M8: =IF($C7>0,SUMIFS(EDSR!$J:$J,EDSR!$A:$A,'Progress%'!$B7,EDSR!$L:$L,"<="&M$6)*0.5+SUMIFS(EDSR!$J:$J,EDSR!$A:$A,'Progress%'!$B7,EDSR!$O:$O,"<="&M$6)*0.2+SUMIFS(EDSR!$J:$J,EDSR!$A:$A,'Progress%'!$B7,EDSR!$R:$R,"<="&M$6)*0.1+SUMIFS(EDSR!$J:$J,EDSR!$A:$A,'Progress%'!$B7,EDSR!$U:$U,"<="&M$6)*0.2)/$C7 -> 0.14 | ... DM8: =IF($C7>0,SUMIFS(EDSR!$J:$J,EDSR!$A:$A,'Progress%'!$B7,EDSR!$L:$L,"<="&DM$6)*0.5+SUMIFS(EDSR!$J:$J,EDSR!$A:$A,'Progress%'!$B7,EDSR!$O:$O,"<="&DM$6)*0.2+SUMIFS(EDSR!$J:$J,EDSR!$A:$A,'Progress%'!$B7,EDSR!$R:$R,"<="&DM$6)*0.1+SUMIFS(EDSR!$J:$J,EDSR!$A:$A,'Progress%'!$B7,EDSR!$U:$U,"<="&DM$6)*0.2)/$C7 -> 0.9
A9: 9 | B9: ZAWTIKA Z1F TS | C9: 100 | D9: 1 | E9: Actual | F9: =IF($C9>0,SUMIFS(EDSR!$J:$J,EDSR!$A:$A,'Progress%'!$B9,EDSR!$M:$M,"<="&F$6)*0.5+SUMIFS(EDSR!$J:$J,EDSR!$A:$A,'Progress%'!$B9,EDSR!$P:$P,"<="&F$6)*0.2+SUMIFS(EDSR!$J:$J,EDSR!$A:$A,'Progress%'!$B9,EDSR!$S:$S,"<="&F$6)*0.1+SUMIFS(EDSR!$J:$J,EDSR!$A:$A,'Progress%'!$B9,EDSR!$V:$V,"<="&F$6)*0.2)/$C9 -> 0 | G9: =IF($C9>0,SUMIFS(EDSR!$J:$J,EDSR!$A:$A,'Progress%'!$B9,EDSR!$M:$M,"<="&G$6)*0.5+SUMIFS(EDSR!$J:$J,EDSR!$A:$A,'Progress%'!$B9,EDSR!$P:$P,"<="&G$6)*0.2+SUMIFS(EDSR!$J:$J,EDSR!$A:$A,'Progress%'!$B9,EDSR!$S:$S,"<="&G$6)*0.1+SUMIFS(EDSR!$J:$J,EDSR!$A:$A,'Progress%'!$B9,EDSR!$V:$V,"<="&G$6)*0.2)/$C9 -> 0 | H9: =IF($C9>0,SUMIFS(EDSR!$J:$J,EDSR!$A:$A,'Progress%'!$B9,EDSR!$M:$M,"<="&H$6)*0.5+SUMIFS(EDSR!$J:$J,EDSR!$A:$A,'Progress%'!$B9,EDSR!$P:$P,"<="&H$6)*0.2+SUMIFS(EDSR!$J:$J,EDSR!$A:$A,'Progress%'!$B9,EDSR!$S:$S,"<="&H$6)*0.1+SUMIFS(EDSR!$J:$J,EDSR!$A:$A,'Progress%'!$B9,EDSR!$V:$V,"<="&H$6)*0.2)/$C9 -> 0 | I9: =IF($C9>0,SUMIFS(EDSR!$J:$J,EDSR!$A:$A,'Progress%'!$B9,EDSR!$M:$M,"<="&I$6)*0.5+SUMIFS(EDSR!$J:$J,EDSR!$A:$A,'Progress%'!$B9,EDSR!$P:$P,"<="&I$6)*0.2+SUMIFS(EDSR!$J:$J,EDSR!$A:$A,'Progress%'!$B9,EDSR!$S:$S,"<="&I$6)*0.1+SUMIFS(EDSR!$J:$J,EDSR!$A:$A,'Progress%'!$B9,EDSR!$V:$V,"<="&I$6)*0.2)/$C9 -> 0.02 | J9: =IF($C9>0,SUMIFS(EDSR!$J:$J,EDSR!$A:$A,'Progress%'!$B9,EDSR!$M:$M,"<="&J$6)*0.5+SUMIFS(EDSR!$J:$J,EDSR!$A:$A,'Progress%'!$B9,EDSR!$P:$P,"<="&J$6)*0.2+SUMIFS(EDSR!$J:$J,EDSR!$A:$A,'Progress%'!$B9,EDSR!$S:$S,"<="&J$6)*0.1+SUMIFS(EDSR!$J:$J,EDSR!$A:$A,'Progress%'!$B9,EDSR!$V:$V,"<="&J$6)*0.2)/$C9 -> 0.02 | K9: =IF($C9>0,SUMIFS(EDSR!$J:$J,EDSR!$A:$A,'Progress%'!$B9,EDSR!$M:$M,"<="&K$6)*0.5+SUMIFS(EDSR!$J:$J,EDSR!$A:$A,'Progress%'!$B9,EDSR!$P:$P,"<="&K$6)*0.2+SUMIFS(EDSR!$J:$J,EDSR!$A:$A,'Progress%'!$B9,EDSR!$S:$S,"<="&K$6)*0.1+SUMIFS(EDSR!$J:$J,EDSR!$A:$A,'Progress%'!$B9,EDSR!$V:$V,"<="&K$6)*0.2)/$C9 -> 0.06125 | L9: =IF($C9>0,SUMIFS(EDSR!$J:$J,EDSR!$A:$A,'Progress%'!$B9,EDSR!$M:$M,"<="&L$6)*0.5+SUMIFS(EDSR!$J:$J,EDSR!$A:$A,'Progress%'!$B9,EDSR!$P:$P,"<="&L$6)*0.2+SUMIFS(EDSR!$J:$J,EDSR!$A:$A,'Progress%'!$B9,EDSR!$S:$S,"<="&L$6)*0.1+SUMIFS(EDSR!$J:$J,EDSR!$A:$A,'Progress%'!$B9,EDSR!$V:$V,"<="&L$6)*0.2)/$C9 -> 0.11125 | M9: =IF($C9>0,SUMIFS(EDSR!$J:$J,EDSR!$A:$A,'Progress%'!$B9,EDSR!$M:$M,"<="&M$6)*0.5+SUMIFS(EDSR!$J:$J,EDSR!$A:$A,'Progress%'!$B9,EDSR!$P:$P,"<="&M$6)*0.2+SUMIFS(EDSR!$J:$J,EDSR!$A:$A,'Progress%'!$B9,EDSR!$S:$S,"<="&M$6)*0.1+SUMIFS(EDSR!$J:$J,EDSR!$A:$A,'Progress%'!$B9,EDSR!$V:$V,"<="&M$6)*0.2)/$C9 -> 0.1345 | ... DM9: =IF($C9>0,SUMIFS(EDSR!$J:$J,EDSR!$A:$A,'Progress%'!$B9,EDSR!$M:$M,"<="&DM$6)*0.5+SUMIFS(EDSR!$J:$J,EDSR!$A:$A,'Progress%'!$B9,EDSR!$P:$P,"<="&DM$6)*0.2+SUMIFS(EDSR!$J:$J,EDSR!$A:$A,'Progress%'!$B9,EDSR!$S:$S,"<="&DM$6)*0.1+SUMIFS(EDSR!$J:$J,EDSR!$A:$A,'Progress%'!$B9,EDSR!$V:$V,"<="&DM$6)*0.2)/$C9 -> 0.65085
A10: 10

Sheet S-Curves
C4: Zawtika 1F
C5: Topsides Detailed Design
D10: 6 | E10: 7 | F10: 8 | G10: 9 | H10: 10 | I10: 11 | J10: 12 | K10: 13 | L10: 14 | M10: 15 | N10: 16 | O10: 17 | P10: 18 | Q10: 19 | R10: 20 | S10: 21 | T10: 22 | U10: 23 | V10: 24 | W10: 25 | X10: 26 | Y10: 27 | Z10: 28 | AA10: 29 | AB10: 30 | AC10: 31 | AD10: 32 | AE10: 33 | AF10: 34 | AG10: 35 | AH10: 36 | AI10: 37 | AJ10: 38 | AK10: 39 | AL10: 40 | AM10: 41 | AN10: 42 | AO10: 43 | AP10: 44 | AQ10: 45 | AR10: 46 | AS10: 47 | AT10: 48 | AU10: 49 | AV10: 50 | AW10: 51 | AX10: 52 | AY10: 53 | AZ10: 54 | BA10: 55 | BB10: 56 | BC10: 57 | BD10: 58 | BE10: 59 | BF10: 60 | BG10: 61 | BH10: 62 | BI10: 63 | BJ10: 64 | BK10: 65 | BL10: 66 | BM10: 67 | BN10: 68 | BO10: 69 | BP10: 70 | BQ10: 71 | BR10: 72 | BS10: 73 | BT10: 74 | BU10: 75 | BV10: 76 | BW10: 77 | BX10: 78 | BY10: 79 | BZ10: 80 | CA10: 81 | CB10: 82 | CC10: 83 | CD10: 84 | CE10: 85 | CF10: 86 | CG10: 87 | CH10: 88 | CI10: 89 | CJ10: 90 | CK10: 91 | CL10: 92 | CM10: 93 | CN10: 94 | CO10: 95 | CP10: 96 | CQ10: 97 | CR10: 98 | CS10: 99 | CT10: 100 | CU10: 101 | CV10: 102 | CW10: 103 | CX10: 104 | CY10: 105 | CZ10: 106 | DA10: 107 | DB10: 108 | DC10: 109 | DD10: 110 | DE10: 111
A11: ZAWTIKA Z1F TS | C11: Description | D11: 46101 | E11: 46108 | F11: 46115 | G11: 46122 | H11: 46129 | I11: 46136 | J11: 46143 | K11: 46150 | L11: 46157 | M11: 46164 | N11: 46171 | O11: 46178 | P11: 46185 | Q11: 46192 | R11: 46199 | S11: 46206 | T11: 46213 | U11: 46220 | V11: 46227 | W11: 46234 | X11: 46241 | Y11: 46248 | Z11: 46255 | AA11: 46262 | AB11: 46269 | AC11: 46276 | AD11: 46283 | AE11: 46290 | AF11: 46297 | AG11: 46304 | AH11: 46311 | AI11: 46318 | AJ11: 46325 | AK11: 46332 | AL11: 46339 | AM11: 46346 | AN11: 46353 | AO11: 46360 | AP11: 46367 | AQ11: 46374 | AR11: 46381 | AS11: 46388 | AT11: 46395 | AU11: 46402 | AV11: 46409 | AW11: 46416 | AX11: 46423 | AY11: 46430 | AZ11: 46437 | BA11: 46444 | BB11: 46451 | BC11: 46458 | BD11: 46465 | BE11: 46472 | BF11: 46479 | BG11: 46486 | BH11: 46493 | BI11: 46500 | BJ11: 46507 | BK11: 46514 | BL11: 46521 | BM11: 46528 | BN11: 46535 | BO11: 46542 | BP11: 46549 | BQ11: 46556 | BR11: 46563 | BS11: 46570 | BT11: 46577 | BU11: 46584 | BV11: 46591 | BW11: 46598 | BX11: 46605 | BY11: 46612 | BZ11: 46619 | CA11: 46626 | CB11: 46633 | CC11: 46640 | CD11: 46647 | CE11: 46654 | CF11: 46661 | CG11: 46668 | CH11: 46675 | CI11: 46682 | CJ11: 46689 | CK11: 46696 | CL11: 46703 | CM11: 46710 | CN11: 46717 | CO11: 46724 | CP11: 46731 | CQ11: 46738 | CR11: 46745 | CS11: 46752 | CT11: 46759 | CU11: 46766 | CV11: 46773 | CW11: 46780 | CX11: 46787 | CY11: 46794 | CZ11: 46801 | DA11: 46808 | DB11: 46815 | DC11: 46822 | DD11: 46829 | DE11: 46836
A12: =_xlfn.XLOOKUP(A11,Cut_Off!E:E,Cut_Off!F:F,0) -> 7 | C12: Cumulative Plan | D12: {=INDEX('Progress%'!$A$1:$DG$10,'S-Curves'!$A12,'S-Curves'!D$10)} -> 0 | E12: {=INDEX('Progress%'!$A$1:$DG$10,'S-Curves'!$A12,'S-Curves'!E$10)} -> 0 | F12: {=INDEX('Progress%'!$A$1:$DG$10,'S-Curves'!$A12,'S-Curves'!F$10)} -> 0.005 | G12: {=INDEX('Progress%'!$A$1:$DG$10,'S-Curves'!$A12,'S-Curves'!G$10)} -> 0.07 | H12: {=INDEX('Progress%'!$A$1:$DG$10,'S-Curves'!$A12,'S-Curves'!H$10)} -> 0.07 | I12: {=INDEX('Progress%'!$A$1:$DG$10,'S-Curves'!$A12,'S-Curves'!I$10)} -> 0.0975 | J12: {=INDEX('Progress%'!$A$1:$DG$10,'S-Curves'!$A12,'S-Curves'!J$10)} -> 0.13 | K12: {=INDEX('Progress%'!$A$1:$DG$10,'S-Curves'!$A12,'S-Curves'!K$10)} -> 0.14 | ... DE12: {=INDEX('Progress%'!$A$1:$DG$10,'S-Curves'!$A12,'S-Curves'!DE$10)} -> 0.9
A13: =A12+1 -> 8 | C13: Cumulative Forecast | D13: {=INDEX('Progress%'!$A$1:$DG$10,'S-Curves'!$A13,'S-Curves'!D$10)} -> 0 | E13: {=INDEX('Progress%'!$A$1:$DG$10,'S-Curves'!$A13,'S-Curves'!E$10)} -> 0 | F13: {=INDEX('Progress%'!$A$1:$DG$10,'S-Curves'!$A13,'S-Curves'!F$10)} -> 0.005 | G13: {=INDEX('Progress%'!$A$1:$DG$10,'S-Curves'!$A13,'S-Curves'!G$10)} -> 0.07 | H13: {=INDEX('Progress%'!$A$1:$DG$10,'S-Curves'!$A13,'S-Curves'!H$10)} -> 0.07 | I13: {=INDEX('Progress%'!$A$1:$DG$10,'S-Curves'!$A13,'S-Curves'!I$10)} -> 0.0975 | J13: {=INDEX('Progress%'!$A$1:$DG$10,'S-Curves'!$A13,'S-Curves'!J$10)} -> 0.13 | K13: {=INDEX('Progress%'!$A$1:$DG$10,'S-Curves'!$A13,'S-Curves'!K$10)} -> 0.14 | ... DE13: {=INDEX('Progress%'!$A$1:$DG$10,'S-Curves'!$A13,'S-Curves'!DE$10)} -> 0.9
A14: =A12+2 -> 9 | C14: Cumulative Actual | D14: {=INDEX('Progress%'!$A$1:$DG$10,'S-Curves'!$A14,'S-Curves'!D$10)} -> 0 | E14: {=INDEX('Progress%'!$A$1:$DG$10,'S-Curves'!$A14,'S-Curves'!E$10)} -> 0 | F14: {=INDEX('Progress%'!$A$1:$DG$10,'S-Curves'!$A14,'S-Curves'!F$10)} -> 0 | G14: {=INDEX('Progress%'!$A$1:$DG$10,'S-Curves'!$A14,'S-Curves'!G$10)} -> 0.02 | H14: {=INDEX('Progress%'!$A$1:$DG$10,'S-Curves'!$A14,'S-Curves'!H$10)} -> 0.02 | I14: {=INDEX('Progress%'!$A$1:$DG$10,'S-Curves'!$A14,'S-Curves'!I$10)} -> 0.06125 | J14: {=INDEX('Progress%'!$A$1:$DG$10,'S-Curves'!$A14,'S-Curves'!J$10)} -> 0.11125 | K14: {=INDEX('Progress%'!$A$1:$DG$10,'S-Curves'!$A14,'S-Curves'!K$10)} -> 0.1345 | ... X14: {=INDEX('Progress%'!$A$1:$DG$10,'S-Curves'!$A14,'S-Curves'!X$10)} -> 0.65085
C15: Period Plan (Early) | D15: =D12 -> 0 | E15: =E12-D12 -> 0 | F15: =F12-E12 -> 0.005 | G15: =G12-F12 -> 0.065 | H15: =H12-G12 -> 0 | I15: =I12-H12 -> 0.0275 | J15: =J12-I12 -> 0.0325 | K15: =K12-J12 -> 0.01 | L15: =L12-K12 -> 0.02575 | ... DE15: =DE12-DD12 -> 0
C16: Period Forecast | D16: =D13 -> 0 | E16: =E13-D13 -> 0 | F16: =F13-E13 -> 0.005 | G16: =G13-F13 -> 0.065 | H16: =H13-G13 -> 0 | I16: =I13-H13 -> 0.0275 | J16: =J13-I13 -> 0.0325 | K16: =K13-J13 -> 0.01 | L16: =L13-K13 -> 0.02575 | ... DE16: =DE13-DD13 -> 0
B17: Remaining Units | C17: Period Actual | D17: =D14 -> 0 | E17: =E14-D14 -> 0 | F17: =F14-E14 -> 0 | G17: =G14-F14 -> 0.02 | H17: =H14-G14 -> 0 | I17: =I14-H14 -> 0.04125 | J17: =J14-I14 -> 0.05 | K17: =K14-J14 -> 0.02325 | L17: =L14-K14 -> 0.02 | ... X17: =X14-W14 -> 0.02625

Sheet EDSR
A1: Cut-off Date | D1: 46241
A2: EDSR -TOPSIDES | K2: IFR (50%) | N2: IFA (20%) | Q2: AFC Sub (10%) | T2: AFC App. (20%) | X2: For Project control engineer follow up
A3: Facility | C3: Type | D3: Deliverable Title | E3: Description | F3: Plan [A] | G3: Forecast [B] | H3: Actual [C] | I3: Var. [C-A] | J3: Weight % | K3: Plan | L3: Forecast | M3: Actual | N3: Plan | O3: Forecast | P3: Actual | Q3: Plan | R3: Forecast | S3: Actual | T3: Plan | U3: Forecast | V3: Actual | X3: IFR (50%) | Y3: IFA (20%) | Z3: AFC Sub (10%) | AA3: AFC App. (20%)
A4: ZAWTIKA Z1F TS | B4: GENERIC | C4: RPT | D4: MM-ZTK-1F-GEN-STR-BOD-0001 | E4: STRUCTURAL DESIGN BASIS | F4: =(COUNTIFS(K4,"<="&$D$1)*50%)+(COUNTIFS(N4,"<="&$D$1)*20%)+(COUNTIFS(Q4,"<="&$D$1)*10%)+(COUNTIFS(T4,"<="&$D$1)*20%) -> 1 | G4: =(COUNTIFS(L4,"<="&$D$1)*50%)+(COUNTIFS(O4,"<="&$D$1)*20%)+(COUNTIFS(R4,"<="&$D$1)*10%)+(COUNTIFS(U4,"<="&$D$1)*20%) -> 1 | H4: =(COUNTIFS(M4,"<="&$D$1)*50%)+(COUNTIFS(P4,"<="&$D$1)*20%)+(COUNTIFS(S4,"<="&$D$1)*10%)+(COUNTIFS(V4,"<="&$D$1)*20%) -> 0.7 | I4: =H4-F4 -> -0.3 | J4: 1 | K4: 46115 | L4: =K4 -> 46115 | M4: 46136 | N4: =K4+42 -> 46157 | O4: =N4 -> 46157 | P4: 46227 | Q4: =N4+42 -> 46199 | R4: =Q4 -> 46199 | T4: =Q4+14 -> 46213 | U4: =T4 -> 46213 | X4: =IF(OR(M4<>""),"Completed", IF(L4="","",IF(L4<TODAY(),"Overdue", IF(AND(L4>=TODAY()-WEEKDAY(TODAY(),2)+1,L4<=TODAY()-WEEKDAY(TODAY(),2)+7),"Follow-This Week", IF(AND(L4>=TODAY()-WEEKDAY(TODAY(),2)+8,L4<=TODAY()-WEEKDAY(TODAY(),2)+14),"Follow-Next Week",""))))) -> Completed | Y4: =IF(OR(P4<>""),"Completed",IF(O4="","", IF(O4<TODAY(),"Overdue", IF(AND(O4>=TODAY()-WEEKDAY(TODAY(),2)+1,O4<=TODAY()-WEEKDAY(TODAY(),2)+7),"Follow-This Week", IF(AND(O4>=TODAY()-WEEKDAY(TODAY(),2)+8,O4<=TODAY()-WEEKDAY(TODAY(),2)+14),"Follow-Next Week",""))))) -> Completed | Z4: =IF(OR(S4<>""),"Completed",IF(R4="","", IF(R4<TODAY(),"Overdue", IF(AND(R4>=TODAY()-WEEKDAY(TODAY(),2)+1,R4<=TODAY()-WEEKDAY(TODAY(),2)+7),"Follow-This Week", IF(AND(R4>=TODAY()-WEEKDAY(TODAY(),2)+8,R4<=TODAY()-WEEKDAY(TODAY(),2)+14),"Follow-Next Week",""))))) -> Overdue | AA4: =IF(OR(V4<>""),"Completed",IF(U4="","", IF(U4<TODAY(),"Overdue", IF(AND(U4>=TODAY()-WEEKDAY(TODAY(),2)+1,U4<=TODAY()-WEEKDAY(TODAY(),2)+7),"Follow-This Week", IF(AND(U4>=TODAY()-WEEKDAY(TODAY(),2)+8,U4<=TODAY()-WEEKDAY(TODAY(),2)+14),"Follow-Next Week",""))))) -> Overdue
A5: ZAWTIKA Z1F TS | B5: GENERIC | C5: RPT | D5: MM-ZTK-1F-GEN-NVA-BOD-0001 | E5: NAVAL ARCHITECTURE DESIGN BASIS | F5: =(COUNTIFS(K5,"<="&$D$1)*50%)+(COUNTIFS(N5,"<="&$D$1)*20%)+(COUNTIFS(Q5,"<="&$D$1)*10%)+(COUNTIFS(T5,"<="&$D$1)*20%) -> 1 | G5: =(COUNTIFS(L5,"<="&$D$1)*50%)+(COUNTIFS(O5,"<="&$D$1)*20%)+(COUNTIFS(R5,"<="&$D$1)*10%)+(COUNTIFS(U5,"<="&$D$1)*20%) -> 1 | H5: =(COUNTIFS(M5,"<="&$D$1)*50%)+(COUNTIFS(P5,"<="&$D$1)*20%)+(COUNTIFS(S5,"<="&$D$1)*10%)+(COUNTIFS(V5,"<="&$D$1)*20%) -> 0.7 | I5: =H5-F5 -> -0.3 | J5: 1 | K5: 46122 | L5: =K5 -> 46122 | M5: 46135 | N5: =K5+42 -> 46164 | O5: =N5 -> 46164 | P5: 46230 | Q5: =N5+42 -> 46206 | R5: =Q5 -> 46206 | T5: =Q5+14 -> 46220 | U5: =T5 -> 46220 | X5: =IF(OR(M5<>""),"Completed", IF(L5="","",IF(L5<TODAY(),"Overdue", IF(AND(L5>=TODAY()-WEEKDAY(TODAY(),2)+1,L5<=TODAY()-WEEKDAY(TODAY(),2)+7),"Follow-This Week", IF(AND(L5>=TODAY()-WEEKDAY(TODAY(),2)+8,L5<=TODAY()-WEEKDAY(TODAY(),2)+14),"Follow-Next Week",""))))) -> Completed | Y5: =IF(OR(P5<>""),"Completed",IF(O5="","", IF(O5<TODAY(),"Overdue", IF(AND(O5>=TODAY()-WEEKDAY(TODAY(),2)+1,O5<=TODAY()-WEEKDAY(TODAY(),2)+7),"Follow-This Week", IF(AND(O5>=TODAY()-WEEKDAY(TODAY(),2)+8,O5<=TODAY()-WEEKDAY(TODAY(),2)+14),"Follow-Next Week",""))))) -> Completed | Z5: =IF(OR(S5<>""),"Completed",IF(R5="","", IF(R5<TODAY(),"Overdue", IF(AND(R5>=TODAY()-WEEKDAY(TODAY(),2)+1,R5<=TODAY()-WEEKDAY(TODAY(),2)+7),"Follow-This Week", IF(AND(R5>=TODAY()-WEEKDAY(TODAY(),2)+8,R5<=TODAY()-WEEKDAY(TODAY(),2)+14),"Follow-Next Week",""))))) -> Overdue | AA5: =IF(OR(V5<>""),"Completed",IF(U5="","", IF(U5<TODAY(),"Overdue", IF(AND(U5>=TODAY()-WEEKDAY(TODAY(),2)+1,U5<=TODAY()-WEEKDAY(TODAY(),2)+7),"Follow-This Week", IF(AND(U5>=TODAY()-WEEKDAY(TODAY(),2)+8,U5<=TODAY()-WEEKDAY(TODAY(),2)+14),"Follow-Next Week",""))))) -> Overdue
A6: ZAWTIKA Z1F TS | B6: GENERIC | C6: RPT | D6: MM-ZTK-1F-GEN-STR-PDR-0001 | E6: WEIGHT CONTROL PROCEDURE | F6: =(COUNTIFS(K6,"<="&$D$1)*50%)+(COUNTIFS(N6,"<="&$D$1)*20%)+(COUNTIFS(Q6,"<="&$D$1)*10%)+(COUNTIFS(T6,"<="&$D$1)*20%) -> 1 | G6: =(COUNTIFS(L6,"<="&$D$1)*50%)+(COUNTIFS(O6,"<="&$D$1)*20%)+(COUNTIFS(R6,"<="&$D$1)*10%)+(COUNTIFS(U6,"<="&$D$1)*20%) -> 1 | H6: =(COUNTIFS(M6,"<="&$D$1)*50%)+(COUNTIFS(P6,"<="&$D$1)*20%)+(COUNTIFS(S6,"<="&$D$1)*10%)+(COUNTIFS(V6,"<="&$D$1)*20%) -> 1 | I6: =H6-F6 -> 0 | J6: 1 | K6: 46122 | L6: =K6 -> 46122 | M6: 46122 | N6: =K6+42 -> 46164 | O6: =N6 -> 46164 | P6: 46171 | Q6: =N6+42 -> 46206 | R6: =Q6 -> 46206 | S6: 46171 | T6: =Q6+14 -> 46220 | U6: =T6 -> 46220 | V6: 46192 | X6: =IF(OR(M6<>""),"Completed", IF(L6="","",IF(L6<TODAY(),"Overdue", IF(AND(L6>=TODAY()-WEEKDAY(TODAY(),2)+1,L6<=TODAY()-WEEKDAY(TODAY(),2)+7),"Follow-This Week", IF(AND(L6>=TODAY()-WEEKDAY(TODAY(),2)+8,L6<=TODAY()-WEEKDAY(TODAY(),2)+14),"Follow-Next Week",""))))) -> Completed | Y6: =IF(OR(P6<>""),"Completed",IF(O6="","", IF(O6<TODAY(),"Overdue", IF(AND(O6>=TODAY()-WEEKDAY(TODAY(),2)+1,O6<=TODAY()-WEEKDAY(TODAY(),2)+7),"Follow-This Week", IF(AND(O6>=TODAY()-WEEKDAY(TODAY(),2)+8,O6<=TODAY()-WEEKDAY(TODAY(),2)+14),"Follow-Next Week",""))))) -> Completed | Z6: =IF(OR(S6<>""),"Completed",IF(R6="","", IF(R6<TODAY(),"Overdue", IF(AND(R6>=TODAY()-WEEKDAY(TODAY(),2)+1,R6<=TODAY()-WEEKDAY(TODAY(),2)+7),"Follow-This Week", IF(AND(R6>=TODAY()-WEEKDAY(TODAY(),2)+8,R6<=TODAY()-WEEKDAY(TODAY(),2)+14),"Follow-Next Week",""))))) -> Completed | AA6: =IF(OR(V6<>""),"Completed",IF(U6="","", IF(U6<TODAY(),"Overdue", IF(AND(U6>=TODAY()-WEEKDAY(TODAY(),2)+1,U6<=TODAY()-WEEKDAY(TODAY(),2)+7),"Follow-This Week", IF(AND(U6>=TODAY()-WEEKDAY(TODAY(),2)+8,U6<=TODAY()-WEEKDAY(TODAY(),2)+14),"Follow-Next Week",""))))) -> Completed
A7: ZAWTIKA Z1F TS | B7: ZWP-20 | C7: RPT | D7: MM-ZTK-1F-ZWP20-STR-CAL-0001 | E7: ZWP20- BASIC STRUCTURAL ENGINEERING VERIFICATION REPORT | X7: =IF(OR(M7<>""),"Completed", IF(L7="","",IF(L7<TODAY(),"Overdue", IF(AND(L7>=TODAY()-WEEKDAY(TODAY(),2)+1,L7<=TODAY()-WEEKDAY(TODAY(),2)+7),"Follow-This Week", IF(AND(L7>=TODAY()-WEEKDAY(TODAY(),2)+8,L7<=TODAY()-WEEKDAY(TODAY(),2)+14),"Follow-Next Week",""))))) | Y7: =IF(OR(P7<>""),"Completed",IF(O7="","", IF(O7<TODAY(),"Overdue", IF(AND(O7>=TODAY()-WEEKDAY(TODAY(),2)+1,O7<=TODAY()-WEEKDAY(TODAY(),2)+7),"Follow-This Week", IF(AND(O7>=TODAY()-WEEKDAY(TODAY(),2)+8,O7<=TODAY()-WEEKDAY(TODAY(),2)+14),"Follow-Next Week",""))))) | Z7: =IF(OR(S7<>""),"Completed",IF(R7="","", IF(R7<TODAY(),"Overdue", IF(AND(R7>=TODAY()-WEEKDAY(TODAY(),2)+1,R7<=TODAY()-WEEKDAY(TODAY(),2)+7),"Follow-This Week", IF(AND(R7>=TODAY()-WEEKDAY(TODAY(),2)+8,R7<=TODAY()-WEEKDAY(TODAY(),2)+14),"Follow-Next Week",""))))) | AA7: =IF(OR(V7<>""),"Completed",IF(U7="","", IF(U7<TODAY(),"Overdue", IF(AND(U7>=TODAY()-WEEKDAY(TODAY(),2)+1,U7<=TODAY()-WEEKDAY(TODAY(),2)+7),"Follow-This Week", IF(AND(U7>=TODAY()-WEEKDAY(TODAY(),2)+8,U7<=TODAY()-WEEKDAY(TODAY(),2)+14),"Follow-Next Week","")))))
A8: ZAWTIKA Z1F TS | B8: ZWP-21 | C8: RPT | D8: MM-ZTK-1F-ZWP21-STR-CAL-0001 | E8: ZWP21- BASIC STRUCTURAL ENGINEERING VERIFICATION REPORT | X8: =IF(OR(M8<>""),"Completed", IF(L8="","",IF(L8<TODAY(),"Overdue", IF(AND(L8>=TODAY()-WEEKDAY(TODAY(),2)+1,L8<=TODAY()-WEEKDAY(TODAY(),2)+7),"Follow-This Week", IF(AND(L8>=TODAY()-WEEKDAY(TODAY(),2)+8,L8<=TODAY()-WEEKDAY(TODAY(),2)+14),"Follow-Next Week",""))))) | Y8: =IF(OR(P8<>""),"Completed",IF(O8="","", IF(O8<TODAY(),"Overdue", IF(AND(O8>=TODAY()-WEEKDAY(TODAY(),2)+1,O8<=TODAY()-WEEKDAY(TODAY(),2)+7),"Follow-This Week", IF(AND(O8>=TODAY()-WEEKDAY(TODAY(),2)+8,O8<=TODAY()-WEEKDAY(TODAY(),2)+14),"Follow-Next Week",""))))) | Z8: =IF(OR(S8<>""),"Completed",IF(R8="","", IF(R8<TODAY(),"Overdue", IF(AND(R8>=TODAY()-WEEKDAY(TODAY(),2)+1,R8<=TODAY()-WEEKDAY(TODAY(),2)+7),"Follow-This Week", IF(AND(R8>=TODAY()-WEEKDAY(TODAY(),2)+8,R8<=TODAY()-WEEKDAY(TODAY(),2)+14),"Follow-Next Week",""))))) | AA8: =IF(OR(V8<>""),"Completed",IF(U8="","", IF(U8<TODAY(),"Overdue", IF(AND(U8>=TODAY()-WEEKDAY(TODAY(),2)+1,U8<=TODAY()-WEEKDAY(TODAY(),2)+7),"Follow-This Week", IF(AND(U8>=TODAY()-WEEKDAY(TODAY(),2)+8,U8<=TODAY()-WEEKDAY(TODAY(),2)+14),"Follow-Next Week","")))))
A9: ZAWTIKA Z1F TS | B9: ZWP-22 | C9: RPT | D9: MM-ZTK-1F-ZWP22-STR-CAL-0001 | E9: ZWP22- BASIC STRUCTURAL ENGINEERING VERIFICATION REPORT | X9: =IF(OR(M9<>""),"Completed", IF(L9="","",IF(L9<TODAY(),"Overdue", IF(AND(L9>=TODAY()-WEEKDAY(TODAY(),2)+1,L9<=TODAY()-WEEKDAY(TODAY(),2)+7),"Follow-This Week", IF(AND(L9>=TODAY()-WEEKDAY(TODAY(),2)+8,L9<=TODAY()-WEEKDAY(TODAY(),2)+14),"Follow-Next Week",""))))) | Y9: =IF(OR(P9<>""),"Completed",IF(O9="","", IF(O9<TODAY(),"Overdue", IF(AND(O9>=TODAY()-WEEKDAY(TODAY(),2)+1,O9<=TODAY()-WEEKDAY(TODAY(),2)+7),"Follow-This Week", IF(AND(O9>=TODAY()-WEEKDAY(TODAY(),2)+8,O9<=TODAY()-WEEKDAY(TODAY(),2)+14),"Follow-Next Week",""))))) | Z9: =IF(OR(S9<>""),"Completed",IF(R9="","", IF(R9<TODAY(),"Overdue", IF(AND(R9>=TODAY()-WEEKDAY(TODAY(),2)+1,R9<=TODAY()-WEEKDAY(TODAY(),2)+7),"Follow-This Week", IF(AND(R9>=TODAY()-WEEKDAY(TODAY(),2)+8,R9<=TODAY()-WEEKDAY(TODAY(),2)+14),"Follow-Next Week",""))))) | AA9: =IF(OR(V9<>""),"Completed",IF(U9="","", IF(U9<TODAY(),"Overdue", IF(AND(U9>=TODAY()-WEEKDAY(TODAY(),2)+1,U9<=TODAY()-WEEKDAY(TODAY(),2)+7),"Follow-This Week", IF(AND(U9>=TODAY()-WEEKDAY(TODAY(),2)+8,U9<=TODAY()-WEEKDAY(TODAY(),2)+14),"Follow-Next Week","")))))
A10: ZAWTIKA Z1F TS | B10: ZWP-23 | C10: RPT | D10: MM-ZTK-1F-ZWP23-STR-CAL-0001 | E10: ZWP23- BASIC STRUCTURAL ENGINEERING VERIFICATION REPORT | X10: =IF(OR(M10<>""),"Completed", IF(L10="","",IF(L10<TODAY(),"Overdue", IF(AND(L10>=TODAY()-WEEKDAY(TODAY(),2)+1,L10<=TODAY()-WEEKDAY(TODAY(),2)+7),"Follow-This Week", IF(AND(L10>=TODAY()-WEEKDAY(TODAY(),2)+8,L10<=TODAY()-WEEKDAY(TODAY(),2)+14),"Follow-Next Week",""))))) | Y10: =IF(OR(P10<>""),"Completed",IF(O10="","", IF(O10<TODAY(),"Overdue", IF(AND(O10>=TODAY()-WEEKDAY(TODAY(),2)+1,O10<=TODAY()-WEEKDAY(TODAY(),2)+7),"Follow-This Week", IF(AND(O10>=TODAY()-WEEKDAY(TODAY(),2)+8,O10<=TODAY()-WEEKDAY(TODAY(),2)+14),"Follow-Next Week",""))))) | Z10: =IF(OR(S10<>""),"Completed",IF(R10="","", IF(R10<TODAY(),"Overdue", IF(AND(R10>=TODAY()-WEEKDAY(TODAY(),2)+1,R10<=TODAY()-WEEKDAY(TODAY(),2)+7),"Follow-This Week", IF(AND(R10>=TODAY()-WEEKDAY(TODAY(),2)+8,R10<=TODAY()-WEEKDAY(TODAY(),2)+14),"Follow-Next Week",""))))) | AA10: =IF(OR(V10<>""),"Completed",IF(U10="","", IF(U10<TODAY(),"Overdue", IF(AND(U10>=TODAY()-WEEKDAY(TODAY(),2)+1,U10<=TODAY()-WEEKDAY(TODAY(),2)+7),"Follow-This Week", IF(AND(U10>=TODAY()-WEEKDAY(TODAY(),2)+8,U10<=TODAY()-WEEKDAY(TODAY(),2)+14),"Follow-Next Week","")))))
A11: ZAWTIKA Z1F TS | B11: GENERIC | C11: RPT | D11: MM-ZTK-1F-GEN-STR-CAL-0001 | E11: TOPSIDES- BASIC STRUCTURAL ENGINEERING VERIFICATION REPORT | F11: =(COUNTIFS(K11,"<="&$D$1)*50%)+(COUNTIFS(N11,"<="&$D$1)*20%)+(COUNTIFS(Q11,"<="&$D$1)*10%)+(COUNTIFS(T11,"<="&$D$1)*20%) -> 1 | G11: =(COUNTIFS(L11,"<="&$D$1)*50%)+(COUNTIFS(O11,"<="&$D$1)*20%)+(COUNTIFS(R11,"<="&$D$1)*10%)+(COUNTIFS(U11,"<="&$D$1)*20%) -> 1 | H11: =(COUNTIFS(M11,"<="&$D$1)*50%)+(COUNTIFS(P11,"<="&$D$1)*20%)+(COUNTIFS(S11,"<="&$D$1)*10%)+(COUNTIFS(V11,"<="&$D$1)*20%) -> 1 | I11: =H11-F11 -> 0 | J11: 8 | K11: 46122 | L11: =K11 -> 46122 | M11: 46142 | N11: =K11+42 -> 46164 | O11: =N11 -> 46164 | P11: 46183 | Q11: =N11+42 -> 46206 | R11: =Q11 -> 46206 | S11: 46183 | T11: =Q11+14 -> 46220 | U11: =T11 -> 46220 | V11: 46183 | X11: =IF(OR(M11<>""),"Completed", IF(L11="","",IF(L11<TODAY(),"Overdue", IF(AND(L11>=TODAY()-WEEKDAY(TODAY(),2)+1,L11<=TODAY()-WEEKDAY(TODAY(),2)+7),"Follow-This Week", IF(AND(L11>=TODAY()-WEEKDAY(TODAY(),2)+8,L11<=TODAY()-WEEKDAY(TODAY(),2)+14),"Follow-Next Week",""))))) -> Completed | Y11: =IF(OR(P11<>""),"Completed",IF(O11="","", IF(O11<TODAY(),"Overdue", IF(AND(O11>=TODAY()-WEEKDAY(TODAY(),2)+1,O11<=TODAY()-WEEKDAY(TODAY(),2)+7),"Follow-This Week", IF(AND(O11>=TODAY()-WEEKDAY(TODAY(),2)+8,O11<=TODAY()-WEEKDAY(TODAY(),2)+14),"Follow-Next Week",""))))) -> Completed | Z11: =IF(OR(S11<>""),"Completed",IF(R11="","", IF(R11<TODAY(),"Overdue", IF(AND(R11>=TODAY()-WEEKDAY(TODAY(),2)+1,R11<=TODAY()-WEEKDAY(TODAY(),2)+7),"Follow-This Week", IF(AND(R11>=TODAY()-WEEKDAY(TODAY(),2)+8,R11<=TODAY()-WEEKDAY(TODAY(),2)+14),"Follow-Next Week",""))))) -> Completed | AA11: =IF(OR(V11<>""),"Completed",IF(U11="","", IF(U11<TODAY(),"Overdue", IF(AND(U11>=TODAY()-WEEKDAY(TODAY(),2)+1,U11<=TODAY()-WEEKDAY(TODAY(),2)+7),"Follow-This Week", IF(AND(U11>=TODAY()-WEEKDAY(TODAY(),2)+8,U11<=TODAY()-WEEKDAY(TODAY(),2)+14),"Follow-Next Week",""))))) -> Completed
A12: ZAWTIKA Z1F TS | B12: GENERIC | C12: RPT | D12: MM-ZTK-1F-GEN-STR-WCR-1001 | E12: TOPSIDES WEIGHT CONTROL REPORT (UPDATE MONHLY) | F12: =(COUNTIFS(K12,"<="&$D$1)*50%)+(COUNTIFS(N12,"<="&$D$1)*20%)+(COUNTIFS(Q12,"<="&$D$1)*10%)+(COUNTIFS(T12,"<="&$D$1)*20%) -> 1 | G12: =(COUNTIFS(L12,"<="&$D$1)*50%)+(COUNTIFS(O12,"<="&$D$1)*20%)+(COUNTIFS(R12,"<="&$D$1)*10%)+(COUNTIFS(U12,"<="&$D$1)*20%) -> 1 | H12: =(COUNTIFS(M12,"<="&$D$1)*50%)+(COUNTIFS(P12,"<="&$D$1)*20%)+(COUNTIFS(S12,"<="&$D$1)*10%)+(COUNTIFS(V12,"<="&$D$1)*20%) -> 0.7 | I12: =H12-F12 -> -0.3 | J12: 2 | K12: 46136 | L12: =K12 -> 46136 | M12: 46136 | N12: =K12+42 -> 46178 | O12: =N12 -> 46178 | P12: 46188 | Q12: =N12+42 -> 46220 | R12: =Q12 -> 46220 | T12: =Q12+14 -> 46234 | U12: =T12 -> 46234 | X12: =IF(OR(M12<>""),"Completed", IF(L12="","",IF(L12<TODAY(),"Overdue", IF(AND(L12>=TODAY()-WEEKDAY(TODAY(),2)+1,L12<=TODAY()-WEEKDAY(TODAY(),2)+7),"Follow-This Week", IF(AND(L12>=TODAY()-WEEKDAY(TODAY(),2)+8,L12<=TODAY()-WEEKDAY(TODAY(),2)+14),"Follow-Next Week",""))))) -> Completed | Y12: =IF(OR(P12<>""),"Completed",IF(O12="","", IF(O12<TODAY(),"Overdue", IF(AND(O12>=TODAY()-WEEKDAY(TODAY(),2)+1,O12<=TODAY()-WEEKDAY(TODAY(),2)+7),"Follow-This Week", IF(AND(O12>=TODAY()-WEEKDAY(TODAY(),2)+8,O12<=TODAY()-WEEKDAY(TODAY(),2)+14),"Follow-Next Week",""))))) -> Completed | Z12: =IF(OR(S12<>""),"Completed",IF(R12="","", IF(R12<TODAY(),"Overdue", IF(AND(R12>=TODAY()-WEEKDAY(TODAY(),2)+1,R12<=TODAY()-WEEKDAY(TODAY(),2)+7),"Follow-This Week", IF(AND(R12>=TODAY()-WEEKDAY(TODAY(),2)+8,R12<=TODAY()-WEEKDAY(TODAY(),2)+14),"Follow-Next Week",""))))) -> Overdue | AA12: =IF(OR(V12<>""),"Completed",IF(U12="","", IF(U12<TODAY(),"Overdue", IF(AND(U12>=TODAY()-WEEKDAY(TODAY(),2)+1,U12<=TODAY()-WEEKDAY(TODAY(),2)+7),"Follow-This Week", IF(AND(U12>=TODAY()-WEEKDAY(TODAY(),2)+8,U12<=TODAY()-WEEKDAY(TODAY(),2)+14),"Follow-Next Week",""))))) -> Overdue
A13: ZAWTIKA Z1F TS | B13: GENERIC | C13: RPT | D13: MM-ZTK-1F-GEN-STR-CAL-1001 | E13: TOPSIDES COMPUTER MODELLING WITH VENT BOOM & LOAD FORMULATION | F13: =(COUNTIFS(K13,"<="&$D$1)*50%)+(COUNTIFS(N13,"<="&$D$1)*20%)+(COUNTIFS(Q13,"<="&$D$1)*10%)+(COUNTIFS(T13,"<="&$D$1)*20%) -> 1 | G13: =(COUNTIFS(L13,"<="&$D$1)*50%)+(COUNTIFS(O13,"<="&$D$1)*20%)+(COUNTIFS(R13,"<="&$D$1)*10%)+(COUNTIFS(U13,"<="&$D$1)*20%) -> 1 | H13: =(COUNTIFS(M13,"<="&$D$1)*50%)+(COUNTIFS(P13,"<="&$D$1)*20%)+(COUNTIFS(S13,"<="&$D$1)*10%)+(COUNTIFS(V13,"<="&$D$1)*20%) -> 0.7 | I13: =H13-F13 -> -0.3 | J13: 2 | K13: 46136 | L13: =K13 -> 46136 | M13: 46142 | N13: =K13+42 -> 46178 | O13: =N13 -> 46178 | P13: 46220 | Q13: =N13+42 -> 46220 | R13: =Q13 -> 46220 | T13: =Q13+14 -> 46234 | U13: =T13 -> 46234 | X13: =IF(OR(M13<>""),"Completed", IF(L13="","",IF(L13<TODAY(),"Overdue", IF(AND(L13>=TODAY()-WEEKDAY(TODAY(),2)+1,L13<=TODAY()-WEEKDAY(TODAY(),2)+7),"Follow-This Week", IF(AND(L13>=TODAY()-WEEKDAY(TODAY(),2)+8,L13<=TODAY()-WEEKDAY(TODAY(),2)+14),"Follow-Next Week",""))))) -> Completed | Y13: =IF(OR(P13<>""),"Completed",IF(O13="","", IF(O13<TODAY(),"Overdue", IF(AND(O13>=TODAY()-WEEKDAY(TODAY(),2)+1,O13<=TODAY()-WEEKDAY(TODAY(),2)+7),"Follow-This Week", IF(AND(O13>=TODAY()-WEEKDAY(TODAY(),2)+8,O13<=TODAY()-WEEKDAY(TODAY(),2)+14),"Follow-Next Week",""))))) -> Completed | Z13: =IF(OR(S13<>""),"Completed",IF(R13="","", IF(R13<TODAY(),"Overdue", IF(AND(R13>=TODAY()-WEEKDAY(TODAY(),2)+1,R13<=TODAY()-WEEKDAY(TODAY(),2)+7),"Follow-This Week", IF(AND(R13>=TODAY()-WEEKDAY(TODAY(),2)+8,R13<=TODAY()-WEEKDAY(TODAY(),2)+14),"Follow-Next Week",""))))) -> Overdue | AA13: =IF(OR(V13<>""),"Completed",IF(U13="","", IF(U13<TODAY(),"Overdue", IF(AND(U13>=TODAY()-WEEKDAY(TODAY(),2)+1,U13<=TODAY()-WEEKDAY(TODAY(),2)+7),"Follow-This Week", IF(AND(U13>=TODAY()-WEEKDAY(TODAY(),2)+8,U13<=TODAY()-WEEKDAY(TODAY(),2)+14),"Follow-Next Week",""))))) -> Overdue
A14: ZAWTIKA Z1F TS | B14: GENERIC | C14: RPT | D14: MM-ZTK-1F-GEN-STR-CAL-1011 | E14: TOPSIDES IN-PLACE ANALYSIS REPORT | F14: =(COUNTIFS(K14,"<="&$D$1)*50%)+(COUNTIFS(N14,"<="&$D$1)*20%)+(COUNTIFS(Q14,"<="&$D$1)*10%)+(COUNTIFS(T14,"<="&$D$1)*20%) -> 1 | G14: =(COUNTIFS(L14,"<="&$D$1)*50%)+(COUNTIFS(O14,"<="&$D$1)*20%)+(COUNTIFS(R14,"<="&$D$1)*10%)+(COUNTIFS(U14,"<="&$D$1)*20%) -> 1 | H14: =(COUNTIFS(M14,"<="&$D$1)*50%)+(COUNTIFS(P14,"<="&$D$1)*20%)+(COUNTIFS(S14,"<="&$D$1)*10%)+(COUNTIFS(V14,"<="&$D$1)*20%) -> 0.7 | I14: =H14-F14 -> -0.3 | J14: 2 | K14: 46143 | L14: =K14 -> 46143 | M14: 46161 | N14: =K14+42 -> 46185 | O14: =N14 -> 46185 | P14: 46234 | Q14: =N14+42 -> 46227 | R14: =Q14 -> 46227 | T14: =Q14+14 -> 46241 | U14: =T14 -> 46241 | X14: =IF(OR(M14<>""),"Completed", IF(L14="","",IF(L14<TODAY(),"Overdue", IF(AND(L14>=TODAY()-WEEKDAY(TODAY(),2)+1,L14<=TODAY()-WEEKDAY(TODAY(),2)+7),"Follow-This Week", IF(AND(L14>=TODAY()-WEEKDAY(TODAY(),2)+8,L14<=TODAY()-WEEKDAY(TODAY(),2)+14),"Follow-Next Week",""))))) -> Completed | Y14: =IF(OR(P14<>""),"Completed",IF(O14="","", IF(O14<TODAY(),"Overdue", IF(AND(O14>=TODAY()-WEEKDAY(TODAY(),2)+1,O14<=TODAY()-WEEKDAY(TODAY(),2)+7),"Follow-This Week", IF(AND(O14>=TODAY()-WEEKDAY(TODAY(),2)+8,O14<=TODAY()-WEEKDAY(TODAY(),2)+14),"Follow-Next Week",""))))) -> Completed | Z14: =IF(OR(S14<>""),"Completed",IF(R14="","", IF(R14<TODAY(),"Overdue", IF(AND(R14>=TODAY()-WEEKDAY(TODAY(),2)+1,R14<=TODAY()-WEEKDAY(TODAY(),2)+7),"Follow-This Week", IF(AND(R14>=TODAY()-WEEKDAY(TODAY(),2)+8,R14<=TODAY()-WEEKDAY(TODAY(),2)+14),"Follow-Next Week",""))))) -> Overdue | AA14: =IF(OR(V14<>""),"Completed",IF(U14="","", IF(U14<TODAY(),"Overdue", IF(AND(U14>=TODAY()-WEEKDAY(TODAY(),2)+1,U14<=TODAY()-WEEKDAY(TODAY(),2)+7),"Follow-This Week", IF(AND(U14>=TODAY()-WEEKDAY(TODAY(),2)+8,U14<=TODAY()-WEEKDAY(TODAY(),2)+14),"Follow-Next Week",""))))) -> Overdue
A15: ZAWTIKA Z1F TS | B15: GENERIC | C15: RPT | D15: MM-ZTK-1F-GEN-STR-CAL-1012 | E15: TOPSIDES LOADOUT ANALYSIS REPORT | F15: =(COUNTIFS(K15,"<="&$D$1)*50%)+(COUNTIFS(N15,"<="&$D$1)*20%)+(COUNTIFS(Q15,"<="&$D$1)*10%)+(COUNTIFS(T15,"<="&$D$1)*20%) -> 0.8 | G15: =(COUNTIFS(L15,"<="&$D$1)*50%)+(COUNTIFS(O15,"<="&$D$1)*20%)+(COUNTIFS(R15,"<="&$D$1)*10%)+(COUNTIFS(U15,"<="&$D$1)*20%) -> 0.8 | H15: =(COUNTIFS(M15,"<="&$D$1)*50%)+(COUNTIFS(P15,"<="&$D$1)*20%)+(COUNTIFS(S15,"<="&$D$1)*10%)+(COUNTIFS(V15,"<="&$D$1)*20%) -> 0.7 | I15: =H15-F15 -> -0.1 | J15: 2 | K15: 46150 | L15: =K15 -> 46150 | M15: 46155 | N15: =K15+42 -> 46192 | O15: =N15 -> 46192 | P15: 46226 | Q15: =N15+42 -> 46234 | R15: =Q15 -> 46234 | T15: =Q15+14 -> 46248 | U15: =T15 -> 46248 | X15: =IF(OR(M15<>""),"Completed", IF(L15="","",IF(L15<TODAY(),"Overdue", IF(AND(L15>=TODAY()-WEEKDAY(TODAY(),2)+1,L15<=TODAY()-WEEKDAY(TODAY(),2)+7),"Follow-This Week", IF(AND(L15>=TODAY()-WEEKDAY(TODAY(),2)+8,L15<=TODAY()-WEEKDAY(TODAY(),2)+14),"Follow-Next Week",""))))) -> Completed | Y15: =IF(OR(P15<>""),"Completed",IF(O15="","", IF(O15<TODAY(),"Overdue", IF(AND(O15>=TODAY()-WEEKDAY(TODAY(),2)+1,O15<=TODAY()-WEEKDAY(TODAY(),2)+7),"Follow-This Week", IF(AND(O15>=TODAY()-WEEKDAY(TODAY(),2)+8,O15<=TODAY()-WEEKDAY(TODAY(),2)+14),"Follow-Next Week",""))))) -> Completed | Z15: =IF(OR(S15<>""),"Completed",IF(R15="","", IF(R15<TODAY(),"Overdue", IF(AND(R15>=TODAY()-WEEKDAY(TODAY(),2)+1,R15<=TODAY()-WEEKDAY(TODAY(),2)+7),"Follow-This Week", IF(AND(R15>=TODAY()-WEEKDAY(TODAY(),2)+8,R15<=TODAY()-WEEKDAY(TODAY(),2)+14),"Follow-Next Week",""))))) -> Overdue | AA15: =IF(OR(V15<>""),"Completed",IF(U15="","", IF(U15<TODAY(),"Overdue", IF(AND(U15>=TODAY()-WEEKDAY(TODAY(),2)+1,U15<=TODAY()-WEEKDAY(TODAY(),2)+7),"Follow-This Week", IF(AND(U15>=TODAY()-WEEKDAY(TODAY(),2)+8,U15<=TODAY()-WEEKDAY(TODAY(),2)+14),"Follow-Next Week",""))))) -> Follow-Next Week
A16: ZAWTIKA Z1F TS | B16: GENERIC | C16: RPT | D16: MM-ZTK-1F-GEN-STR-CAL-1013 | E16: TOPSIDES TRANSPORATION ANALYSIS - SUPERSEDED | F16: =(COUNTIFS(K16,"<="&$D$1)*50%)+(COUNTIFS(N16,"<="&$D$1)*20%)+(COUNTIFS(Q16,"<="&$D$1)*10%)+(COUNTIFS(T16,"<="&$D$1)*20%) -> 0.7 | G16: =(COUNTIFS(L16,"<="&$D$1)*50%)+(COUNTIFS(O16,"<="&$D$1)*20%)+(COUNTIFS(R16,"<="&$D$1)*10%)+(COUNTIFS(U16,"<="&$D$1)*20%) -> 0.7 | H16: =(COUNTIFS(M16,"<="&$D$1)*50%)+(COUNTIFS(P16,"<="&$D$1)*20%)+(COUNTIFS(S16,"<="&$D$1)*10%)+(COUNTIFS(V16,"<="&$D$1)*20%) -> 1 | I16: =H16-F16 -> 0.3 | J16: 1.2 | K16: 46171 | L16: =K16 -> 46171 | M16: 46178 | N16: =K16+42 -> 46213 | O16: =N16 -> 46213 | P16: 46234 | Q16: =N16+42 -> 46255 | R16: =Q16 -> 46255 | S16: 46234 | T16: =Q16+14 -> 46269 | U16: =T16 -> 46269 | V16: 46234 | X16: =IF(OR(M16<>""),"Completed", IF(L16="","",IF(L16<TODAY(),"Overdue", IF(AND(L16>=TODAY()-WEEKDAY(TODAY(),2)+1,L16<=TODAY()-WEEKDAY(TODAY(),2)+7),"Follow-This Week", IF(AND(L16>=TODAY()-WEEKDAY(TODAY(),2)+8,L16<=TODAY()-WEEKDAY(TODAY(),2)+14),"Follow-Next Week",""))))) -> Completed | Y16: =IF(OR(P16<>""),"Completed",IF(O16="","", IF(O16<TODAY(),"Overdue", IF(AND(O16>=TODAY()-WEEKDAY(TODAY(),2)+1,O16<=TODAY()-WEEKDAY(TODAY(),2)+7),"Follow-This Week", IF(AND(O16>=TODAY()-WEEKDAY(TODAY(),2)+8,O16<=TODAY()-WEEKDAY(TODAY(),2)+14),"Follow-Next Week",""))))) -> Completed | Z16: =IF(OR(S16<>""),"Completed",IF(R16="","", IF(R16<TODAY(),"Overdue", IF(AND(R16>=TODAY()-WEEKDAY(TODAY(),2)+1,R16<=TODAY()-WEEKDAY(TODAY(),2)+7),"Follow-This Week", IF(AND(R16>=TODAY()-WEEKDAY(TODAY(),2)+8,R16<=TODAY()-WEEKDAY(TODAY(),2)+14),"Follow-Next Week",""))))) -> Completed | AA16: =IF(OR(V16<>""),"Completed",IF(U16="","", IF(U16<TODAY(),"Overdue", IF(AND(U16>=TODAY()-WEEKDAY(TODAY(),2)+1,U16<=TODAY()-WEEKDAY(TODAY(),2)+7),"Follow-This Week", IF(AND(U16>=TODAY()-WEEKDAY(TODAY(),2)+8,U16<=TODAY()-WEEKDAY(TODAY(),2)+14),"Follow-Next Week",""))))) -> Completed
A17: ZAWTIKA Z1F TS | B17: GENERIC | C17: RPT | D17: MM-ZTK-1F-GEN-STR-CAL-1013 | E17: TOPSIDES TRANSPORATION ANALYSIS REPORT - UPDATED TOW ROUTE | F17: =(COUNTIFS(K17,"<="&$D$1)*50%)+(COUNTIFS(N17,"<="&$D$1)*20%)+(COUNTIFS(Q17,"<="&$D$1)*10%)+(COUNTIFS(T17,"<="&$D$1)*20%) -> 0.7 | G17: =(COUNTIFS(L17,"<="&$D$1)*50%)+(COUNTIFS(O17,"<="&$D$1)*20%)+(COUNTIFS(R17,"<="&$D$1)*10%)+(COUNTIFS(U17,"<="&$D$1)*20%) -> 0.7 | H17: =(COUNTIFS(M17,"<="&$D$1)*50%)+(COUNTIFS(P17,"<="&$D$1)*20%)+(COUNTIFS(S17,"<="&$D$1)*10%)+(COUNTIFS(V17,"<="&$D$1)*20%) -> 0.5 | I17: =H17-F17 -> -0.2 | J17: 0.8 | K17: 46171 | L17: =K17 -> 46171 | M17: 46178 | N17: =K17+42 -> 46213 | O17: =N17 -> 46213 | Q17: =N17+42 -> 46255 | R17: =Q17 -> 46255 | T17: =Q17+14 -> 46269 | U17: =T17 -> 46269 | X17: =IF(OR(M17<>""),"Completed", IF(L17="","",IF(L17<TODAY(),"Overdue", IF(AND(L17>=TODAY()-WEEKDAY(TODAY(),2)+1,L17<=TODAY()-WEEKDAY(TODAY(),2)+7),"Follow-This Week", IF(AND(L17>=TODAY()-WEEKDAY(TODAY(),2)+8,L17<=TODAY()-WEEKDAY(TODAY(),2)+14),"Follow-Next Week",""))))) -> Completed | Y17: =IF(OR(P17<>""),"Completed",IF(O17="","", IF(O17<TODAY(),"Overdue", IF(AND(O17>=TODAY()-WEEKDAY(TODAY(),2)+1,O17<=TODAY()-WEEKDAY(TODAY(),2)+7),"Follow-This Week", IF(AND(O17>=TODAY()-WEEKDAY(TODAY(),2)+8,O17<=TODAY()-WEEKDAY(TODAY(),2)+14),"Follow-Next Week",""))))) -> Overdue | Z17: =IF(OR(S17<>""),"Completed",IF(R17="","", IF(R17<TODAY(),"Overdue", IF(AND(R17>=TODAY()-WEEKDAY(TODAY(),2)+1,R17<=TODAY()-WEEKDAY(TODAY(),2)+7),"Follow-This Week", IF(AND(R17>=TODAY()-WEEKDAY(TODAY(),2)+8,R17<=TODAY()-WEEKDAY(TODAY(),2)+14),"Follow-Next Week",""))))) | AA17: =IF(OR(V17<>""),"Completed",IF(U17="","", IF(U17<TODAY(),"Overdue", IF(AND(U17>=TODAY()-WEEKDAY(TODAY(),2)+1,U17<=TODAY()-WEEKDAY(TODAY(),2)+7),"Follow-This Week", IF(AND(U17>=TODAY()-WEEKDAY(TODAY(),2)+8,U17<=TODAY()-WEEKDAY(TODAY(),2)+14),"Follow-Next Week","")))))
A18: ZAWTIKA Z1F TS | B18: GENERIC | C18: RPT | D18: MM-ZTK-1F-GEN-STR-CAL-1014 | E18: TOPSIDES TRANSPORATION FATIGUE ANALYSIS REPORT - SUPERSEDED | F18: =(COUNTIFS(K18,"<="&$D$1)*50%)+(COUNTIFS(N18,"<="&$D$1)*20%)+(COUNTIFS(Q18,"<="&$D$1)*10%)+(COUNTIFS(T18,"<="&$D$1)*20%) -> 0.7 | G18: =(COUNTIFS(L18,"<="&$D$1)*50%)+(COUNTIFS(O18,"<="&$D$1)*20%)+(COUNTIFS(R18,"<="&$D$1)*10%)+(COUNTIFS(U18,"<="&$D$1)*20%) -> 0.7 | H18: =(COUNTIFS(M18,"<="&$D$1)*50%)+(COUNTIFS(P18,"<="&$D$1)*20%)+(COUNTIFS(S18,"<="&$D$1)*10%)+(COUNTIFS(V18,"<="&$D$1)*20%) -> 1 | I18: =H18-F18 -> 0.3 | J18: 1.2 | K18: 46185 | L18: =K18 -> 46185 | M18: 46205 | N18: =K18+42 -> 46227 | O18: =N18 -> 46227 | P18: 46234 | Q18: =N18+42 -> 46269 | R18: =Q18 -> 46269 | S18: 46234 | T18: =Q18+14 -> 46283 | U18: =T18 -> 46283 | V18: 46234 | X18: =IF(OR(M18<>""),"Completed", IF(L18="","",IF(L18<TODAY(),"Overdue", IF(AND(L18>=TODAY()-WEEKDAY(TODAY(),2)+1,L18<=TODAY()-WEEKDAY(TODAY(),2)+7),"Follow-This Week", IF(AND(L18>=TODAY()-WEEKDAY(TODAY(),2)+8,L18<=TODAY()-WEEKDAY(TODAY(),2)+14),"Follow-Next Week",""))))) -> Completed | Y18: =IF(OR(P18<>""),"Completed",IF(O18="","", IF(O18<TODAY(),"Overdue", IF(AND(O18>=TODAY()-WEEKDAY(TODAY(),2)+1,O18<=TODAY()-WEEKDAY(TODAY(),2)+7),"Follow-This Week", IF(AND(O18>=TODAY()-WEEKDAY(TODAY(),2)+8,O18<=TODAY()-WEEKDAY(TODAY(),2)+14),"Follow-Next Week",""))))) -> Completed | Z18: =IF(OR(S18<>""),"Completed",IF(R18="","", IF(R18<TODAY(),"Overdue", IF(AND(R18>=TODAY()-WEEKDAY(TODAY(),2)+1,R18<=TODAY()-WEEKDAY(TODAY(),2)+7),"Follow-This Week", IF(AND(R18>=TODAY()-WEEKDAY(TODAY(),2)+8,R18<=TODAY()-WEEKDAY(TODAY(),2)+14),"Follow-Next Week",""))))) -> Completed | AA18: =IF(OR(V18<>""),"Completed",IF(U18="","", IF(U18<TODAY(),"Overdue", IF(AND(U18>=TODAY()-WEEKDAY(TODAY(),2)+1,U18<=TODAY()-WEEKDAY(TODAY(),2)+7),"Follow-This Week", IF(AND(U18>=TODAY()-WEEKDAY(TODAY(),2)+8,U18<=TODAY()-WEEKDAY(TODAY(),2)+14),"Follow-Next Week",""))))) -> Completed
A19: ZAWTIKA Z1F TS | B19: GENERIC | C19: RPT | D19: MM-ZTK-1F-GEN-STR-CAL-1014 | E19: TOPSIDES TRANSPORATION FATIGUE ANALYSIS REPORT - UPDATED TOW ROUTE | F19: =(COUNTIFS(K19,"<="&$D$1)*50%)+(COUNTIFS(N19,"<="&$D$1)*20%)+(COUNTIFS(Q19,"<="&$D$1)*10%)+(COUNTIFS(T19,"<="&$D$1)*20%) -> 0.7 | G19: =(COUNTIFS(L19,"<="&$D$1)*50%)+(COUNTIFS(O19,"<="&$D$1)*20%)+(COUNTIFS(R19,"<="&$D$1)*10%)+(COUNTIFS(U19,"<="&$D$1)*20%) -> 0.7 | H19: =(COUNTIFS(M19,"<="&$D$1)*50%)+(COUNTIFS(P19,"<="&$D$1)*20%)+(COUNTIFS(S19,"<="&$D$1)*10%)+(COUNTIFS(V19,"<="&$D$1)*20%) -> 0.5 | I19: =H19-F19 -> -0.2 | J19: 0.8 | K19: 46185 | L19: =K19 -> 46185 | M19: 46205 | N19: 46218 | O19: =N19 -> 46218 | Q19: =N19+42 -> 46260 | R19: =Q19 -> 46260 | T19: =Q19+14 -> 46274 | U19: =T19 -> 46274 | X19: =IF(OR(M19<>""),"Completed", IF(L19="","",IF(L19<TODAY(),"Overdue", IF(AND(L19>=TODAY()-WEEKDAY(TODAY(),2)+1,L19<=TODAY()-WEEKDAY(TODAY(),2)+7),"Follow-This Week", IF(AND(L19>=TODAY()-WEEKDAY(TODAY(),2)+8,L19<=TODAY()-WEEKDAY(TODAY(),2)+14),"Follow-Next Week",""))))) -> Completed | Y19: =IF(OR(P19<>""),"Completed",IF(O19="","", IF(O19<TODAY(),"Overdue", IF(AND(O19>=TODAY()-WEEKDAY(TODAY(),2)+1,O19<=TODAY()-WEEKDAY(TODAY(),2)+7),"Follow-This Week", IF(AND(O19>=TODAY()-WEEKDAY(TODAY(),2)+8,O19<=TODAY()-WEEKDAY(TODAY(),2)+14),"Follow-Next Week",""))))) -> Overdue | Z19: =IF(OR(S19<>""),"Completed",IF(R19="","", IF(R19<TODAY(),"Overdue", IF(AND(R19>=TODAY()-WEEKDAY(TODAY(),2)+1,R19<=TODAY()-WEEKDAY(TODAY(),2)+7),"Follow-This Week", IF(AND(R19>=TODAY()-WEEKDAY(TODAY(),2)+8,R19<=TODAY()-WEEKDAY(TODAY(),2)+14),"Follow-Next Week",""))))) | AA19: =IF(OR(V19<>""),"Completed",IF(U19="","", IF(U19<TODAY(),"Overdue", IF(AND(U19>=TODAY()-WEEKDAY(TODAY(),2)+1,U19<=TODAY()-WEEKDAY(TODAY(),2)+7),"Follow-This Week", IF(AND(U19>=TODAY()-WEEKDAY(TODAY(),2)+8,U19<=TODAY()-WEEKDAY(TODAY(),2)+14),"Follow-Next Week","")))))
A20: ZAWTIKA Z1F TS | B20: GENERIC | C20: RPT | D20: MM-ZTK-1F-GEN-STR-CAL-1015 | E20: TOPSIDES LIFTING ANALYSIS REPORT | F20: =(COUNTIFS(K20,"<="&$D$1)*50%)+(COUNTIFS(N20,"<="&$D$1)*20%)+(COUNTIFS(Q20,"<="&$D$1)*10%)+(COUNTIFS(T20,"<="&$D$1)*20%) -> 0.7 | G20: =(COUNTIFS(L20,"<="&$D$1)*50%)+(COUNTIFS(O20,"<="&$D$1)*20%)+(COUNTIFS(R20,"<="&$D$1)*10%)+(COUNTIFS(U20,"<="&$D$1)*20%) -> 0.7 | H20: =(COUNTIFS(M20,"<="&$D$1)*50%)+(COUNTIFS(P20,"<="&$D$1)*20%)+(COUNTIFS(S20,"<="&$D$1)*10%)+(COUNTIFS(V20,"<="&$D$1)*20%) -> 0.7 | I20: =H20-F20 -> 0 | J20: 2 | K20: 46164 | L20: =K20 -> 46164 | M20: 46157 | N20: =K20+42 -> 46206 | O20: =N20 -> 46206 | P20: 46226 | Q20: =N20+42 -> 46248 | R20: =Q20 -> 46248 | T20: =Q20+14 -> 46262 | U20: =T20 -> 46262 | X20: =IF(OR(M20<>""),"Completed", IF(L20="","",IF(L20<TODAY(),"Overdue", IF(AND(L20>=TODAY()-WEEKDAY(TODAY(),2)+1,L20<=TODAY()-WEEKDAY(TODAY(),2)+7),"Follow-This Week", IF(AND(L20>=TODAY()-WEEKDAY(TODAY(),2)+8,L20<=TODAY()-WEEKDAY(TODAY(),2)+14),"Follow-Next Week",""))))) -> Completed | Y20: =IF(OR(P20<>""),"Completed",IF(O20="","", IF(O20<TODAY(),"Overdue", IF(AND(O20>=TODAY()-WEEKDAY(TODAY(),2)+1,O20<=TODAY()-WEEKDAY(TODAY(),2)+7),"Follow-This Week", IF(AND(O20>=TODAY()-WEEKDAY(TODAY(),2)+8,O20<=TODAY()-WEEKDAY(TODAY(),2)+14),"Follow-Next Week",""))))) -> Completed | Z20: =IF(OR(S20<>""),"Completed",IF(R20="","", IF(R20<TODAY(),"Overdue", IF(AND(R20>=TODAY()-WEEKDAY(TODAY(),2)+1,R20<=TODAY()-WEEKDAY(TODAY(),2)+7),"Follow-This Week", IF(AND(R20>=TODAY()-WEEKDAY(TODAY(),2)+8,R20<=TODAY()-WEEKDAY(TODAY(),2)+14),"Follow-Next Week",""))))) -> Follow-Next Week | AA20: =IF(OR(V20<>""),"Completed",IF(U20="","", IF(U20<TODAY(),"Overdue", IF(AND(U20>=TODAY()-WEEKDAY(TODAY(),2)+1,U20<=TODAY()-WEEKDAY(TODAY(),2)+7),"Follow-This Week", IF(AND(U20>=TODAY()-WEEKDAY(TODAY(),2)+8,U20<=TODAY()-WEEKDAY(TODAY(),2)+14),"Follow-Next Week","")))))
A21: ZAWTIKA Z1F TS | B21: GENERIC | C21: RPT | D21: MM-ZTK-1F-GEN-STR-CAL-1016 | E21: TOPSIDES MISCELLANEOUSD DESIGN REPORT | F21: =(COUNTIFS(K21,"<="&$D$1)*50%)+(COUNTIFS(N21,"<="&$D$1)*20%)+(COUNTIFS(Q21,"<="&$D$1)*10%)+(COUNTIFS(T21,"<="&$D$1)*20%) -> 0.7 | G21: =(COUNTIFS(L21,"<="&$D$1)*50%)+(COUNTIFS(O21,"<="&$D$1)*20%)+(COUNTIFS(R21,"<="&$D$1)*10%)+(COUNTIFS(U21,"<="&$D$1)*20%) -> 0.7 | H21: =(COUNTIFS(M21,"<="&$D$1)*50%)+(COUNTIFS(P21,"<="&$D$1)*20%)+(COUNTIFS(S21,"<="&$D$1)*10%)+(COUNTIFS(V21,"<="&$D$1)*20%) -> 0.5 | I21: =H21-F21 -> -0.2 | J21: 4.1 | K21: 46199 | L21: =K21 -> 46199 | M21: 46196 | N21: =K21+42 -> 46241 | O21: =N21 -> 46241 | Q21: =N21+42 -> 46283 | R21: =Q21 -> 46283 | T21: =Q21+14 -> 46297 | U21: =T21 -> 46297 | X21: =IF(OR(M21<>""),"Completed", IF(L21="","",IF(L21<TODAY(),"Overdue", IF(AND(L21>=TODAY()-WEEKDAY(TODAY(),2)+1,L21<=TODAY()-WEEKDAY(TODAY(),2)+7),"Follow-This Week", IF(AND(L21>=TODAY()-WEEKDAY(TODAY(),2)+8,L21<=TODAY()-WEEKDAY(TODAY(),2)+14),"Follow-Next Week",""))))) -> Completed | Y21: =IF(OR(P21<>""),"Completed",IF(O21="","", IF(O21<TODAY(),"Overdue", IF(AND(O21>=TODAY()-WEEKDAY(TODAY(),2)+1,O21<=TODAY()-WEEKDAY(TODAY(),2)+7),"Follow-This Week", IF(AND(O21>=TODAY()-WEEKDAY(TODAY(),2)+8,O21<=TODAY()-WEEKDAY(TODAY(),2)+14),"Follow-Next Week",""))))) -> Overdue | Z21: =IF(OR(S21<>""),"Completed",IF(R21="","", IF(R21<TODAY(),"Overdue", IF(AND(R21>=TODAY()-WEEKDAY(TODAY(),2)+1,R21<=TODAY()-WEEKDAY(TODAY(),2)+7),"Follow-This Week", IF(AND(R21>=TODAY()-WEEKDAY(TODAY(),2)+8,R21<=TODAY()-WEEKDAY(TODAY(),2)+14),"Follow-Next Week",""))))) | AA21: =IF(OR(V21<>""),"Completed",IF(U21="","", IF(U21<TODAY(),"Overdue", IF(AND(U21>=TODAY()-WEEKDAY(TODAY(),2)+1,U21<=TODAY()-WEEKDAY(TODAY(),2)+7),"Follow-This Week", IF(AND(U21>=TODAY()-WEEKDAY(TODAY(),2)+8,U21<=TODAY()-WEEKDAY(TODAY(),2)+14),"Follow-Next Week","")))))
A22: ZAWTIKA Z1F TS | B22: GENERIC | C22: RPT | D22: MM-ZTK-1F-GEN-STR-CAL-1017 | E22: TOPSIDE FINITE ELEMENT ANALYSIS FOR CASING SLOTS AND UNIHEAD SPACER REPORT | F22: =(COUNTIFS(K22,"<="&$D$1)*50%)+(COUNTIFS(N22,"<="&$D$1)*20%)+(COUNTIFS(Q22,"<="&$D$1)*10%)+(COUNTIFS(T22,"<="&$D$1)*20%) -> 0.5 | G22: =(COUNTIFS(L22,"<="&$D$1)*50%)+(COUNTIFS(O22,"<="&$D$1)*20%)+(COUNTIFS(R22,"<="&$D$1)*10%)+(COUNTIFS(U22,"<="&$D$1)*20%) -> 0.5 | H22: =(COUNTIFS(M22,"<="&$D$1)*50%)+(COUNTIFS(P22,"<="&$D$1)*20%)+(COUNTIFS(S22,"<="&$D$1)*10%)+(COUNTIFS(V22,"<="&$D$1)*20%) -> 0.7 | I22: =H22-F22 -> 0.2 | J22: 2 | K22: 46206 | L22: =K22 -> 46206 | M22: 46213 | N22: =K22+42 -> 46248 | O22: =N22 -> 46248 | P22: 46220 | Q22: =N22+42 -> 46290 | R22: =Q22 -> 46290 | T22: =Q22+14 -> 46304 | U22: =T22 -> 46304 | X22: =IF(OR(M22<>""),"Completed", IF(L22="","",IF(L22<TODAY(),"Overdue", IF(AND(L22>=TODAY()-WEEKDAY(TODAY(),2)+1,L22<=TODAY()-WEEKDAY(TODAY(),2)+7),"Follow-This Week", IF(AND(L22>=TODAY()-WEEKDAY(TODAY(),2)+8,L22<=TODAY()-WEEKDAY(TODAY(),2)+14),"Follow-Next Week",""))))) -> Completed | Y22: =IF(OR(P22<>""),"Completed",IF(O22="","", IF(O22<TODAY(),"Overdue", IF(AND(O22>=TODAY()-WEEKDAY(TODAY(),2)+1,O22<=TODAY()-WEEKDAY(TODAY(),2)+7),"Follow-This Week", IF(AND(O22>=TODAY()-WEEKDAY(TODAY(),2)+8,O22<=TODAY()-WEEKDAY(TODAY(),2)+14),"Follow-Next Week",""))))) -> Completed | Z22: =IF(OR(S22<>""),"Completed",IF(R22="","", IF(R22<TODAY(),"Overdue", IF(AND(R22>=TODAY()-WEEKDAY(TODAY(),2)+1,R22<=TODAY()-WEEKDAY(TODAY(),2)+7),"Follow-This Week", IF(AND(R22>=TODAY()-WEEKDAY(TODAY(),2)+8,R22<=TODAY()-WEEKDAY(TODAY(),2)+14),"Follow-Next Week",""))))) | AA22: =IF(OR(V22<>""),"Completed",IF(U22="","", IF(U22<TODAY(),"Overdue", IF(AND(U22>=TODAY()-WEEKDAY(TODAY(),2)+1,U22<=TODAY()-WEEKDAY(TODAY(),2)+7),"Follow-This Week", IF(AND(U22>=TODAY()-WEEKDAY(TODAY(),2)+8,U22<=TODAY()-WEEKDAY(TODAY(),2)+14),"Follow-Next Week","")))))
A23: ZAWTIKA Z1F TS | B23: ZWP-20 | C23: RPT | D23: MM-ZTK-1F-ZWP20-STR-CAL-2013 | E23: ZWP20 IN-SERVICE COMBINED TOPSIDES AND JACKET FATIGUE ANALYSIS REPORT - SUPERSEDED | F23: =(COUNTIFS(K23,"<="&$D$1)*50%)+(COUNTIFS(N23,"<="&$D$1)*20%)+(COUNTIFS(Q23,"<="&$D$1)*10%)+(COUNTIFS(T23,"<="&$D$1)*20%) -> 0.7 | G23: =(COUNTIFS(L23,"<="&$D$1)*50%)+(COUNTIFS(O23,"<="&$D$1)*20%)+(COUNTIFS(R23,"<="&$D$1)*10%)+(COUNTIFS(U23,"<="&$D$1)*20%) -> 0.7 | H23: =(COUNTIFS(M23,"<="&$D$1)*50%)+(COUNTIFS(P23,"<="&$D$1)*20%)+(COUNTIFS(S23,"<="&$D$1)*10%)+(COUNTIFS(V23,"<="&$D$1)*20%) -> 1 | I23: =H23-F23 -> 0.3 | J23: 1 | K23: 46199 | L23: =K23 -> 46199 | M23: 46220 | N23: =K23+42 -> 46241 | O23: =N23 -> 46241 | P23: 46220 | Q23: =N23+42 -> 46283 | R23: =Q23 -> 46283 | S23: 46220 | T23: =Q23+14 -> 46297 | U23: =T23 -> 46297 | V23: 46220 | X23: =IF(OR(M23<>""),"Completed", IF(L23="","",IF(L23<TODAY(),"Overdue", IF(AND(L23>=TODAY()-WEEKDAY(TODAY(),2)+1,L23<=TODAY()-WEEKDAY(TODAY(),2)+7),"Follow-This Week", IF(AND(L23>=TODAY()-WEEKDAY(TODAY(),2)+8,L23<=TODAY()-WEEKDAY(TODAY(),2)+14),"Follow-Next Week",""))))) -> Completed | Y23: =IF(OR(P23<>""),"Completed",IF(O23="","", IF(O23<TODAY(),"Overdue", IF(AND(O23>=TODAY()-WEEKDAY(TODAY(),2)+1,O23<=TODAY()-WEEKDAY(TODAY(),2)+7),"Follow-This Week", IF(AND(O23>=TODAY()-WEEKDAY(TODAY(),2)+8,O23<=TODAY()-WEEKDAY(TODAY(),2)+14),"Follow-Next Week",""))))) -> Completed | Z23: =IF(OR(S23<>""),"Completed",IF(R23="","", IF(R23<TODAY(),"Overdue", IF(AND(R23>=TODAY()-WEEKDAY(TODAY(),2)+1,R23<=TODAY()-WEEKDAY(TODAY(),2)+7),"Follow-This Week", IF(AND(R23>=TODAY()-WEEKDAY(TODAY(),2)+8,R23<=TODAY()-WEEKDAY(TODAY(),2)+14),"Follow-Next Week",""))))) -> Completed | AA23: =IF(OR(V23<>""),"Completed",IF(U23="","", IF(U23<TODAY(),"Overdue", IF(AND(U23>=TODAY()-WEEKDAY(TODAY(),2)+1,U23<=TODAY()-WEEKDAY(TODAY(),2)+7),"Follow-This Week", IF(AND(U23>=TODAY()-WEEKDAY(TODAY(),2)+8,U23<=TODAY()-WEEKDAY(TODAY(),2)+14),"Follow-Next Week",""))))) -> Completed
A24: ZAWTIKA Z1F TS | B24: ZWP-20 | C24: RPT | D24: MM-ZTK-1F-ZWP20-STR-CAL-2013 | E24: ZWP20 IN-SERVICE COMBINED TOPSIDES AND JACKET FATIGUE ANALYSIS REPORT - NEW WATER DEPTH | F24: =(COUNTIFS(K24,"<="&$D$1)*50%)+(COUNTIFS(N24,"<="&$D$1)*20%)+(COUNTIFS(Q24,"<="&$D$1)*10%)+(COUNTIFS(T24,"<="&$D$1)*20%) -> 0 | G24: =(COUNTIFS(L24,"<="&$D$1)*50%)+(COUNTIFS(O24,"<="&$D$1)*20%)+(COUNTIFS(R24,"<="&$D$1)*10%)+(COUNTIFS(U24,"<="&$D$1)*20%) -> 0 | H24: =(COUNTIFS(M24,"<="&$D$1)*50%)+(COUNTIFS(P24,"<="&$D$1)*20%)+(COUNTIFS(S24,"<="&$D$1)*10%)+(COUNTIFS(V24,"<="&$D$1)*20%) -> 0 | I24: =H24-F24 -> 0 | J24: 1 | K24: 46265 | L24: =K24 -> 46265 | N24: =K24+42 -> 46307 | O24: =N24 -> 46307 | Q24: =N24+42 -> 46349 | R24: =Q24 -> 46349 | T24: =Q24+14 -> 46363 | U24: =T24 -> 46363 | X24: =IF(OR(M24<>""),"Completed", IF(L24="","",IF(L24<TODAY(),"Overdue", IF(AND(L24>=TODAY()-WEEKDAY(TODAY(),2)+1,L24<=TODAY()-WEEKDAY(TODAY(),2)+7),"Follow-This Week", IF(AND(L24>=TODAY()-WEEKDAY(TODAY(),2)+8,L24<=TODAY()-WEEKDAY(TODAY(),2)+14),"Follow-Next Week",""))))) | Y24: =IF(OR(P24<>""),"Completed",IF(O24="","", IF(O24<TODAY(),"Overdue", IF(AND(O24>=TODAY()-WEEKDAY(TODAY(),2)+1,O24<=TODAY()-WEEKDAY(TODAY(),2)+7),"Follow-This Week", IF(AND(O24>=TODAY()-WEEKDAY(TODAY(),2)+8,O24<=TODAY()-WEEKDAY(TODAY(),2)+14),"Follow-Next Week",""))))) | Z24: =IF(OR(S24<>""),"Completed",IF(R24="","", IF(R24<TODAY(),"Overdue", IF(AND(R24>=TODAY()-WEEKDAY(TODAY(),2)+1,R24<=TODAY()-WEEKDAY(TODAY(),2)+7),"Follow-This Week", IF(AND(R24>=TODAY()-WEEKDAY(TODAY(),2)+8,R24<=TODAY()-WEEKDAY(TODAY(),2)+14),"Follow-Next Week",""))))) | AA24: =IF(OR(V24<>""),"Completed",IF(U24="","", IF(U24<TODAY(),"Overdue", IF(AND(U24>=TODAY()-WEEKDAY(TODAY(),2)+1,U24<=TODAY()-WEEKDAY(TODAY(),2)+7),"Follow-This Week", IF(AND(U24>=TODAY()-WEEKDAY(TODAY(),2)+8,U24<=TODAY()-WEEKDAY(TODAY(),2)+14),"Follow-Next Week","")))))
A25: ZAWTIKA Z1F TS | B25: ZWP-21 | C25: RPT | D25: MM-ZTK-1F-ZWP21-STR-CAL-2013 | E25: ZWP21 IN-SERVICE COMBINED TOPSIDES AND JACKET FATIGUE ANALYSIS REPORT - SUPERSEDED | F25: =(COUNTIFS(K25,"<="&$D$1)*50%)+(COUNTIFS(N25,"<="&$D$1)*20%)+(COUNTIFS(Q25,"<="&$D$1)*10%)+(COUNTIFS(T25,"<="&$D$1)*20%) -> 0.8 | G25: =(COUNTIFS(L25,"<="&$D$1)*50%)+(COUNTIFS(O25,"<="&$D$1)*20%)+(COUNTIFS(R25,"<="&$D$1)*10%)+(COUNTIFS(U25,"<="&$D$1)*20%) -> 0.8 | H25: =(COUNTIFS(M25,"<="&$D$1)*50%)+(COUNTIFS(P25,"<="&$D$1)*20%)+(COUNTIFS(S25,"<="&$D$1)*10%)+(COUNTIFS(V25,"<="&$D$1)*20%) -> 1 | I25: =H25-F25 -> 0.2 | J25: 1 | K25: 46157 | L25: =K25 -> 46157 | M25: 46188 | N25: =K25+42 -> 46199 | O25: =N25 -> 46199 | P25: 46220 | Q25: =N25+42 -> 46241 | R25: =Q25 -> 46241 | S25: 46220 | T25: =Q25+14 -> 46255 | U25: =T25 -> 46255 | V25: 46220 | X25: =IF(OR(M25<>""),"Completed", IF(L25="","",IF(L25<TODAY(),"Overdue", IF(AND(L25>=TODAY()-WEEKDAY(TODAY(),2)+1,L25<=TODAY()-WEEKDAY(TODAY(),2)+7),"Follow-This Week", IF(AND(L25>=TODAY()-WEEKDAY(TODAY(),2)+8,L25<=TODAY()-WEEKDAY(TODAY(),2)+14),"Follow-Next Week",""))))) -> Completed | Y25: =IF(OR(P25<>""),"Completed",IF(O25="","", IF(O25<TODAY(),"Overdue", IF(AND(O25>=TODAY()-WEEKDAY(TODAY(),2)+1,O25<=TODAY()-WEEKDAY(TODAY(),2)+7),"Follow-This Week", IF(AND(O25>=TODAY()-WEEKDAY(TODAY(),2)+8,O25<=TODAY()-WEEKDAY(TODAY(),2)+14),"Follow-Next Week",""))))) -> Completed | Z25: =IF(OR(S25<>""),"Completed",IF(R25="","", IF(R25<TODAY(),"Overdue", IF(AND(R25>=TODAY()-WEEKDAY(TODAY(),2)+1,R25<=TODAY()-WEEKDAY(TODAY(),2)+7),"Follow-This Week", IF(AND(R25>=TODAY()-WEEKDAY(TODAY(),2)+8,R25<=TODAY()-WEEKDAY(TODAY(),2)+14),"Follow-Next Week",""))))) -> Completed | AA25: =IF(OR(V25<>""),"Completed",IF(U25="","", IF(U25<TODAY(),"Overdue", IF(AND(U25>=TODAY()-WEEKDAY(TODAY(),2)+1,U25<=TODAY()-WEEKDAY(TODAY(),2)+7),"Follow-This Week", IF(AND(U25>=TODAY()-WEEKDAY(TODAY(),2)+8,U25<=TODAY()-WEEKDAY(TODAY(),2)+14),"Follow-Next Week",""))))) -> Completed
