Workbook
Name B: #REF!
Name Cutoff_Date: HLOOKUP(#REF!,#REF!,2,FALSE)
Name Cutoff_Date: HLOOKUP(#REF!,#REF!,2,FALSE)
Name G: #REF!
Name Graph_Select: 'S-Curves'!$A$7&" | "&'S-Curves'!$A$8&IF('S-Curves'!$A$7="Structural Engineering"," | "&'S-Curves'!$A$11,"")
Name Graph_Select: #REF!&" | "&#REF!&IF(#REF!="Structural Engineering"," | "&#REF!,"")
Name H: #REF!
Name I: #REF!

Sheet Progress Summary
F1: =N1-1 -> 34 | G1: =O1-1 -> 34 | H1: =P1-1 -> 34 | I1: =Q1-1 -> 34 | N1: =_xlfn.XLOOKUP(D3,'Progress%'!6:6,'Progress%'!1:1,0) -> 35 | O1: =_xlfn.XLOOKUP(D3,'Progress%'!6:6,'Progress%'!1:1,0) -> 35 | P1: =N1 -> 35 | Q1: =P1 -> 35
D2: Cut_Off Date
D3: 46304
D5: Table 8: Work Package 1B EPCI Jacket & Pile DDE Progress by Platform
D6: Descriptions | E6: % WT | F6: Last Week Cumulative (%) | J6: This Week Period (%) | N6: Cumulative up to this week (%)
F7: Plan [A] | G7: Forecast [B] | H7: Actual [C] | I7: Var. [C-A] | J7: Plan [A] | K7: Forecast [B] | L7: Actual [C] | M7: Var. [C-A] | N7: Plan [A] | O7: Forecast [B] | P7: Actual [C] | Q7: Var. [C-A]
A8: ='Progress%'!A7 -> 7 | B8: =A8+1 -> 8 | C8: =B8+1 -> 9 | D8: ZWP-21 | E8: 0.25 | F8: {=INDEX('Progress%'!$A$1:$CT$37,'Progress Summary'!$A8,'Progress Summary'!F$1)} -> 0.83356 | G8: {=INDEX('Progress%'!$A$1:$CT$37,'Progress Summary'!$B8,'Progress Summary'!G$1)} -> 0.83356 | H8: {=INDEX('Progress%'!$A$1:$CT$37,'Progress Summary'!$C8,'Progress Summary'!H$1)} -> 0.815996 | I8: =H8-F8 -> -0.017564 | J8: =N8-F8 -> 0.01964 | K8: =O8-G8 -> 0.01964 | L8: =P8-H8 -> 0.00674 | M8: =Q8-I8 -> -0.0129 | N8: {=INDEX('Progress%'!$A$1:$CT$37,'Progress Summary'!$A8,'Progress Summary'!N$1)} -> 0.8532 | O8: {=INDEX('Progress%'!$A$1:$CT$37,'Progress Summary'!$B8,'Progress Summary'!O$1)} -> 0.8532 | P8: {=INDEX('Progress%'!$A$1:$CT$37,'Progress Summary'!$C8,'Progress Summary'!P$1)} -> 0.822736 | Q8: =P8-N8 -> -0.030464
A9: ='Progress%'!A14 -> 14 | B9: =A9+1 -> 15 | C9: =B9+1 -> 16 | D9: ZWP-23 | E9: 0.25 | F9: {=INDEX('Progress%'!$A$1:$CT$37,'Progress Summary'!$A9,'Progress Summary'!F$1)} -> 0.75832 | G9: {=INDEX('Progress%'!$A$1:$CT$37,'Progress Summary'!$B9,'Progress Summary'!G$1)} -> 0.75832 | H9: {=INDEX('Progress%'!$A$1:$CT$37,'Progress Summary'!$C9,'Progress Summary'!H$1)} -> 0.748216 | I9: =H9-F9 -> -0.010104 | J9: =N9-F9 -> 0.018016 | K9: =O9-G9 -> 0.018016 | L9: =P9-H9 -> 0.021392 | M9: =Q9-I9 -> 0.003376 | N9: {=INDEX('Progress%'!$A$1:$CT$37,'Progress Summary'!$A9,'Progress Summary'!N$1)} -> 0.776336 | O9: {=INDEX('Progress%'!$A$1:$CT$37,'Progress Summary'!$B9,'Progress Summary'!O$1)} -> 0.776336 | P9: {=INDEX('Progress%'!$A$1:$CT$37,'Progress Summary'!$C9,'Progress Summary'!P$1)} -> 0.769608 | Q9: =P9-N9 -> -0.006728
A10: ='Progress%'!A21 -> 21 | B10: =A10+1 -> 22 | C10: =B10+1 -> 23 | D10: ZWP-22 | E10: 0.25 | F10: {=INDEX('Progress%'!$A$1:$CT$37,'Progress Summary'!$A10,'Progress Summary'!F$1)} -> 0.64806 | G10: {=INDEX('Progress%'!$A$1:$CT$37,'Progress Summary'!$B10,'Progress Summary'!G$1)} -> 0.64806 | H10: {=INDEX('Progress%'!$A$1:$CT$37,'Progress Summary'!$C10,'Progress Summary'!H$1)} -> 0.682232 | I10: =H10-F10 -> 0.034172 | J10: =N10-F10 -> 0.033956 | K10: =O10-G10 -> 0.033956 | L10: =P10-H10 -> 0.026516 | M10: =Q10-I10 -> -0.00744 | N10: {=INDEX('Progress%'!$A$1:$CT$37,'Progress Summary'!$A10,'Progress Summary'!N$1)} -> 0.682016 | O10: {=INDEX('Progress%'!$A$1:$CT$37,'Progress Summary'!$B10,'Progress Summary'!O$1)} -> 0.682016 | P10: {=INDEX('Progress%'!$A$1:$CT$37,'Progress Summary'!$C10,'Progress Summary'!P$1)} -> 0.708748 | Q10: =P10-N10 -> 0.026732
A11: ='Progress%'!A28 -> 28 | B11: =A11+1 -> 29 | C11: =B11+1 -> 30 | D11: ZWP-20 | E11: 0.25 | F11: {=INDEX('Progress%'!$A$1:$CT$37,'Progress Summary'!$A11,'Progress Summary'!F$1)} -> 0.524736 | G11: {=INDEX('Progress%'!$A$1:$CT$37,'Progress Summary'!$B11,'Progress Summary'!G$1)} -> 0.524736 | H11: {=INDEX('Progress%'!$A$1:$CT$37,'Progress Summary'!$C11,'Progress Summary'!H$1)} -> 0.648796 | I11: =H11-F11 -> 0.12406 | J11: =N11-F11 -> 0.018888 | K11: =O11-G11 -> 0.018888 | L11: =P11-H11 -> 0.028316 | M11: =Q11-I11 -> 0.009428 | N11: {=INDEX('Progress%'!$A$1:$CT$37,'Progress Summary'!$A11,'Progress Summary'!N$1)} -> 0.543624 | O11: {=INDEX('Progress%'!$A$1:$CT$37,'Progress Summary'!$B11,'Progress Summary'!O$1)} -> 0.543624 | P11: {=INDEX('Progress%'!$A$1:$CT$37,'Progress Summary'!$C11,'Progress Summary'!P$1)} -> 0.677112 | Q11: =P11-N11 -> 0.133488
D12: Overall Jacket & Pile DDE Progress | E12: =SUM(E8:E11) -> 1 | F12: =SUMPRODUCT($E8:$E11,F8:F11)/$E12 -> 0.691169 | G12: =SUMPRODUCT($E8:$E11,G8:G11)/$E12 -> 0.691169 | H12: =SUMPRODUCT($E8:$E11,H8:H11)/$E12 -> 0.72381 | I12: =SUMPRODUCT($E8:$E11,I8:I11)/$E12 -> 0.032641 | J12: =SUMPRODUCT($E8:$E11,J8:J11)/$E12 -> 0.022625 | K12: =SUMPRODUCT($E8:$E11,K8:K11)/$E12 -> 0.022625 | L12: =SUMPRODUCT($E8:$E11,L8:L11)/$E12 -> 0.020741 | M12: =SUMPRODUCT($E8:$E11,M8:M11)/$E12 -> -0.001884 | ... Q12: =SUMPRODUCT($E8:$E11,Q8:Q11)/$E12 -> 0.030757

Sheet Cut_Off
B2: 46101 | E2: Overall DDE Jacket | F2: ='Progress%'!A35 -> 35
B3: =B2+7 -> 46108 | E3: ZWP-23 Jacket | F3: ='Progress%'!A14 -> 14
B4: =B3+7 -> 46115 | E4: ZWP-20 Jacket | F4: ='Progress%'!A28 -> 28
B5: =B4+7 -> 46122 | E5: ZWP-21 Jacket | F5: ='Progress%'!A7 -> 7
B6: =B5+7 -> 46129 | E6: ZWP-22 Jacket | F6: ='Progress%'!A21 -> 21
B7: =B6+7 -> 46136
B8: =B7+7 -> 46143
B9: =B8+7 -> 46150
B10: =B9+7 -> 46157
B11: =B10+7 -> 46164
B12: =B11+7 -> 46171
B13: =B12+7 -> 46178
B14: =B13+7 -> 46185
B15: =B14+7 -> 46192
B16: =B15+7 -> 46199
B17: =B16+7 -> 46206
B18: =B17+7 -> 46213
... B104: =B103+7 -> 46815

Sheet Progress%
A1: 1 | B1: 2 | C1: 3 | D1: 4 | E1: 5 | F1: 6 | G1: 7 | H1: 8 | I1: 9 | J1: 10 | K1: 11 | L1: 12 | M1: 13 | N1: 14 | O1: 15 | P1: 16 | Q1: 17 | R1: 18 | S1: 19 | T1: 20 | U1: 21 | V1: 22 | W1: 23 | X1: 24 | Y1: 25 | Z1: 26 | AA1: 27 | AB1: 28 | AC1: 29 | AD1: 30 | AE1: 31 | AF1: 32 | AG1: 33 | AH1: 34 | AI1: 35 | AJ1: 36 | AK1: 37 | AL1: 38 | AM1: 39 | AN1: 40 | AO1: 41 | AP1: 42 | AQ1: 43 | AR1: 44 | AS1: 45 | AT1: 46 | AU1: 47 | AV1: 48 | AW1: 49 | AX1: 50 | AY1: 51 | AZ1: 52 | BA1: 53 | BB1: 54 | BC1: 55 | BD1: 56 | BE1: 57 | BF1: 58 | BG1: 59 | BH1: 60 | BI1: 61 | BJ1: 62 | BK1: 63 | BL1: 64 | BM1: 65 | BN1: 66 | BO1: 67 | BP1: 68 | BQ1: 69 | BR1: 70 | BS1: 71 | BT1: 72 | BU1: 73 | BV1: 74 | BW1: 75 | BX1: 76 | BY1: 77 | BZ1: 78 | CA1: 79 | CB1: 80 | CC1: 81 | CD1: 82 | CE1: 83 | CF1: 84 | CG1: 85 | CH1: 86 | CI1: 87 | CJ1: 88 | CK1: 89 | CL1: 90 | CM1: 91 | CN1: 92 | CO1: 93 | CP1: 94 | CQ1: 95 | CR1: 96 | CS1: 97 | CT1: 98
A2: 2 | D2: Cut_Off
A3: 3 | D3: ='Progress Summary'!D3 -> 46304
A4: 4
A5: 5 | B5: Scope | C5: Total WF | D5: WF% | E5: Jacket & Pile ZWP-21
A6: 6 | F6: 46101 | G6: =F6+7 -> 46108 | H6: =G6+7 -> 46115 | I6: =H6+7 -> 46122 | J6: =I6+7 -> 46129 | K6: =J6+7 -> 46136 | L6: =K6+7 -> 46143 | M6: =L6+7 -> 46150 | N6: =M6+7 -> 46157 | ... CT6: =CS6+7 -> 46745
A7: 7 | B7: ZWP-21 | C7: 25 | D7: 0.25 | E7: Plan | F7: =IF($C7>0,SUMIFS(EDSR!$I:$I,EDSR!$A:$A,'Progress%'!$B7,EDSR!$J:$J,"<="&F$6)*0.5+SUMIFS(EDSR!$I:$I,EDSR!$A:$A,'Progress%'!$B7,EDSR!$M:$M,"<="&F$6)*0.2+SUMIFS(EDSR!$I:$I,EDSR!$A:$A,'Progress%'!$B7,EDSR!$P:$P,"<="&F$6)*0.1+SUMIFS(EDSR!$I:$I,EDSR!$A:$A,'Progress%'!$B7,EDSR!$S:$S,"<="&F$6)*0.2)/$C7 -> 0 | G7: =IF($C7>0,SUMIFS(EDSR!$I:$I,EDSR!$A:$A,'Progress%'!$B7,EDSR!$J:$J,"<="&G$6)*0.5+SUMIFS(EDSR!$I:$I,EDSR!$A:$A,'Progress%'!$B7,EDSR!$M:$M,"<="&G$6)*0.2+SUMIFS(EDSR!$I:$I,EDSR!$A:$A,'Progress%'!$B7,EDSR!$P:$P,"<="&G$6)*0.1+SUMIFS(EDSR!$I:$I,EDSR!$A:$A,'Progress%'!$B7,EDSR!$S:$S,"<="&G$6)*0.2)/$C7 -> 0 | H7: =IF($C7>0,SUMIFS(EDSR!$I:$I,EDSR!$A:$A,'Progress%'!$B7,EDSR!$J:$J,"<="&H$6)*0.5+SUMIFS(EDSR!$I:$I,EDSR!$A:$A,'Progress%'!$B7,EDSR!$M:$M,"<="&H$6)*0.2+SUMIFS(EDSR!$I:$I,EDSR!$A:$A,'Progress%'!$B7,EDSR!$P:$P,"<="&H$6)*0.1+SUMIFS(EDSR!$I:$I,EDSR!$A:$A,'Progress%'!$B7,EDSR!$S:$S,"<="&H$6)*0.2)/$C7 -> 0.04 | I7: =IF($C7>0,SUMIFS(EDSR!$I:$I,EDSR!$A:$A,'Progress%'!$B7,EDSR!$J:$J,"<="&I$6)*0.5+SUMIFS(EDSR!$I:$I,EDSR!$A:$A,'Progress%'!$B7,EDSR!$M:$M,"<="&I$6)*0.2+SUMIFS(EDSR!$I:$I,EDSR!$A:$A,'Progress%'!$B7,EDSR!$P:$P,"<="&I$6)*0.1+SUMIFS(EDSR!$I:$I,EDSR!$A:$A,'Progress%'!$B7,EDSR!$S:$S,"<="&I$6)*0.2)/$C7 -> 0.058 | J7: =IF($C7>0,SUMIFS(EDSR!$I:$I,EDSR!$A:$A,'Progress%'!$B7,EDSR!$J:$J,"<="&J$6)*0.5+SUMIFS(EDSR!$I:$I,EDSR!$A:$A,'Progress%'!$B7,EDSR!$M:$M,"<="&J$6)*0.2+SUMIFS(EDSR!$I:$I,EDSR!$A:$A,'Progress%'!$B7,EDSR!$P:$P,"<="&J$6)*0.1+SUMIFS(EDSR!$I:$I,EDSR!$A:$A,'Progress%'!$B7,EDSR!$S:$S,"<="&J$6)*0.2)/$C7 -> 0.066 | K7: =IF($C7>0,SUMIFS(EDSR!$I:$I,EDSR!$A:$A,'Progress%'!$B7,EDSR!$J:$J,"<="&K$6)*0.5+SUMIFS(EDSR!$I:$I,EDSR!$A:$A,'Progress%'!$B7,EDSR!$M:$M,"<="&K$6)*0.2+SUMIFS(EDSR!$I:$I,EDSR!$A:$A,'Progress%'!$B7,EDSR!$P:$P,"<="&K$6)*0.1+SUMIFS(EDSR!$I:$I,EDSR!$A:$A,'Progress%'!$B7,EDSR!$S:$S,"<="&K$6)*0.2)/$C7 -> 0.076 | L7: =IF($C7>0,SUMIFS(EDSR!$I:$I,EDSR!$A:$A,'Progress%'!$B7,EDSR!$J:$J,"<="&L$6)*0.5+SUMIFS(EDSR!$I:$I,EDSR!$A:$A,'Progress%'!$B7,EDSR!$M:$M,"<="&L$6)*0.2+SUMIFS(EDSR!$I:$I,EDSR!$A:$A,'Progress%'!$B7,EDSR!$P:$P,"<="&L$6)*0.1+SUMIFS(EDSR!$I:$I,EDSR!$A:$A,'Progress%'!$B7,EDSR!$S:$S,"<="&L$6)*0.2)/$C7 -> 0.098 | M7: =IF($C7>0,SUMIFS(EDSR!$I:$I,EDSR!$A:$A,'Progress%'!$B7,EDSR!$J:$J,"<="&M$6)*0.5+SUMIFS(EDSR!$I:$I,EDSR!$A:$A,'Progress%'!$B7,EDSR!$M:$M,"<="&M$6)*0.2+SUMIFS(EDSR!$I:$I,EDSR!$A:$A,'Progress%'!$B7,EDSR!$P:$P,"<="&M$6)*0.1+SUMIFS(EDSR!$I:$I,EDSR!$A:$A,'Progress%'!$B7,EDSR!$S:$S,"<="&M$6)*0.2)/$C7 -> 0.1475 | ... CT7: =IF($C7>0,SUMIFS(EDSR!$I:$I,EDSR!$A:$A,'Progress%'!$B7,EDSR!$J:$J,"<="&CT$6)*0.5+SUMIFS(EDSR!$I:$I,EDSR!$A:$A,'Progress%'!$B7,EDSR!$M:$M,"<="&CT$6)*0.2+SUMIFS(EDSR!$I:$I,EDSR!$A:$A,'Progress%'!$B7,EDSR!$P:$P,"<="&CT$6)*0.1+SUMIFS(EDSR!$I:$I,EDSR!$A:$A,'Progress%'!$B7,EDSR!$S:$S,"<="&CT$6)*0.2)/$C7 -> 0.9
A8: 8 | B8: ZWP-21 | C8: 25 | D8: 0.25 | E8: Forecast | F8: =IF($C7>0,SUMIFS(EDSR!$I:$I,EDSR!$A:$A,'Progress%'!$B7,EDSR!$K:$K,"<="&F$6)*0.5+SUMIFS(EDSR!$I:$I,EDSR!$A:$A,'Progress%'!$B7,EDSR!$N:$N,"<="&F$6)*0.2+SUMIFS(EDSR!$I:$I,EDSR!$A:$A,'Progress%'!$B7,EDSR!$Q:$Q,"<="&F$6)*0.1+SUMIFS(EDSR!$I:$I,EDSR!$A:$A,'Progress%'!$B7,EDSR!$T:$T,"<="&F$6)*0.2)/$C7 -> 0 | G8: =IF($C7>0,SUMIFS(EDSR!$I:$I,EDSR!$A:$A,'Progress%'!$B7,EDSR!$K:$K,"<="&G$6)*0.5+SUMIFS(EDSR!$I:$I,EDSR!$A:$A,'Progress%'!$B7,EDSR!$N:$N,"<="&G$6)*0.2+SUMIFS(EDSR!$I:$I,EDSR!$A:$A,'Progress%'!$B7,EDSR!$Q:$Q,"<="&G$6)*0.1+SUMIFS(EDSR!$I:$I,EDSR!$A:$A,'Progress%'!$B7,EDSR!$T:$T,"<="&G$6)*0.2)/$C7 -> 0 | H8: =IF($C7>0,SUMIFS(EDSR!$I:$I,EDSR!$A:$A,'Progress%'!$B7,EDSR!$K:$K,"<="&H$6)*0.5+SUMIFS(EDSR!$I:$I,EDSR!$A:$A,'Progress%'!$B7,EDSR!$N:$N,"<="&H$6)*0.2+SUMIFS(EDSR!$I:$I,EDSR!$A:$A,'Progress%'!$B7,EDSR!$Q:$Q,"<="&H$6)*0.1+SUMIFS(EDSR!$I:$I,EDSR!$A:$A,'Progress%'!$B7,EDSR!$T:$T,"<="&H$6)*0.2)/$C7 -> 0.04 | I8: =IF($C7>0,SUMIFS(EDSR!$I:$I,EDSR!$A:$A,'Progress%'!$B7,EDSR!$K:$K,"<="&I$6)*0.5+SUMIFS(EDSR!$I:$I,EDSR!$A:$A,'Progress%'!$B7,EDSR!$N:$N,"<="&I$6)*0.2+SUMIFS(EDSR!$I:$I,EDSR!$A:$A,'Progress%'!$B7,EDSR!$Q:$Q,"<="&I$6)*0.1+SUMIFS(EDSR!$I:$I,EDSR!$A:$A,'Progress%'!$B7,EDSR!$T:$T,"<="&I$6)*0.2)/$C7 -> 0.058 | J8: =IF($C7>0,SUMIFS(EDSR!$I:$I,EDSR!$A:$A,'Progress%'!$B7,EDSR!$K:$K,"<="&J$6)*0.5+SUMIFS(EDSR!$I:$I,EDSR!$A:$A,'Progress%'!$B7,EDSR!$N:$N,"<="&J$6)*0.2+SUMIFS(EDSR!$I:$I,EDSR!$A:$A,'Progress%'!$B7,EDSR!$Q:$Q,"<="&J$6)*0.1+SUMIFS(EDSR!$I:$I,EDSR!$A:$A,'Progress%'!$B7,EDSR!$T:$T,"<="&J$6)*0.2)/$C7 -> 0.066 | K8: =IF($C7>0,SUMIFS(EDSR!$I:$I,EDSR!$A:$A,'Progress%'!$B7,EDSR!$K:$K,"<="&K$6)*0.5+SUMIFS(EDSR!$I:$I,EDSR!$A:$A,'Progress%'!$B7,EDSR!$N:$N,"<="&K$6)*0.2+SUMIFS(EDSR!$I:$I,EDSR!$A:$A,'Progress%'!$B7,EDSR!$Q:$Q,"<="&K$6)*0.1+SUMIFS(EDSR!$I:$I,EDSR!$A:$A,'Progress%'!$B7,EDSR!$T:$T,"<="&K$6)*0.2)/$C7 -> 0.076 | L8: =IF($C7>0,SUMIFS(EDSR!$I:$I,EDSR!$A:$A,'Progress%'!$B7,EDSR!$K:$K,"<="&L$6)*0.5+SUMIFS(EDSR!$I:$I,EDSR!$A:$A,'Progress%'!$B7,EDSR!$N:$N,"<="&L$6)*0.2+SUMIFS(EDSR!$I:$I,EDSR!$A:$A,'Progress%'!$B7,EDSR!$Q:$Q,"<="&L$6)*0.1+SUMIFS(EDSR!$I:$I,EDSR!$A:$A,'Progress%'!$B7,EDSR!$T:$T,"<="&L$6)*0.2)/$C7 -> 0.098 | M8: =IF($C7>0,SUMIFS(EDSR!$I:$I,EDSR!$A:$A,'Progress%'!$B7,EDSR!$K:$K,"<="&M$6)*0.5+SUMIFS(EDSR!$I:$I,EDSR!$A:$A,'Progress%'!$B7,EDSR!$N:$N,"<="&M$6)*0.2+SUMIFS(EDSR!$I:$I,EDSR!$A:$A,'Progress%'!$B7,EDSR!$Q:$Q,"<="&M$6)*0.1+SUMIFS(EDSR!$I:$I,EDSR!$A:$A,'Progress%'!$B7,EDSR!$T:$T,"<="&M$6)*0.2)/$C7 -> 0.1475 | ... CT8: =IF($C7>0,SUMIFS(EDSR!$I:$I,EDSR!$A:$A,'Progress%'!$B7,EDSR!$K:$K,"<="&CT$6)*0.5+SUMIFS(EDSR!$I:$I,EDSR!$A:$A,'Progress%'!$B7,EDSR!$N:$N,"<="&CT$6)*0.2+SUMIFS(EDSR!$I:$I,EDSR!$A:$A,'Progress%'!$B7,EDSR!$Q:$Q,"<="&CT$6)*0.1+SUMIFS(EDSR!$I:$I,EDSR!$A:$A,'Progress%'!$B7,EDSR!$T:$T,"<="&CT$6)*0.2)/$C7 -> 0.9
A9: 9 | B9: ZWP-21 | C9: 25 | D9: 0.25 | E9: Actual | F9: =IF($C9>0,SUMIFS(EDSR!$I:$I,EDSR!$A:$A,'Progress%'!$B9,EDSR!$L:$L,"<="&F$6)*0.5+SUMIFS(EDSR!$I:$I,EDSR!$A:$A,'Progress%'!$B9,EDSR!$O:$O,"<="&F$6)*0.2+SUMIFS(EDSR!$I:$I,EDSR!$A:$A,'Progress%'!$B9,EDSR!$R:$R,"<="&F$6)*0.1+SUMIFS(EDSR!$I:$I,EDSR!$A:$A,'Progress%'!$B9,EDSR!$U:$U,"<="&F$6)*0.2)/$C9 -> 0 | G9: =IF($C9>0,SUMIFS(EDSR!$I:$I,EDSR!$A:$A,'Progress%'!$B9,EDSR!$L:$L,"<="&G$6)*0.5+SUMIFS(EDSR!$I:$I,EDSR!$A:$A,'Progress%'!$B9,EDSR!$O:$O,"<="&G$6)*0.2+SUMIFS(EDSR!$I:$I,EDSR!$A:$A,'Progress%'!$B9,EDSR!$R:$R,"<="&G$6)*0.1+SUMIFS(EDSR!$I:$I,EDSR!$A:$A,'Progress%'!$B9,EDSR!$U:$U,"<="&G$6)*0.2)/$C9 -> 0 | H9: =IF($C9>0,SUMIFS(EDSR!$I:$I,EDSR!$A:$A,'Progress%'!$B9,EDSR!$L:$L,"<="&H$6)*0.5+SUMIFS(EDSR!$I:$I,EDSR!$A:$A,'Progress%'!$B9,EDSR!$O:$O,"<="&H$6)*0.2+SUMIFS(EDSR!$I:$I,EDSR!$A:$A,'Progress%'!$B9,EDSR!$R:$R,"<="&H$6)*0.1+SUMIFS(EDSR!$I:$I,EDSR!$A:$A,'Progress%'!$B9,EDSR!$U:$U,"<="&H$6)*0.2)/$C9 -> 0.028 | I9: =IF($C9>0,SUMIFS(EDSR!$I:$I,EDSR!$A:$A,'Progress%'!$B9,EDSR!$L:$L,"<="&I$6)*0.5+SUMIFS(EDSR!$I:$I,EDSR!$A:$A,'Progress%'!$B9,EDSR!$O:$O,"<="&I$6)*0.2+SUMIFS(EDSR!$I:$I,EDSR!$A:$A,'Progress%'!$B9,EDSR!$R:$R,"<="&I$6)*0.1+SUMIFS(EDSR!$I:$I,EDSR!$A:$A,'Progress%'!$B9,EDSR!$U:$U,"<="&I$6)*0.2)/$C9 -> 0.048 | J9: =IF($C9>0,SUMIFS(EDSR!$I:$I,EDSR!$A:$A,'Progress%'!$B9,EDSR!$L:$L,"<="&J$6)*0.5+SUMIFS(EDSR!$I:$I,EDSR!$A:$A,'Progress%'!$B9,EDSR!$O:$O,"<="&J$6)*0.2+SUMIFS(EDSR!$I:$I,EDSR!$A:$A,'Progress%'!$B9,EDSR!$R:$R,"<="&J$6)*0.1+SUMIFS(EDSR!$I:$I,EDSR!$A:$A,'Progress%'!$B9,EDSR!$U:$U,"<="&J$6)*0.2)/$C9 -> 0.048 | K9: =IF($C9>0,SUMIFS(EDSR!$I:$I,EDSR!$A:$A,'Progress%'!$B9,EDSR!$L:$L,"<="&K$6)*0.5+SUMIFS(EDSR!$I:$I,EDSR!$A:$A,'Progress%'!$B9,EDSR!$O:$O,"<="&K$6)*0.2+SUMIFS(EDSR!$I:$I,EDSR!$A:$A,'Progress%'!$B9,EDSR!$R:$R,"<="&K$6)*0.1+SUMIFS(EDSR!$I:$I,EDSR!$A:$A,'Progress%'!$B9,EDSR!$U:$U,"<="&K$6)*0.2)/$C9 -> 0.08466 | L9: =IF($C9>0,SUMIFS(EDSR!$I:$I,EDSR!$A:$A,'Progress%'!$B9,EDSR!$L:$L,"<="&L$6)*0.5+SUMIFS(EDSR!$I:$I,EDSR!$A:$A,'Progress%'!$B9,EDSR!$O:$O,"<="&L$6)*0.2+SUMIFS(EDSR!$I:$I,EDSR!$A:$A,'Progress%'!$B9,EDSR!$R:$R,"<="&L$6)*0.1+SUMIFS(EDSR!$I:$I,EDSR!$A:$A,'Progress%'!$B9,EDSR!$U:$U,"<="&L$6)*0.2)/$C9 -> 0.14006 | M9: =IF($C9>0,SUMIFS(EDSR!$I:$I,EDSR!$A:$A,'Progress%'!$B9,EDSR!$L:$L,"<="&M$6)*0.5+SUMIFS(EDSR!$I:$I,EDSR!$A:$A,'Progress%'!$B9,EDSR!$O:$O,"<="&M$6)*0.2+SUMIFS(EDSR!$I:$I,EDSR!$A:$A,'Progress%'!$B9,EDSR!$R:$R,"<="&M$6)*0.1+SUMIFS(EDSR!$I:$I,EDSR!$A:$A,'Progress%'!$B9,EDSR!$U:$U,"<="&M$6)*0.2)/$C9 -> 0.15206 | ... CT9: =IF($C9>0,SUMIFS(EDSR!$I:$I,EDSR!$A:$A,'Progress%'!$B9,EDSR!$L:$L,"<="&CT$6)*0.5+SUMIFS(EDSR!$I:$I,EDSR!$A:$A,'Progress%'!$B9,EDSR!$O:$O,"<="&CT$6)*0.2+SUMIFS(EDSR!$I:$I,EDSR!$A:$A,'Progress%'!$B9,EDSR!$R:$R,"<="&CT$6)*0.1+SUMIFS(EDSR!$I:$I,EDSR!$A:$A,'Progress%'!$B9,EDSR!$U:$U,"<="&CT$6)*0.2)/$C9 -> 0.822736
A10: 10
A11: 11
A12: 12 | B12: Scope | C12: Total WF | D12: WF% | E12: Jacket & Pile ZWP-23
A13: 13 | F13: 46101 | G13: =F13+7 -> 46108 | H13: =G13+7 -> 46115 | I13: =H13+7 -> 46122 | J13: =I13+7 -> 46129 | K13: =J13+7 -> 46136 | L13: =K13+7 -> 46143 | M13: =L13+7 -> 46150 | N13: =M13+7 -> 46157 | ... CT13: =CS13+7 -> 46745
A14: 14 | B14: ZWP-23 | C14: 25 | D14: 0.25 | E14: Plan | F14: =IF($C14>0,SUMIFS(EDSR!$I:$I,EDSR!$A:$A,'Progress%'!$B14,EDSR!$J:$J,"<="&F$6)*0.5+SUMIFS(EDSR!$I:$I,EDSR!$A:$A,'Progress%'!$B14,EDSR!$M:$M,"<="&F$6)*0.2+SUMIFS(EDSR!$I:$I,EDSR!$A:$A,'Progress%'!$B14,EDSR!$P:$P,"<="&F$6)*0.1+SUMIFS(EDSR!$I:$I,EDSR!$A:$A,'Progress%'!$B14,EDSR!$S:$S,"<="&F$6)*0.2)/$C14 -> 0 | G14: =IF($C14>0,SUMIFS(EDSR!$I:$I,EDSR!$A:$A,'Progress%'!$B14,EDSR!$J:$J,"<="&G$6)*0.5+SUMIFS(EDSR!$I:$I,EDSR!$A:$A,'Progress%'!$B14,EDSR!$M:$M,"<="&G$6)*0.2+SUMIFS(EDSR!$I:$I,EDSR!$A:$A,'Progress%'!$B14,EDSR!$P:$P,"<="&G$6)*0.1+SUMIFS(EDSR!$I:$I,EDSR!$A:$A,'Progress%'!$B14,EDSR!$S:$S,"<="&G$6)*0.2)/$C14 -> 0 | H14: =IF($C14>0,SUMIFS(EDSR!$I:$I,EDSR!$A:$A,'Progress%'!$B14,EDSR!$J:$J,"<="&H$6)*0.5+SUMIFS(EDSR!$I:$I,EDSR!$A:$A,'Progress%'!$B14,EDSR!$M:$M,"<="&H$6)*0.2+SUMIFS(EDSR!$I:$I,EDSR!$A:$A,'Progress%'!$B14,EDSR!$P:$P,"<="&H$6)*0.1+SUMIFS(EDSR!$I:$I,EDSR!$A:$A,'Progress%'!$B14,EDSR!$S:$S,"<="&H$6)*0.2)/$C14 -> 0.02 | I14: =IF($C14>0,SUMIFS(EDSR!$I:$I,EDSR!$A:$A,'Progress%'!$B14,EDSR!$J:$J,"<="&I$6)*0.5+SUMIFS(EDSR!$I:$I,EDSR!$A:$A,'Progress%'!$B14,EDSR!$M:$M,"<="&I$6)*0.2+SUMIFS(EDSR!$I:$I,EDSR!$A:$A,'Progress%'!$B14,EDSR!$P:$P,"<="&I$6)*0.1+SUMIFS(EDSR!$I:$I,EDSR!$A:$A,'Progress%'!$B14,EDSR!$S:$S,"<="&I$6)*0.2)/$C14 -> 0.028 | J14: =IF($C14>0,SUMIFS(EDSR!$I:$I,EDSR!$A:$A,'Progress%'!$B14,EDSR!$J:$J,"<="&J$6)*0.5+SUMIFS(EDSR!$I:$I,EDSR!$A:$A,'Progress%'!$B14,EDSR!$M:$M,"<="&J$6)*0.2+SUMIFS(EDSR!$I:$I,EDSR!$A:$A,'Progress%'!$B14,EDSR!$P:$P,"<="&J$6)*0.1+SUMIFS(EDSR!$I:$I,EDSR!$A:$A,'Progress%'!$B14,EDSR!$S:$S,"<="&J$6)*0.2)/$C14 -> 0.036 | K14: =IF($C14>0,SUMIFS(EDSR!$I:$I,EDSR!$A:$A,'Progress%'!$B14,EDSR!$J:$J,"<="&K$6)*0.5+SUMIFS(EDSR!$I:$I,EDSR!$A:$A,'Progress%'!$B14,EDSR!$M:$M,"<="&K$6)*0.2+SUMIFS(EDSR!$I:$I,EDSR!$A:$A,'Progress%'!$B14,EDSR!$P:$P,"<="&K$6)*0.1+SUMIFS(EDSR!$I:$I,EDSR!$A:$A,'Progress%'!$B14,EDSR!$S:$S,"<="&K$6)*0.2)/$C14 -> 0.036 | L14: =IF($C14>0,SUMIFS(EDSR!$I:$I,EDSR!$A:$A,'Progress%'!$B14,EDSR!$J:$J,"<="&L$6)*0.5+SUMIFS(EDSR!$I:$I,EDSR!$A:$A,'Progress%'!$B14,EDSR!$M:$M,"<="&L$6)*0.2+SUMIFS(EDSR!$I:$I,EDSR!$A:$A,'Progress%'!$B14,EDSR!$P:$P,"<="&L$6)*0.1+SUMIFS(EDSR!$I:$I,EDSR!$A:$A,'Progress%'!$B14,EDSR!$S:$S,"<="&L$6)*0.2)/$C14 -> 0.068 | M14: =IF($C14>0,SUMIFS(EDSR!$I:$I,EDSR!$A:$A,'Progress%'!$B14,EDSR!$J:$J,"<="&M$6)*0.5+SUMIFS(EDSR!$I:$I,EDSR!$A:$A,'Progress%'!$B14,EDSR!$M:$M,"<="&M$6)*0.2+SUMIFS(EDSR!$I:$I,EDSR!$A:$A,'Progress%'!$B14,EDSR!$P:$P,"<="&M$6)*0.1+SUMIFS(EDSR!$I:$I,EDSR!$A:$A,'Progress%'!$B14,EDSR!$S:$S,"<="&M$6)*0.2)/$C14 -> 0.078 | ... CT14: =IF($C14>0,SUMIFS(EDSR!$I:$I,EDSR!$A:$A,'Progress%'!$B14,EDSR!$J:$J,"<="&CT$6)*0.5+SUMIFS(EDSR!$I:$I,EDSR!$A:$A,'Progress%'!$B14,EDSR!$M:$M,"<="&CT$6)*0.2+SUMIFS(EDSR!$I:$I,EDSR!$A:$A,'Progress%'!$B14,EDSR!$P:$P,"<="&CT$6)*0.1+SUMIFS(EDSR!$I:$I,EDSR!$A:$A,'Progress%'!$B14,EDSR!$S:$S,"<="&CT$6)*0.2)/$C14 -> 0.9
A15: 15 | B15: ZWP-23 | C15: 25 | D15: 0.25 | E15: Forecast | F15: =IF($C14>0,SUMIFS(EDSR!$I:$I,EDSR!$A:$A,'Progress%'!$B14,EDSR!$K:$K,"<="&F$6)*0.5+SUMIFS(EDSR!$I:$I,EDSR!$A:$A,'Progress%'!$B14,EDSR!$N:$N,"<="&F$6)*0.2+SUMIFS(EDSR!$I:$I,EDSR!$A:$A,'Progress%'!$B14,EDSR!$Q:$Q,"<="&F$6)*0.1+SUMIFS(EDSR!$I:$I,EDSR!$A:$A,'Progress%'!$B14,EDSR!$T:$T,"<="&F$6)*0.2)/$C14 -> 0 | G15: =IF($C14>0,SUMIFS(EDSR!$I:$I,EDSR!$A:$A,'Progress%'!$B14,EDSR!$K:$K,"<="&G$6)*0.5+SUMIFS(EDSR!$I:$I,EDSR!$A:$A,'Progress%'!$B14,EDSR!$N:$N,"<="&G$6)*0.2+SUMIFS(EDSR!$I:$I,EDSR!$A:$A,'Progress%'!$B14,EDSR!$Q:$Q,"<="&G$6)*0.1+SUMIFS(EDSR!$I:$I,EDSR!$A:$A,'Progress%'!$B14,EDSR!$T:$T,"<="&G$6)*0.2)/$C14 -> 0 | H15: =IF($C14>0,SUMIFS(EDSR!$I:$I,EDSR!$A:$A,'Progress%'!$B14,EDSR!$K:$K,"<="&H$6)*0.5+SUMIFS(EDSR!$I:$I,EDSR!$A:$A,'Progress%'!$B14,EDSR!$N:$N,"<="&H$6)*0.2+SUMIFS(EDSR!$I:$I,EDSR!$A:$A,'Progress%'!$B14,EDSR!$Q:$Q,"<="&H$6)*0.1+SUMIFS(EDSR!$I:$I,EDSR!$A:$A,'Progress%'!$B14,EDSR!$T:$T,"<="&H$6)*0.2)/$C14 -> 0.02 | I15: =IF($C14>0,SUMIFS(EDSR!$I:$I,EDSR!$A:$A,'Progress%'!$B14,EDSR!$K:$K,"<="&I$6)*0.5+SUMIFS(EDSR!$I:$I,EDSR!$A:$A,'Progress%'!$B14,EDSR!$N:$N,"<="&I$6)*0.2+SUMIFS(EDSR!$I:$I,EDSR!$A:$A,'Progress%'!$B14,EDSR!$Q:$Q,"<="&I$6)*0.1+SUMIFS(EDSR!$I:$I,EDSR!$A:$A,'Progress%'!$B14,EDSR!$T:$T,"<="&I$6)*0.2)/$C14 -> 0.028 | J15: =IF($C14>0,SUMIFS(EDSR!$I:$I,EDSR!$A:$A,'Progress%'!$B14,EDSR!$K:$K,"<="&J$6)*0.5+SUMIFS(EDSR!$I:$I,EDSR!$A:$A,'Progress%'!$B14,EDSR!$N:$N,"<="&J$6)*0.2+SUMIFS(EDSR!$I:$I,EDSR!$A:$A,'Progress%'!$B14,EDSR!$Q:$Q,"<="&J$6)*0.1+SUMIFS(EDSR!$I:$I,EDSR!$A:$A,'Progress%'!$B14,EDSR!$T:$T,"<="&J$6)*0.2)/$C14 -> 0.036 | K15: =IF($C14>0,SUMIFS(EDSR!$I:$I,EDSR!$A:$A,'Progress%'!$B14,EDSR!$K:$K,"<="&K$6)*0.5+SUMIFS(EDSR!$I:$I,EDSR!$A:$A,'Progress%'!$B14,EDSR!$N:$N,"<="&K$6)*0.2+SUMIFS(EDSR!$I:$I,EDSR!$A:$A,'Progress%'!$B14,EDSR!$Q:$Q,"<="&K$6)*0.1+SUMIFS(EDSR!$I:$I,EDSR!$A:$A,'Progress%'!$B14,EDSR!$T:$T,"<="&K$6)*0.2)/$C14 -> 0.036 | L15: =IF($C14>0,SUMIFS(EDSR!$I:$I,EDSR!$A:$A,'Progress%'!$B14,EDSR!$K:$K,"<="&L$6)*0.5+SUMIFS(EDSR!$I:$I,EDSR!$A:$A,'Progress%'!$B14,EDSR!$N:$N,"<="&L$6)*0.2+SUMIFS(EDSR!$I:$I,EDSR!$A:$A,'Progress%'!$B14,EDSR!$Q:$Q,"<="&L$6)*0.1+SUMIFS(EDSR!$I:$I,EDSR!$A:$A,'Progress%'!$B14,EDSR!$T:$T,"<="&L$6)*0.2)/$C14 -> 0.068 | M15: =IF($C14>0,SUMIFS(EDSR!$I:$I,EDSR!$A:$A,'Progress%'!$B14,EDSR!$K:$K,"<="&M$6)*0.5+SUMIFS(EDSR!$I:$I,EDSR!$A:$A,'Progress%'!$B14,EDSR!$N:$N,"<="&M$6)*0.2+SUMIFS(EDSR!$I:$I,EDSR!$A:$A,'Progress%'!$B14,EDSR!$Q:$Q,"<="&M$6)*0.1+SUMIFS(EDSR!$I:$I,EDSR!$A:$A,'Progress%'!$B14,EDSR!$T:$T,"<="&M$6)*0.2)/$C14 -> 0.078 | ... CT15: =IF($C14>0,SUMIFS(EDSR!$I:$I,EDSR!$A:$A,'Progress%'!$B14,EDSR!$K:$K,"<="&CT$6)*0.5+SUMIFS(EDSR!$I:$I,EDSR!$A:$A,'Progress%'!$B14,EDSR!$N:$N,"<="&CT$6)*0.2+SUMIFS(EDSR!$I:$I,EDSR!$A:$A,'Progress%'!$B14,EDSR!$Q:$Q,"<="&CT$6)*0.1+SUMIFS(EDSR!$I:$I,EDSR!$A:$A,'Progress%'!$B14,EDSR!$T:$T,"<="&CT$6)*0.2)/$C14 -> 0.9
A16: 16 | B16: ZWP-23 | C16: 25 | D16: 0.25 | E16: Actual | F16: =IF($C16>0,SUMIFS(EDSR!$I:$I,EDSR!$A:$A,'Progress%'!$B16,EDSR!$L:$L,"<="&F$6)*0.5+SUMIFS(EDSR!$I:$I,EDSR!$A:$A,'Progress%'!$B16,EDSR!$O:$O,"<="&F$6)*0.2+SUMIFS(EDSR!$I:$I,EDSR!$A:$A,'Progress%'!$B16,EDSR!$R:$R,"<="&F$6)*0.1+SUMIFS(EDSR!$I:$I,EDSR!$A:$A,'Progress%'!$B16,EDSR!$U:$U,"<="&F$6)*0.2)/$C16 -> 0 | G16: =IF($C16>0,SUMIFS(EDSR!$I:$I,EDSR!$A:$A,'Progress%'!$B16,EDSR!$L:$L,"<="&G$6)*0.5+SUMIFS(EDSR!$I:$I,EDSR!$A:$A,'Progress%'!$B16,EDSR!$O:$O,"<="&G$6)*0.2+SUMIFS(EDSR!$I:$I,EDSR!$A:$A,'Progress%'!$B16,EDSR!$R:$R,"<="&G$6)*0.1+SUMIFS(EDSR!$I:$I,EDSR!$A:$A,'Progress%'!$B16,EDSR!$U:$U,"<="&G$6)*0.2)/$C16 -> 0 | H16: =IF($C16>0,SUMIFS(EDSR!$I:$I,EDSR!$A:$A,'Progress%'!$B16,EDSR!$L:$L,"<="&H$6)*0.5+SUMIFS(EDSR!$I:$I,EDSR!$A:$A,'Progress%'!$B16,EDSR!$O:$O,"<="&H$6)*0.2+SUMIFS(EDSR!$I:$I,EDSR!$A:$A,'Progress%'!$B16,EDSR!$R:$R,"<="&H$6)*0.1+SUMIFS(EDSR!$I:$I,EDSR!$A:$A,'Progress%'!$B16,EDSR!$U:$U,"<="&H$6)*0.2)/$C16 -> 0.028 | I16: =IF($C16>0,SUMIFS(EDSR!$I:$I,EDSR!$A:$A,'Progress%'!$B16,EDSR!$L:$L,"<="&I$6)*0.5+SUMIFS(EDSR!$I:$I,EDSR!$A:$A,'Progress%'!$B16,EDSR!$O:$O,"<="&I$6)*0.2+SUMIFS(EDSR!$I:$I,EDSR!$A:$A,'Progress%'!$B16,EDSR!$R:$R,"<="&I$6)*0.1+SUMIFS(EDSR!$I:$I,EDSR!$A:$A,'Progress%'!$B16,EDSR!$U:$U,"<="&I$6)*0.2)/$C16 -> 0.048 | J16: =IF($C16>0,SUMIFS(EDSR!$I:$I,EDSR!$A:$A,'Progress%'!$B16,EDSR!$L:$L,"<="&J$6)*0.5+SUMIFS(EDSR!$I:$I,EDSR!$A:$A,'Progress%'!$B16,EDSR!$O:$O,"<="&J$6)*0.2+SUMIFS(EDSR!$I:$I,EDSR!$A:$A,'Progress%'!$B16,EDSR!$R:$R,"<="&J$6)*0.1+SUMIFS(EDSR!$I:$I,EDSR!$A:$A,'Progress%'!$B16,EDSR!$U:$U,"<="&J$6)*0.2)/$C16 -> 0.048 | K16: =IF($C16>0,SUMIFS(EDSR!$I:$I,EDSR!$A:$A,'Progress%'!$B16,EDSR!$L:$L,"<="&K$6)*0.5+SUMIFS(EDSR!$I:$I,EDSR!$A:$A,'Progress%'!$B16,EDSR!$O:$O,"<="&K$6)*0.2+SUMIFS(EDSR!$I:$I,EDSR!$A:$A,'Progress%'!$B16,EDSR!$R:$R,"<="&K$6)*0.1+SUMIFS(EDSR!$I:$I,EDSR!$A:$A,'Progress%'!$B16,EDSR!$U:$U,"<="&K$6)*0.2)/$C16 -> 0.0668 | L16: =IF($C16>0,SUMIFS(EDSR!$I:$I,EDSR!$A:$A,'Progress%'!$B16,EDSR!$L:$L,"<="&L$6)*0.5+SUMIFS(EDSR!$I:$I,EDSR!$A:$A,'Progress%'!$B16,EDSR!$O:$O,"<="&L$6)*0.2+SUMIFS(EDSR!$I:$I,EDSR!$A:$A,'Progress%'!$B16,EDSR!$R:$R,"<="&L$6)*0.1+SUMIFS(EDSR!$I:$I,EDSR!$A:$A,'Progress%'!$B16,EDSR!$U:$U,"<="&L$6)*0.2)/$C16 -> 0.10254 | M16: =IF($C16>0,SUMIFS(EDSR!$I:$I,EDSR!$A:$A,'Progress%'!$B16,EDSR!$L:$L,"<="&M$6)*0.5+SUMIFS(EDSR!$I:$I,EDSR!$A:$A,'Progress%'!$B16,EDSR!$O:$O,"<="&M$6)*0.2+SUMIFS(EDSR!$I:$I,EDSR!$A:$A,'Progress%'!$B16,EDSR!$R:$R,"<="&M$6)*0.1+SUMIFS(EDSR!$I:$I,EDSR!$A:$A,'Progress%'!$B16,EDSR!$U:$U,"<="&M$6)*0.2)/$C16 -> 0.14736 | ... CT16: =IF($C16>0,SUMIFS(EDSR!$I:$I,EDSR!$A:$A,'Progress%'!$B16,EDSR!$L:$L,"<="&CT$6)*0.5+SUMIFS(EDSR!$I:$I,EDSR!$A:$A,'Progress%'!$B16,EDSR!$O:$O,"<="&CT$6)*0.2+SUMIFS(EDSR!$I:$I,EDSR!$A:$A,'Progress%'!$B16,EDSR!$R:$R,"<="&CT$6)*0.1+SUMIFS(EDSR!$I:$I,EDSR!$A:$A,'Progress%'!$B16,EDSR!$U:$U,"<="&CT$6)*0.2)/$C16 -> 0.769608
A17: 17
A18: 18
A19: 19 | B19: Scope | C19: Total WF | D19: WF% | E19: Jacket & Pile ZWP-22
A20: 20 | F20: 46101 | G20: =F20+7 -> 46108 | H20: =G20+7 -> 46115 | I20: =H20+7 -> 46122 | J20: =I20+7 -> 46129 | K20: =J20+7 -> 46136 | L20: =K20+7 -> 46143 | M20: =L20+7 -> 46150 | N20: =M20+7 -> 46157 | ... CT20: =CS20+7 -> 46745
A21: 21 | B21: ZWP-22 | C21: 25 | D21: 0.25 | E21: Plan | F21: =IF($C21>0,SUMIFS(EDSR!$I:$I,EDSR!$A:$A,'Progress%'!$B21,EDSR!$J:$J,"<="&F$6)*0.5+SUMIFS(EDSR!$I:$I,EDSR!$A:$A,'Progress%'!$B21,EDSR!$M:$M,"<="&F$6)*0.2+SUMIFS(EDSR!$I:$I,EDSR!$A:$A,'Progress%'!$B21,EDSR!$P:$P,"<="&F$6)*0.1+SUMIFS(EDSR!$I:$I,EDSR!$A:$A,'Progress%'!$B21,EDSR!$S:$S,"<="&F$6)*0.2)/$C21 -> 0 | G21: =IF($C21>0,SUMIFS(EDSR!$I:$I,EDSR!$A:$A,'Progress%'!$B21,EDSR!$J:$J,"<="&G$6)*0.5+SUMIFS(EDSR!$I:$I,EDSR!$A:$A,'Progress%'!$B21,EDSR!$M:$M,"<="&G$6)*0.2+SUMIFS(EDSR!$I:$I,EDSR!$A:$A,'Progress%'!$B21,EDSR!$P:$P,"<="&G$6)*0.1+SUMIFS(EDSR!$I:$I,EDSR!$A:$A,'Progress%'!$B21,EDSR!$S:$S,"<="&G$6)*0.2)/$C21 -> 0 | H21: =IF($C21>0,SUMIFS(EDSR!$I:$I,EDSR!$A:$A,'Progress%'!$B21,EDSR!$J:$J,"<="&H$6)*0.5+SUMIFS(EDSR!$I:$I,EDSR!$A:$A,'Progress%'!$B21,EDSR!$M:$M,"<="&H$6)*0.2+SUMIFS(EDSR!$I:$I,EDSR!$A:$A,'Progress%'!$B21,EDSR!$P:$P,"<="&H$6)*0.1+SUMIFS(EDSR!$I:$I,EDSR!$A:$A,'Progress%'!$B21,EDSR!$S:$S,"<="&H$6)*0.2)/$C21 -> 0.02 | I21: =IF($C21>0,SUMIFS(EDSR!$I:$I,EDSR!$A:$A,'Progress%'!$B21,EDSR!$J:$J,"<="&I$6)*0.5+SUMIFS(EDSR!$I:$I,EDSR!$A:$A,'Progress%'!$B21,EDSR!$M:$M,"<="&I$6)*0.2+SUMIFS(EDSR!$I:$I,EDSR!$A:$A,'Progress%'!$B21,EDSR!$P:$P,"<="&I$6)*0.1+SUMIFS(EDSR!$I:$I,EDSR!$A:$A,'Progress%'!$B21,EDSR!$S:$S,"<="&I$6)*0.2)/$C21 -> 0.028 | J21: =IF($C21>0,SUMIFS(EDSR!$I:$I,EDSR!$A:$A,'Progress%'!$B21,EDSR!$J:$J,"<="&J$6)*0.5+SUMIFS(EDSR!$I:$I,EDSR!$A:$A,'Progress%'!$B21,EDSR!$M:$M,"<="&J$6)*0.2+SUMIFS(EDSR!$I:$I,EDSR!$A:$A,'Progress%'!$B21,EDSR!$P:$P,"<="&J$6)*0.1+SUMIFS(EDSR!$I:$I,EDSR!$A:$A,'Progress%'!$B21,EDSR!$S:$S,"<="&J$6)*0.2)/$C21 -> 0.036 | K21: =IF($C21>0,SUMIFS(EDSR!$I:$I,EDSR!$A:$A,'Progress%'!$B21,EDSR!$J:$J,"<="&K$6)*0.5+SUMIFS(EDSR!$I:$I,EDSR!$A:$A,'Progress%'!$B21,EDSR!$M:$M,"<="&K$6)*0.2+SUMIFS(EDSR!$I:$I,EDSR!$A:$A,'Progress%'!$B21,EDSR!$P:$P,"<="&K$6)*0.1+SUMIFS(EDSR!$I:$I,EDSR!$A:$A,'Progress%'!$B21,EDSR!$S:$S,"<="&K$6)*0.2)/$C21 -> 0.036 | L21: =IF($C21>0,SUMIFS(EDSR!$I:$I,EDSR!$A:$A,'Progress%'!$B21,EDSR!$J:$J,"<="&L$6)*0.5+SUMIFS(EDSR!$I:$I,EDSR!$A:$A,'Progress%'!$B21,EDSR!$M:$M,"<="&L$6)*0.2+SUMIFS(EDSR!$I:$I,EDSR!$A:$A,'Progress%'!$B21,EDSR!$P:$P,"<="&L$6)*0.1+SUMIFS(EDSR!$I:$I,EDSR!$A:$A,'Progress%'!$B21,EDSR!$S:$S,"<="&L$6)*0.2)/$C21 -> 0.048 | M21: =IF($C21>0,SUMIFS(EDSR!$I:$I,EDSR!$A:$A,'Progress%'!$B21,EDSR!$J:$J,"<="&M$6)*0.5+SUMIFS(EDSR!$I:$I,EDSR!$A:$A,'Progress%'!$B21,EDSR!$M:$M,"<="&M$6)*0.2+SUMIFS(EDSR!$I:$I,EDSR!$A:$A,'Progress%'!$B21,EDSR!$P:$P,"<="&M$6)*0.1+SUMIFS(EDSR!$I:$I,EDSR!$A:$A,'Progress%'!$B21,EDSR!$S:$S,"<="&M$6)*0.2)/$C21 -> 0.048 | ... CT21: =IF($C21>0,SUMIFS(EDSR!$I:$I,EDSR!$A:$A,'Progress%'!$B21,EDSR!$J:$J,"<="&CT$6)*0.5+SUMIFS(EDSR!$I:$I,EDSR!$A:$A,'Progress%'!$B21,EDSR!$M:$M,"<="&CT$6)*0.2+SUMIFS(EDSR!$I:$I,EDSR!$A:$A,'Progress%'!$B21,EDSR!$P:$P,"<="&CT$6)*0.1+SUMIFS(EDSR!$I:$I,EDSR!$A:$A,'Progress%'!$B21,EDSR!$S:$S,"<="&CT$6)*0.2)/$C21 -> 0.9
A22: 22 | B22: ZWP-22 | C22: 25 | D22: 0.25 | E22: Forecast | F22: =IF($C21>0,SUMIFS(EDSR!$I:$I,EDSR!$A:$A,'Progress%'!$B21,EDSR!$K:$K,"<="&F$6)*0.5+SUMIFS(EDSR!$I:$I,EDSR!$A:$A,'Progress%'!$B21,EDSR!$N:$N,"<="&F$6)*0.2+SUMIFS(EDSR!$I:$I,EDSR!$A:$A,'Progress%'!$B21,EDSR!$Q:$Q,"<="&F$6)*0.1+SUMIFS(EDSR!$I:$I,EDSR!$A:$A,'Progress%'!$B21,EDSR!$T:$T,"<="&F$6)*0.2)/$C21 -> 0 | G22: =IF($C21>0,SUMIFS(EDSR!$I:$I,EDSR!$A:$A,'Progress%'!$B21,EDSR!$K:$K,"<="&G$6)*0.5+SUMIFS(EDSR!$I:$I,EDSR!$A:$A,'Progress%'!$B21,EDSR!$N:$N,"<="&G$6)*0.2+SUMIFS(EDSR!$I:$I,EDSR!$A:$A,'Progress%'!$B21,EDSR!$Q:$Q,"<="&G$6)*0.1+SUMIFS(EDSR!$I:$I,EDSR!$A:$A,'Progress%'!$B21,EDSR!$T:$T,"<="&G$6)*0.2)/$C21 -> 0 | H22: =IF($C21>0,SUMIFS(EDSR!$I:$I,EDSR!$A:$A,'Progress%'!$B21,EDSR!$K:$K,"<="&H$6)*0.5+SUMIFS(EDSR!$I:$I,EDSR!$A:$A,'Progress%'!$B21,EDSR!$N:$N,"<="&H$6)*0.2+SUMIFS(EDSR!$I:$I,EDSR!$A:$A,'Progress%'!$B21,EDSR!$Q:$Q,"<="&H$6)*0.1+SUMIFS(EDSR!$I:$I,EDSR!$A:$A,'Progress%'!$B21,EDSR!$T:$T,"<="&H$6)*0.2)/$C21 -> 0.02 | I22: =IF($C21>0,SUMIFS(EDSR!$I:$I,EDSR!$A:$A,'Progress%'!$B21,EDSR!$K:$K,"<="&I$6)*0.5+SUMIFS(EDSR!$I:$I,EDSR!$A:$A,'Progress%'!$B21,EDSR!$N:$N,"<="&I$6)*0.2+SUMIFS(EDSR!$I:$I,EDSR!$A:$A,'Progress%'!$B21,EDSR!$Q:$Q,"<="&I$6)*0.1+SUMIFS(EDSR!$I:$I,EDSR!$A:$A,'Progress%'!$B21,EDSR!$T:$T,"<="&I$6)*0.2)/$C21 -> 0.028 | J22: =IF($C21>0,SUMIFS(EDSR!$I:$I,EDSR!$A:$A,'Progress%'!$B21,EDSR!$K:$K,"<="&J$6)*0.5+SUMIFS(EDSR!$I:$I,EDSR!$A:$A,'Progress%'!$B21,EDSR!$N:$N,"<="&J$6)*0.2+SUMIFS(EDSR!$I:$I,EDSR!$A:$A,'Progress%'!$B21,EDSR!$Q:$Q,"<="&J$6)*0.1+SUMIFS(EDSR!$I:$I,EDSR!$A:$A,'Progress%'!$B21,EDSR!$T:$T,"<="&J$6)*0.2)/$C21 -> 0.036 | K22: =IF($C21>0,SUMIFS(EDSR!$I:$I,EDSR!$A:$A,'Progress%'!$B21,EDSR!$K:$K,"<="&K$6)*0.5+SUMIFS(EDSR!$I:$I,EDSR!$A:$A,'Progress%'!$B21,EDSR!$N:$N,"<="&K$6)*0.2+SUMIFS(EDSR!$I:$I,EDSR!$A:$A,'Progress%'!$B21,EDSR!$Q:$Q,"<="&K$6)*0.1+SUMIFS(EDSR!$I:$I,EDSR!$A:$A,'Progress%'!$B21,EDSR!$T:$T,"<="&K$6)*0.2)/$C21 -> 0.036 | L22: =IF($C21>0,SUMIFS(EDSR!$I:$I,EDSR!$A:$A,'Progress%'!$B21,EDSR!$K:$K,"<="&L$6)*0.5+SUMIFS(EDSR!$I:$I,EDSR!$A:$A,'Progress%'!$B21,EDSR!$N:$N,"<="&L$6)*0.2+SUMIFS(EDSR!$I:$I,EDSR!$A:$A,'Progress%'!$B21,EDSR!$Q:$Q,"<="&L$6)*0.1+SUMIFS(EDSR!$I:$I,EDSR!$A:$A,'Progress%'!$B21,EDSR!$T:$T,"<="&L$6)*0.2)/$C21 -> 0.048 | M22: =IF($C21>0,SUMIFS(EDSR!$I:$I,EDSR!$A:$A,'Progress%'!$B21,EDSR!$K:$K,"<="&M$6)*0.5+SUMIFS(EDSR!$I:$I,EDSR!$A:$A,'Progress%'!$B21,EDSR!$N:$N,"<="&M$6)*0.2+SUMIFS(EDSR!$I:$I,EDSR!$A:$A,'Progress%'!$B21,EDSR!$Q:$Q,"<="&M$6)*0.1+SUMIFS(EDSR!$I:$I,EDSR!$A:$A,'Progress%'!$B21,EDSR!$T:$T,"<="&M$6)*0.2)/$C21 -> 0.048 | ... CT22: =IF($C21>0,SUMIFS(EDSR!$I:$I,EDSR!$A:$A,'Progress%'!$B21,EDSR!$K:$K,"<="&CT$6)*0.5+SUMIFS(EDSR!$I:$I,EDSR!$A:$A,'Progress%'!$B21,EDSR!$N:$N,"<="&CT$6)*0.2+SUMIFS(EDSR!$I:$I,EDSR!$A:$A,'Progress%'!$B21,EDSR!$Q:$Q,"<="&CT$6)*0.1+SUMIFS(EDSR!$I:$I,EDSR!$A:$A,'Progress%'!$B21,EDSR!$T:$T,"<="&CT$6)*0.2)/$C21 -> 0.9
A23: 23 | B23: ZWP-22 | C23: 25 | D23: 0.25 | E23: Actual | F23: =IF($C23>0,SUMIFS(EDSR!$I:$I,EDSR!$A:$A,'Progress%'!$B23,EDSR!$L:$L,"<="&F$6)*0.5+SUMIFS(EDSR!$I:$I,EDSR!$A:$A,'Progress%'!$B23,EDSR!$O:$O,"<="&F$6)*0.2+SUMIFS(EDSR!$I:$I,EDSR!$A:$A,'Progress%'!$B23,EDSR!$R:$R,"<="&F$6)*0.1+SUMIFS(EDSR!$I:$I,EDSR!$A:$A,'Progress%'!$B23,EDSR!$U:$U,"<="&F$6)*0.2)/$C23 -> 0 | G23: =IF($C23>0,SUMIFS(EDSR!$I:$I,EDSR!$A:$A,'Progress%'!$B23,EDSR!$L:$L,"<="&G$6)*0.5+SUMIFS(EDSR!$I:$I,EDSR!$A:$A,'Progress%'!$B23,EDSR!$O:$O,"<="&G$6)*0.2+SUMIFS(EDSR!$I:$I,EDSR!$A:$A,'Progress%'!$B23,EDSR!$R:$R,"<="&G$6)*0.1+SUMIFS(EDSR!$I:$I,EDSR!$A:$A,'Progress%'!$B23,EDSR!$U:$U,"<="&G$6)*0.2)/$C23 -> 0 | H23: =IF($C23>0,SUMIFS(EDSR!$I:$I,EDSR!$A:$A,'Progress%'!$B23,EDSR!$L:$L,"<="&H$6)*0.5+SUMIFS(EDSR!$I:$I,EDSR!$A:$A,'Progress%'!$B23,EDSR!$O:$O,"<="&H$6)*0.2+SUMIFS(EDSR!$I:$I,EDSR!$A:$A,'Progress%'!$B23,EDSR!$R:$R,"<="&H$6)*0.1+SUMIFS(EDSR!$I:$I,EDSR!$A:$A,'Progress%'!$B23,EDSR!$U:$U,"<="&H$6)*0.2)/$C23 -> 0.028 | I23: =IF($C23>0,SUMIFS(EDSR!$I:$I,EDSR!$A:$A,'Progress%'!$B23,EDSR!$L:$L,"<="&I$6)*0.5+SUMIFS(EDSR!$I:$I,EDSR!$A:$A,'Progress%'!$B23,EDSR!$O:$O,"<="&I$6)*0.2+SUMIFS(EDSR!$I:$I,EDSR!$A:$A,'Progress%'!$B23,EDSR!$R:$R,"<="&I$6)*0.1+SUMIFS(EDSR!$I:$I,EDSR!$A:$A,'Progress%'!$B23,EDSR!$U:$U,"<="&I$6)*0.2)/$C23 -> 0.028 | J23: =IF($C23>0,SUMIFS(EDSR!$I:$I,EDSR!$A:$A,'Progress%'!$B23,EDSR!$L:$L,"<="&J$6)*0.5+SUMIFS(EDSR!$I:$I,EDSR!$A:$A,'Progress%'!$B23,EDSR!$O:$O,"<="&J$6)*0.2+SUMIFS(EDSR!$I:$I,EDSR!$A:$A,'Progress%'!$B23,EDSR!$R:$R,"<="&J$6)*0.1+SUMIFS(EDSR!$I:$I,EDSR!$A:$A,'Progress%'!$B23,EDSR!$U:$U,"<="&J$6)*0.2)/$C23 -> 0.028 | K23: =IF($C23>0,SUMIFS(EDSR!$I:$I,EDSR!$A:$A,'Progress%'!$B23,EDSR!$L:$L,"<="&K$6)*0.5+SUMIFS(EDSR!$I:$I,EDSR!$A:$A,'Progress%'!$B23,EDSR!$O:$O,"<="&K$6)*0.2+SUMIFS(EDSR!$I:$I,EDSR!$A:$A,'Progress%'!$B23,EDSR!$R:$R,"<="&K$6)*0.1+SUMIFS(EDSR!$I:$I,EDSR!$A:$A,'Progress%'!$B23,EDSR!$U:$U,"<="&K$6)*0.2)/$C23 -> 0.0668 | L23: =IF($C23>0,SUMIFS(EDSR!$I:$I,EDSR!$A:$A,'Progress%'!$B23,EDSR!$L:$L,"<="&L$6)*0.5+SUMIFS(EDSR!$I:$I,EDSR!$A:$A,'Progress%'!$B23,EDSR!$O:$O,"<="&L$6)*0.2+SUMIFS(EDSR!$I:$I,EDSR!$A:$A,'Progress%'!$B23,EDSR!$R:$R,"<="&L$6)*0.1+SUMIFS(EDSR!$I:$I,EDSR!$A:$A,'Progress%'!$B23,EDSR!$U:$U,"<="&L$6)*0.2)/$C23 -> 0.10254 | M23: =IF($C23>0,SUMIFS(EDSR!$I:$I,EDSR!$A:$A,'Progress%'!$B23,EDSR!$L:$L,"<="&M$6)*0.5+SUMIFS(EDSR!$I:$I,EDSR!$A:$A,'Progress%'!$B23,EDSR!$O:$O,"<="&M$6)*0.2+SUMIFS(EDSR!$I:$I,EDSR!$A:$A,'Progress%'!$B23,EDSR!$R:$R,"<="&M$6)*0.1+SUMIFS(EDSR!$I:$I,EDSR!$A:$A,'Progress%'!$B23,EDSR!$U:$U,"<="&M$6)*0.2)/$C23 -> 0.11736 | ... CT23: =IF($C23>0,SUMIFS(EDSR!$I:$I,EDSR!$A:$A,'Progress%'!$B23,EDSR!$L:$L,"<="&CT$6)*0.5+SUMIFS(EDSR!$I:$I,EDSR!$A:$A,'Progress%'!$B23,EDSR!$O:$O,"<="&CT$6)*0.2+SUMIFS(EDSR!$I:$I,EDSR!$A:$A,'Progress%'!$B23,EDSR!$R:$R,"<="&CT$6)*0.1+SUMIFS(EDSR!$I:$I,EDSR!$A:$A,'Progress%'!$B23,EDSR!$U:$U,"<="&CT$6)*0.2)/$C23 -> 0.708748
A24: 24
A25: 25
A26: 26 | B26: Scope | C26: Total WF | D26: WF% | E26: Jacket & Pile ZWP-20
A27: 27 | F27: 46101 | G27: =F27+7 -> 46108 | H27: =G27+7 -> 46115 | I27: =H27+7 -> 46122 | J27: =I27+7 -> 46129 | K27: =J27+7 -> 46136 | L27: =K27+7 -> 46143 | M27: =L27+7 -> 46150 | N27: =M27+7 -> 46157 | ... CT27: =CS27+7 -> 46745
A28: 28 | B28: ZWP-20 | C28: 25 | D28: 0.25 | E28: Plan | F28: =IF($C28>0,SUMIFS(EDSR!$I:$I,EDSR!$A:$A,'Progress%'!$B28,EDSR!$J:$J,"<="&F$6)*0.5+SUMIFS(EDSR!$I:$I,EDSR!$A:$A,'Progress%'!$B28,EDSR!$M:$M,"<="&F$6)*0.2+SUMIFS(EDSR!$I:$I,EDSR!$A:$A,'Progress%'!$B28,EDSR!$P:$P,"<="&F$6)*0.1+SUMIFS(EDSR!$I:$I,EDSR!$A:$A,'Progress%'!$B28,EDSR!$S:$S,"<="&F$6)*0.2)/$C28 -> 0 | G28: =IF($C28>0,SUMIFS(EDSR!$I:$I,EDSR!$A:$A,'Progress%'!$B28,EDSR!$J:$J,"<="&G$6)*0.5+SUMIFS(EDSR!$I:$I,EDSR!$A:$A,'Progress%'!$B28,EDSR!$M:$M,"<="&G$6)*0.2+SUMIFS(EDSR!$I:$I,EDSR!$A:$A,'Progress%'!$B28,EDSR!$P:$P,"<="&G$6)*0.1+SUMIFS(EDSR!$I:$I,EDSR!$A:$A,'Progress%'!$B28,EDSR!$S:$S,"<="&G$6)*0.2)/$C28 -> 0 | H28: =IF($C28>0,SUMIFS(EDSR!$I:$I,EDSR!$A:$A,'Progress%'!$B28,EDSR!$J:$J,"<="&H$6)*0.5+SUMIFS(EDSR!$I:$I,EDSR!$A:$A,'Progress%'!$B28,EDSR!$M:$M,"<="&H$6)*0.2+SUMIFS(EDSR!$I:$I,EDSR!$A:$A,'Progress%'!$B28,EDSR!$P:$P,"<="&H$6)*0.1+SUMIFS(EDSR!$I:$I,EDSR!$A:$A,'Progress%'!$B28,EDSR!$S:$S,"<="&H$6)*0.2)/$C28 -> 0.02 | I28: =IF($C28>0,SUMIFS(EDSR!$I:$I,EDSR!$A:$A,'Progress%'!$B28,EDSR!$J:$J,"<="&I$6)*0.5+SUMIFS(EDSR!$I:$I,EDSR!$A:$A,'Progress%'!$B28,EDSR!$M:$M,"<="&I$6)*0.2+SUMIFS(EDSR!$I:$I,EDSR!$A:$A,'Progress%'!$B28,EDSR!$P:$P,"<="&I$6)*0.1+SUMIFS(EDSR!$I:$I,EDSR!$A:$A,'Progress%'!$B28,EDSR!$S:$S,"<="&I$6)*0.2)/$C28 -> 0.028 | J28: =IF($C28>0,SUMIFS(EDSR!$I:$I,EDSR!$A:$A,'Progress%'!$B28,EDSR!$J:$J,"<="&J$6)*0.5+SUMIFS(EDSR!$I:$I,EDSR!$A:$A,'Progress%'!$B28,EDSR!$M:$M,"<="&J$6)*0.2+SUMIFS(EDSR!$I:$I,EDSR!$A:$A,'Progress%'!$B28,EDSR!$P:$P,"<="&J$6)*0.1+SUMIFS(EDSR!$I:$I,EDSR!$A:$A,'Progress%'!$B28,EDSR!$S:$S,"<="&J$6)*0.2)/$C28 -> 0.036 | K28: =IF($C28>0,SUMIFS(EDSR!$I:$I,EDSR!$A:$A,'Progress%'!$B28,EDSR!$J:$J,"<="&K$6)*0.5+SUMIFS(EDSR!$I:$I,EDSR!$A:$A,'Progress%'!$B28,EDSR!$M:$M,"<="&K$6)*0.2+SUMIFS(EDSR!$I:$I,EDSR!$A:$A,'Progress%'!$B28,EDSR!$P:$P,"<="&K$6)*0.1+SUMIFS(EDSR!$I:$I,EDSR!$A:$A,'Progress%'!$B28,EDSR!$S:$S,"<="&K$6)*0.2)/$C28 -> 0.036 | L28: =IF($C28>0,SUMIFS(EDSR!$I:$I,EDSR!$A:$A,'Progress%'!$B28,EDSR!$J:$J,"<="&L$6)*0.5+SUMIFS(EDSR!$I:$I,EDSR!$A:$A,'Progress%'!$B28,EDSR!$M:$M,"<="&L$6)*0.2+SUMIFS(EDSR!$I:$I,EDSR!$A:$A,'Progress%'!$B28,EDSR!$P:$P,"<="&L$6)*0.1+SUMIFS(EDSR!$I:$I,EDSR!$A:$A,'Progress%'!$B28,EDSR!$S:$S,"<="&L$6)*0.2)/$C28 -> 0.048 | M28: =IF($C28>0,SUMIFS(EDSR!$I:$I,EDSR!$A:$A,'Progress%'!$B28,EDSR!$J:$J,"<="&M$6)*0.5+SUMIFS(EDSR!$I:$I,EDSR!$A:$A,'Progress%'!$B28,EDSR!$M:$M,"<="&M$6)*0.2+SUMIFS(EDSR!$I:$I,EDSR!$A:$A,'Progress%'!$B28,EDSR!$P:$P,"<="&M$6)*0.1+SUMIFS(EDSR!$I:$I,EDSR!$A:$A,'Progress%'!$B28,EDSR!$S:$S,"<="&M$6)*0.2)/$C28 -> 0.048 | ... CT28: =IF($C28>0,SUMIFS(EDSR!$I:$I,EDSR!$A:$A,'Progress%'!$B28,EDSR!$J:$J,"<="&CT$6)*0.5+SUMIFS(EDSR!$I:$I,EDSR!$A:$A,'Progress%'!$B28,EDSR!$M:$M,"<="&CT$6)*0.2+SUMIFS(EDSR!$I:$I,EDSR!$A:$A,'Progress%'!$B28,EDSR!$P:$P,"<="&CT$6)*0.1+SUMIFS(EDSR!$I:$I,EDSR!$A:$A,'Progress%'!$B28,EDSR!$S:$S,"<="&CT$6)*0.2)/$C28 -> 0.9
A29: 29 | B29: ZWP-20 | C29: 25 | D29: 0.25 | E29: Forecast | F29: =IF($C28>0,SUMIFS(EDSR!$I:$I,EDSR!$A:$A,'Progress%'!$B28,EDSR!$K:$K,"<="&F$6)*0.5+SUMIFS(EDSR!$I:$I,EDSR!$A:$A,'Progress%'!$B28,EDSR!$N:$N,"<="&F$6)*0.2+SUMIFS(EDSR!$I:$I,EDSR!$A:$A,'Progress%'!$B28,EDSR!$Q:$Q,"<="&F$6)*0.1+SUMIFS(EDSR!$I:$I,EDSR!$A:$A,'Progress%'!$B28,EDSR!$T:$T,"<="&F$6)*0.2)/$C28 -> 0 | G29: =IF($C28>0,SUMIFS(EDSR!$I:$I,EDSR!$A:$A,'Progress%'!$B28,EDSR!$K:$K,"<="&G$6)*0.5+SUMIFS(EDSR!$I:$I,EDSR!$A:$A,'Progress%'!$B28,EDSR!$N:$N,"<="&G$6)*0.2+SUMIFS(EDSR!$I:$I,EDSR!$A:$A,'Progress%'!$B28,EDSR!$Q:$Q,"<="&G$6)*0.1+SUMIFS(EDSR!$I:$I,EDSR!$A:$A,'Progress%'!$B28,EDSR!$T:$T,"<="&G$6)*0.2)/$C28 -> 0 | H29: =IF($C28>0,SUMIFS(EDSR!$I:$I,EDSR!$A:$A,'Progress%'!$B28,EDSR!$K:$K,"<="&H$6)*0.5+SUMIFS(EDSR!$I:$I,EDSR!$A:$A,'Progress%'!$B28,EDSR!$N:$N,"<="&H$6)*0.2+SUMIFS(EDSR!$I:$I,EDSR!$A:$A,'Progress%'!$B28,EDSR!$Q:$Q,"<="&H$6)*0.1+SUMIFS(EDSR!$I:$I,EDSR!$A:$A,'Progress%'!$B28,EDSR!$T:$T,"<="&H$6)*0.2)/$C28 -> 0.02 | I29: =IF($C28>0,SUMIFS(EDSR!$I:$I,EDSR!$A:$A,'Progress%'!$B28,EDSR!$K:$K,"<="&I$6)*0.5+SUMIFS(EDSR!$I:$I,EDSR!$A:$A,'Progress%'!$B28,EDSR!$N:$N,"<="&I$6)*0.2+SUMIFS(EDSR!$I:$I,EDSR!$A:$A,'Progress%'!$B28,EDSR!$Q:$Q,"<="&I$6)*0.1+SUMIFS(EDSR!$I:$I,EDSR!$A:$A,'Progress%'!$B28,EDSR!$T:$T,"<="&I$6)*0.2)/$C28 -> 0.028 | J29: =IF($C28>0,SUMIFS(EDSR!$I:$I,EDSR!$A:$A,'Progress%'!$B28,EDSR!$K:$K,"<="&J$6)*0.5+SUMIFS(EDSR!$I:$I,EDSR!$A:$A,'Progress%'!$B28,EDSR!$N:$N,"<="&J$6)*0.2+SUMIFS(EDSR!$I:$I,EDSR!$A:$A,'Progress%'!$B28,EDSR!$Q:$Q,"<="&J$6)*0.1+SUMIFS(EDSR!$I:$I,EDSR!$A:$A,'Progress%'!$B28,EDSR!$T:$T,"<="&J$6)*0.2)/$C28 -> 0.036 | K29: =IF($C28>0,SUMIFS(EDSR!$I:$I,EDSR!$A:$A,'Progress%'!$B28,EDSR!$K:$K,"<="&K$6)*0.5+SUMIFS(EDSR!$I:$I,EDSR!$A:$A,'Progress%'!$B28,EDSR!$N:$N,"<="&K$6)*0.2+SUMIFS(EDSR!$I:$I,EDSR!$A:$A,'Progress%'!$B28,EDSR!$Q:$Q,"<="&K$6)*0.1+SUMIFS(EDSR!$I:$I,EDSR!$A:$A,'Progress%'!$B28,EDSR!$T:$T,"<="&K$6)*0.2)/$C28 -> 0.036 | L29: =IF($C28>0,SUMIFS(EDSR!$I:$I,EDSR!$A:$A,'Progress%'!$B28,EDSR!$K:$K,"<="&L$6)*0.5+SUMIFS(EDSR!$I:$I,EDSR!$A:$A,'Progress%'!$B28,EDSR!$N:$N,"<="&L$6)*0.2+SUMIFS(EDSR!$I:$I,EDSR!$A:$A,'Progress%'!$B28,EDSR!$Q:$Q,"<="&L$6)*0.1+SUMIFS(EDSR!$I:$I,EDSR!$A:$A,'Progress%'!$B28,EDSR!$T:$T,"<="&L$6)*0.2)/$C28 -> 0.048 | M29: =IF($C28>0,SUMIFS(EDSR!$I:$I,EDSR!$A:$A,'Progress%'!$B28,EDSR!$K:$K,"<="&M$6)*0.5+SUMIFS(EDSR!$I:$I,EDSR!$A:$A,'Progress%'!$B28,EDSR!$N:$N,"<="&M$6)*0.2+SUMIFS(EDSR!$I:$I,EDSR!$A:$A,'Progress%'!$B28,EDSR!$Q:$Q,"<="&M$6)*0.1+SUMIFS(EDSR!$I:$I,EDSR!$A:$A,'Progress%'!$B28,EDSR!$T:$T,"<="&M$6)*0.2)/$C28 -> 0.048 | ... CT29: =IF($C28>0,SUMIFS(EDSR!$I:$I,EDSR!$A:$A,'Progress%'!$B28,EDSR!$K:$K,"<="&CT$6)*0.5+SUMIFS(EDSR!$I:$I,EDSR!$A:$A,'Progress%'!$B28,EDSR!$N:$N,"<="&CT$6)*0.2+SUMIFS(EDSR!$I:$I,EDSR!$A:$A,'Progress%'!$B28,EDSR!$Q:$Q,"<="&CT$6)*0.1+SUMIFS(EDSR!$I:$I,EDSR!$A:$A,'Progress%'!$B28,EDSR!$T:$T,"<="&CT$6)*0.2)/$C28 -> 0.9
A30: 30 | B30: ZWP-20 | C30: 25 | D30: 0.25 | E30: Actual | F30: =IF($C30>0,SUMIFS(EDSR!$I:$I,EDSR!$A:$A,'Progress%'!$B30,EDSR!$L:$L,"<="&F$6)*0.5+SUMIFS(EDSR!$I:$I,EDSR!$A:$A,'Progress%'!$B30,EDSR!$O:$O,"<="&F$6)*0.2+SUMIFS(EDSR!$I:$I,EDSR!$A:$A,'Progress%'!$B30,EDSR!$R:$R,"<="&F$6)*0.1+SUMIFS(EDSR!$I:$I,EDSR!$A:$A,'Progress%'!$B30,EDSR!$U:$U,"<="&F$6)*0.2)/$C30 -> 0 | G30: =IF($C30>0,SUMIFS(EDSR!$I:$I,EDSR!$A:$A,'Progress%'!$B30,EDSR!$L:$L,"<="&G$6)*0.5+SUMIFS(EDSR!$I:$I,EDSR!$A:$A,'Progress%'!$B30,EDSR!$O:$O,"<="&G$6)*0.2+SUMIFS(EDSR!$I:$I,EDSR!$A:$A,'Progress%'!$B30,EDSR!$R:$R,"<="&G$6)*0.1+SUMIFS(EDSR!$I:$I,EDSR!$A:$A,'Progress%'!$B30,EDSR!$U:$U,"<="&G$6)*0.2)/$C30 -> 0 | H30: =IF($C30>0,SUMIFS(EDSR!$I:$I,EDSR!$A:$A,'Progress%'!$B30,EDSR!$L:$L,"<="&H$6)*0.5+SUMIFS(EDSR!$I:$I,EDSR!$A:$A,'Progress%'!$B30,EDSR!$O:$O,"<="&H$6)*0.2+SUMIFS(EDSR!$I:$I,EDSR!$A:$A,'Progress%'!$B30,EDSR!$R:$R,"<="&H$6)*0.1+SUMIFS(EDSR!$I:$I,EDSR!$A:$A,'Progress%'!$B30,EDSR!$U:$U,"<="&H$6)*0.2)/$C30 -> 0.028 | I30: =IF($C30>0,SUMIFS(EDSR!$I:$I,EDSR!$A:$A,'Progress%'!$B30,EDSR!$L:$L,"<="&I$6)*0.5+SUMIFS(EDSR!$I:$I,EDSR!$A:$A,'Progress%'!$B30,EDSR!$O:$O,"<="&I$6)*0.2+SUMIFS(EDSR!$I:$I,EDSR!$A:$A,'Progress%'!$B30,EDSR!$R:$R,"<="&I$6)*0.1+SUMIFS(EDSR!$I:$I,EDSR!$A:$A,'Progress%'!$B30,EDSR!$U:$U,"<="&I$6)*0.2)/$C30 -> 0.028 | J30: =IF($C30>0,SUMIFS(EDSR!$I:$I,EDSR!$A:$A,'Progress%'!$B30,EDSR!$L:$L,"<="&J$6)*0.5+SUMIFS(EDSR!$I:$I,EDSR!$A:$A,'Progress%'!$B30,EDSR!$O:$O,"<="&J$6)*0.2+SUMIFS(EDSR!$I:$I,EDSR!$A:$A,'Progress%'!$B30,EDSR!$R:$R,"<="&J$6)*0.1+SUMIFS(EDSR!$I:$I,EDSR!$A:$A,'Progress%'!$B30,EDSR!$U:$U,"<="&J$6)*0.2)/$C30 -> 0.028 | K30: =IF($C30>0,SUMIFS(EDSR!$I:$I,EDSR!$A:$A,'Progress%'!$B30,EDSR!$L:$L,"<="&K$6)*0.5+SUMIFS(EDSR!$I:$I,EDSR!$A:$A,'Progress%'!$B30,EDSR!$O:$O,"<="&K$6)*0.2+SUMIFS(EDSR!$I:$I,EDSR!$A:$A,'Progress%'!$B30,EDSR!$R:$R,"<="&K$6)*0.1+SUMIFS(EDSR!$I:$I,EDSR!$A:$A,'Progress%'!$B30,EDSR!$U:$U,"<="&K$6)*0.2)/$C30 -> 0.0668 | L30: =IF($C30>0,SUMIFS(EDSR!$I:$I,EDSR!$A:$A,'Progress%'!$B30,EDSR!$L:$L,"<="&L$6)*0.5+SUMIFS(EDSR!$I:$I,EDSR!$A:$A,'Progress%'!$B30,EDSR!$O:$O,"<="&L$6)*0.2+SUMIFS(EDSR!$I:$I,EDSR!$A:$A,'Progress%'!$B30,EDSR!$R:$R,"<="&L$6)*0.1+SUMIFS(EDSR!$I:$I,EDSR!$A:$A,'Progress%'!$B30,EDSR!$U:$U,"<="&L$6)*0.2)/$C30 -> 0.10254 | M30: =IF($C30>0,SUMIFS(EDSR!$I:$I,EDSR!$A:$A,'Progress%'!$B30,EDSR!$L:$L,"<="&M$6)*0.5+SUMIFS(EDSR!$I:$I,EDSR!$A:$A,'Progress%'!$B30,EDSR!$O:$O,"<="&M$6)*0.2+SUMIFS(EDSR!$I:$I,EDSR!$A:$A,'Progress%'!$B30,EDSR!$R:$R,"<="&M$6)*0.1+SUMIFS(EDSR!$I:$I,EDSR!$A:$A,'Progress%'!$B30,EDSR!$U:$U,"<="&M$6)*0.2)/$C30 -> 0.11736 | ... CT30: =IF($C30>0,SUMIFS(EDSR!$I:$I,EDSR!$A:$A,'Progress%'!$B30,EDSR!$L:$L,"<="&CT$6)*0.5+SUMIFS(EDSR!$I:$I,EDSR!$A:$A,'Progress%'!$B30,EDSR!$O:$O,"<="&CT$6)*0.2+SUMIFS(EDSR!$I:$I,EDSR!$A:$A,'Progress%'!$B30,EDSR!$R:$R,"<="&CT$6)*0.1+SUMIFS(EDSR!$I:$I,EDSR!$A:$A,'Progress%'!$B30,EDSR!$U:$U,"<="&CT$6)*0.2)/$C30 -> 0.677112
A31: 31
A32: 32
A33: 33 | B33: Scope | C33: Total WF | D33: WF% | E33: Jacket & Pile - Overall DDE
A34: 34 | F34: 46101 | G34: =F34+7 -> 46108 | H34: =G34+7 -> 46115 | I34: =H34+7 -> 46122 | J34: =I34+7 -> 46129 | K34: =J34+7 -> 46136 | L34: =K34+7 -> 46143 | M34: =L34+7 -> 46150 | N34: =M34+7 -> 46157 | ... CT34: =CS34+7 -> 46745
A35: 35 | B35: Overall | C35: 100 | D35: 1 | E35: Plan | F35: =SUMPRODUCT($D7,F7)+SUMPRODUCT($D14,F14)+SUMPRODUCT($D21,F21)+SUMPRODUCT($D28,F28)/$D35 -> 0 | G35: =SUMPRODUCT($D7,G7)+SUMPRODUCT($D14,G14)+SUMPRODUCT($D21,G21)+SUMPRODUCT($D28,G28)/$D35 -> 0 | H35: =SUMPRODUCT($D7,H7)+SUMPRODUCT($D14,H14)+SUMPRODUCT($D21,H21)+SUMPRODUCT($D28,H28)/$D35 -> 0.025 | I35: =SUMPRODUCT($D7,I7)+SUMPRODUCT($D14,I14)+SUMPRODUCT($D21,I21)+SUMPRODUCT($D28,I28)/$D35 -> 0.0355 | J35: =SUMPRODUCT($D7,J7)+SUMPRODUCT($D14,J14)+SUMPRODUCT($D21,J21)+SUMPRODUCT($D28,J28)/$D35 -> 0.0435 | K35: =SUMPRODUCT($D7,K7)+SUMPRODUCT($D14,K14)+SUMPRODUCT($D21,K21)+SUMPRODUCT($D28,K28)/$D35 -> 0.046 | L35: =SUMPRODUCT($D7,L7)+SUMPRODUCT($D14,L14)+SUMPRODUCT($D21,L21)+SUMPRODUCT($D28,L28)/$D35 -> 0.0655 | M35: =SUMPRODUCT($D7,M7)+SUMPRODUCT($D14,M14)+SUMPRODUCT($D21,M21)+SUMPRODUCT($D28,M28)/$D35 -> 0.080375 | ... CT35: =SUMPRODUCT($D7,CT7)+SUMPRODUCT($D14,CT14)+SUMPRODUCT($D21,CT21)+SUMPRODUCT($D28,CT28)/$D35 -> 0.9
A36: 36 | B36: Overall | C36: 100 | D36: 1 | E36: Forecast | F36: =SUMPRODUCT($D8,F8)+SUMPRODUCT($D15,F15)+SUMPRODUCT($D22,F22)+SUMPRODUCT($D29,F29)/$D36 -> 0 | G36: =SUMPRODUCT($D8,G8)+SUMPRODUCT($D15,G15)+SUMPRODUCT($D22,G22)+SUMPRODUCT($D29,G29)/$D36 -> 0 | H36: =SUMPRODUCT($D8,H8)+SUMPRODUCT($D15,H15)+SUMPRODUCT($D22,H22)+SUMPRODUCT($D29,H29)/$D36 -> 0.025 | I36: =SUMPRODUCT($D8,I8)+SUMPRODUCT($D15,I15)+SUMPRODUCT($D22,I22)+SUMPRODUCT($D29,I29)/$D36 -> 0.0355 | J36: =SUMPRODUCT($D8,J8)+SUMPRODUCT($D15,J15)+SUMPRODUCT($D22,J22)+SUMPRODUCT($D29,J29)/$D36 -> 0.0435 | K36: =SUMPRODUCT($D8,K8)+SUMPRODUCT($D15,K15)+SUMPRODUCT($D22,K22)+SUMPRODUCT($D29,K29)/$D36 -> 0.046 | L36: =SUMPRODUCT($D8,L8)+SUMPRODUCT($D15,L15)+SUMPRODUCT($D22,L22)+SUMPRODUCT($D29,L29)/$D36 -> 0.0655 | M36: =SUMPRODUCT($D8,M8)+SUMPRODUCT($D15,M15)+SUMPRODUCT($D22,M22)+SUMPRODUCT($D29,M29)/$D36 -> 0.080375 | ... CT36: =SUMPRODUCT($D8,CT8)+SUMPRODUCT($D15,CT15)+SUMPRODUCT($D22,CT22)+SUMPRODUCT($D29,CT29)/$D36 -> 0.9
A37: 37 | B37: Overall | C37: 100 | D37: 1 | E37: Actual | F37: =SUMPRODUCT($D9,F9)+SUMPRODUCT($D16,F16)+SUMPRODUCT($D23,F23)+SUMPRODUCT($D30,F30)/$D37 -> 0 | G37: =SUMPRODUCT($D9,G9)+SUMPRODUCT($D16,G16)+SUMPRODUCT($D23,G23)+SUMPRODUCT($D30,G30)/$D37 -> 0 | H37: =SUMPRODUCT($D9,H9)+SUMPRODUCT($D16,H16)+SUMPRODUCT($D23,H23)+SUMPRODUCT($D30,H30)/$D37 -> 0.028 | I37: =SUMPRODUCT($D9,I9)+SUMPRODUCT($D16,I16)+SUMPRODUCT($D23,I23)+SUMPRODUCT($D30,I30)/$D37 -> 0.038 | J37: =SUMPRODUCT($D9,J9)+SUMPRODUCT($D16,J16)+SUMPRODUCT($D23,J23)+SUMPRODUCT($D30,J30)/$D37 -> 0.038 | K37: =SUMPRODUCT($D9,K9)+SUMPRODUCT($D16,K16)+SUMPRODUCT($D23,K23)+SUMPRODUCT($D30,K30)/$D37 -> 0.071265 | L37: =SUMPRODUCT($D9,L9)+SUMPRODUCT($D16,L16)+SUMPRODUCT($D23,L23)+SUMPRODUCT($D30,L30)/$D37 -> 0.11192 | M37: =SUMPRODUCT($D9,M9)+SUMPRODUCT($D16,M16)+SUMPRODUCT($D23,M23)+SUMPRODUCT($D30,M30)/$D37 -> 0.133535 | ... CT37: =SUMPRODUCT($D9,CT9)+SUMPRODUCT($D16,CT16)+SUMPRODUCT($D23,CT23)+SUMPRODUCT($D30,CT30)/$D37 -> 0.744551

Sheet S-Curves
C4: Zawtika 1F
C5: Jacket & Pile Detailed Design
D10: 6 | E10: 7 | F10: 8 | G10: 9 | H10: 10 | I10: 11 | J10: 12 | K10: 13 | L10: 14 | M10: 15 | N10: 16 | O10: 17 | P10: 18 | Q10: 19 | R10: 20 | S10: 21 | T10: 22 | U10: 23 | V10: 24 | W10: 25 | X10: 26 | Y10: 27 | Z10: 28 | AA10: 29 | AB10: 30 | AC10: 31 | AD10: 32 | AE10: 33 | AF10: 34 | AG10: 35 | AH10: 36 | AI10: 37 | AJ10: 38 | AK10: 39 | AL10: 40 | AM10: 41 | AN10: 42 | AO10: 43 | AP10: 44 | AQ10: 45 | AR10: 46 | AS10: 47 | AT10: 48 | AU10: 49 | AV10: 50 | AW10: 51 | AX10: 52 | AY10: 53 | AZ10: 54 | BA10: 55 | BB10: 56 | BC10: 57 | BD10: 58 | BE10: 59 | BF10: 60 | BG10: 61 | BH10: 62 | BI10: 63 | BJ10: 64 | BK10: 65 | BL10: 66 | BM10: 67 | BN10: 68 | BO10: 69 | BP10: 70 | BQ10: 71 | BR10: 72 | BS10: 73 | BT10: 74 | BU10: 75 | BV10: 76 | BW10: 77 | BX10: 78 | BY10: 79 | BZ10: 80 | CA10: 81 | CB10: 82 | CC10: 83 | CD10: 84 | CE10: 85 | CF10: 86 | CG10: 87 | CH10: 88 | CI10: 89 | CJ10: 90 | CK10: 91 | CL10: 92 | CM10: 93 | CN10: 94 | CO10: 95 | CP10: 96 | CQ10: 97 | CR10: 98
A11: Overall DDE Jacket | C11: Description | D11: 46101 | E11: 46108 | F11: 46115 | G11: 46122 | H11: 46129 | I11: 46136 | J11: 46143 | K11: 46150 | L11: 46157 | M11: 46164 | N11: 46171 | O11: 46178 | P11: 46185 | Q11: 46192 | R11: 46199 | S11: 46206 | T11: 46213 | U11: 46220 | V11: 46227 | W11: 46234 | X11: 46241 | Y11: 46248 | Z11: 46255 | AA11: 46262 | AB11: 46269 | AC11: 46276 | AD11: 46283 | AE11: 46290 | AF11: 46297 | AG11: 46304 | AH11: 46311 | AI11: 46318 | AJ11: 46325 | AK11: 46332 | AL11: 46339 | AM11: 46346 | AN11: 46353 | AO11: 46360 | AP11: 46367 | AQ11: 46374 | AR11: 46381 | AS11: 46388 | AT11: 46395 | AU11: 46402 | AV11: 46409 | AW11: 46416 | AX11: 46423 | AY11: 46430 | AZ11: 46437 | BA11: 46444 | BB11: 46451 | BC11: 46458 | BD11: 46465 | BE11: 46472 | BF11: 46479 | BG11: 46486 | BH11: 46493 | BI11: 46500 | BJ11: 46507 | BK11: 46514 | BL11: 46521 | BM11: 46528 | BN11: 46535 | BO11: 46542 | BP11: 46549 | BQ11: 46556 | BR11: 46563 | BS11: 46570 | BT11: 46577 | BU11: 46584 | BV11: 46591 | BW11: 46598 | BX11: 46605 | BY11: 46612 | BZ11: 46619 | CA11: 46626 | CB11: 46633 | CC11: 46640 | CD11: 46647 | CE11: 46654 | CF11: 46661 | CG11: 46668 | CH11: 46675 | CI11: 46682 | CJ11: 46689 | CK11: 46696 | CL11: 46703 | CM11: 46710 | CN11: 46717 | CO11: 46724 | CP11: 46731 | CQ11: 46738 | CR11: 46745
A12: =_xlfn.XLOOKUP(A11,Cut_Off!E:E,Cut_Off!F:F,0) -> 35 | C12: Cumulative Plan | D12: {=INDEX('Progress%'!$A$1:$CT$37,'S-Curves'!$A12,'S-Curves'!D$10)} -> 0 | E12: {=INDEX('Progress%'!$A$1:$CT$37,'S-Curves'!$A12,'S-Curves'!E$10)} -> 0 | F12: {=INDEX('Progress%'!$A$1:$CT$37,'S-Curves'!$A12,'S-Curves'!F$10)} -> 0.025 | G12: {=INDEX('Progress%'!$A$1:$CT$37,'S-Curves'!$A12,'S-Curves'!G$10)} -> 0.0355 | H12: {=INDEX('Progress%'!$A$1:$CT$37,'S-Curves'!$A12,'S-Curves'!H$10)} -> 0.0435 | I12: {=INDEX('Progress%'!$A$1:$CT$37,'S-Curves'!$A12,'S-Curves'!I$10)} -> 0.046 | J12: {=INDEX('Progress%'!$A$1:$CT$37,'S-Curves'!$A12,'S-Curves'!J$10)} -> 0.0655 | K12: {=INDEX('Progress%'!$A$1:$CT$37,'S-Curves'!$A12,'S-Curves'!K$10)} -> 0.080375 | ... CR12: {=INDEX('Progress%'!$A$1:$CT$37,'S-Curves'!$A12,'S-Curves'!CR$10)} -> 0.9
A13: =A12+1 -> 36 | C13: Cumulative Forecast | D13: {=INDEX('Progress%'!$A$1:$CT$37,'S-Curves'!$A13,'S-Curves'!D$10)} -> 0 | E13: {=INDEX('Progress%'!$A$1:$CT$37,'S-Curves'!$A13,'S-Curves'!E$10)} -> 0 | F13: {=INDEX('Progress%'!$A$1:$CT$37,'S-Curves'!$A13,'S-Curves'!F$10)} -> 0.025 | G13: {=INDEX('Progress%'!$A$1:$CT$37,'S-Curves'!$A13,'S-Curves'!G$10)} -> 0.0355 | H13: {=INDEX('Progress%'!$A$1:$CT$37,'S-Curves'!$A13,'S-Curves'!H$10)} -> 0.0435 | I13: {=INDEX('Progress%'!$A$1:$CT$37,'S-Curves'!$A13,'S-Curves'!I$10)} -> 0.046 | J13: {=INDEX('Progress%'!$A$1:$CT$37,'S-Curves'!$A13,'S-Curves'!J$10)} -> 0.0655 | K13: {=INDEX('Progress%'!$A$1:$CT$37,'S-Curves'!$A13,'S-Curves'!K$10)} -> 0.080375 | ... CR13: {=INDEX('Progress%'!$A$1:$CT$37,'S-Curves'!$A13,'S-Curves'!CR$10)} -> 0.9
A14: =A12+2 -> 37 | C14: Cumulative Actual | D14: {=INDEX('Progress%'!$A$1:$CT$37,'S-Curves'!$A14,'S-Curves'!D$10)} -> 0 | E14: {=INDEX('Progress%'!$A$1:$CT$37,'S-Curves'!$A14,'S-Curves'!E$10)} -> 0 | F14: {=INDEX('Progress%'!$A$1:$CT$37,'S-Curves'!$A14,'S-Curves'!F$10)} -> 0.028 | G14: {=INDEX('Progress%'!$A$1:$CT$37,'S-Curves'!$A14,'S-Curves'!G$10)} -> 0.038 | H14: {=INDEX('Progress%'!$A$1:$CT$37,'S-Curves'!$A14,'S-Curves'!H$10)} -> 0.038 | I14: {=INDEX('Progress%'!$A$1:$CT$37,'S-Curves'!$A14,'S-Curves'!I$10)} -> 0.071265 | J14: {=INDEX('Progress%'!$A$1:$CT$37,'S-Curves'!$A14,'S-Curves'!J$10)} -> 0.11192 | K14: {=INDEX('Progress%'!$A$1:$CT$37,'S-Curves'!$A14,'S-Curves'!K$10)} -> 0.133535 | ... AG14: {=INDEX('Progress%'!$A$1:$CT$37,'S-Curves'!$A14,'S-Curves'!AG$10)} -> 0.744551
C15: Period Plan (Early) | D15: =D12 -> 0 | E15: =E12-D12 -> 0 | F15: =F12-E12 -> 0.025 | G15: =G12-F12 -> 0.0105 | H15: =H12-G12 -> 0.008 | I15: =I12-H12 -> 0.0025 | J15: =J12-I12 -> 0.0195 | K15: =K12-J12 -> 0.014875 | L15: =L12-K12 -> 0.027 | ... CR15: =CR12-CQ12 -> 0
C16: Period Forecast | D16: =D13 -> 0 | E16: =E13-D13 -> 0 | F16: =F13-E13 -> 0.025 | G16: =G13-F13 -> 0.0105 | H16: =H13-G13 -> 0.008 | I16: =I13-H13 -> 0.0025 | J16: =J13-I13 -> 0.0195 | K16: =K13-J13 -> 0.014875 | L16: =L13-K13 -> 0.027 | ... CR16: =CR13-CQ13 -> 0
B17: Remaining Units | C17: Period Actual | D17: =D14 -> 0 | E17: =E14-D14 -> 0 | F17: =F14-E14 -> 0.028 | G17: =G14-F14 -> 0.01 | H17: =H14-G14 -> 0 | I17: =I14-H14 -> 0.033265 | J17: =J14-I14 -> 0.040655 | K17: =K14-J14 -> 0.021615 | L17: =L14-K14 -> 0.01386 | ... AG17: =AG14-AF14 -> 0.020741

Sheet EDSR
A1: Cut-off Date | C1: 46304
A2: EDSR - JACKET & PILES | J2: IFR (50%) | M2: IFA (20%) | P2: AFC Sub (10%) | S2: AFC App. (20%) | V2: AFC | X2: For Project control engineer follow up
A3: Facility | B3: Type | C3: Deliverable Title | D3: Description | E3: Plan [A] | F3: Forecast [B] | G3: Actual [C] | H3: Var. [C-A] | I3: Weight % | J3: Plan | K3: Forecast | L3: Actual | M3: Plan | N3: Forecast | O3: Actual | P3: Plan | Q3: Forecast | R3: Actual | S3: Plan | T3: Forecast | U3: Actual | V3: Status (AWC) | X3: IFR (50%) | Y3: IFA (20%) | Z3: AFC Sub (10%) | AA3: AFC App. (20%)
A4: ZWP-21 | B4: Report / Documents | C4: MM-ZTK-1F-GEN-STR-SPE-2001 | D4: SPECIFICATION FOR GROUT SEALS AND DIAPHRAGM | E4: =(COUNTIFS(J4,"<="&$C$1)*50%)+(COUNTIFS(M4,"<="&$C$1)*20%)+(COUNTIFS(P4,"<="&$C$1)*10%)+(COUNTIFS(S4,"<="&$C$1)*20%) -> 1 | F4: =(COUNTIFS(K4,"<="&$C$1)*50%)+(COUNTIFS(N4,"<="&$C$1)*20%)+(COUNTIFS(Q4,"<="&$C$1)*10%)+(COUNTIFS(T4,"<="&$C$1)*20%) -> 1 | G4: =(COUNTIFS(L4,"<="&$C$1)*50%)+(COUNTIFS(O4,"<="&$C$1)*20%)+(COUNTIFS(R4,"<="&$C$1)*10%)+(COUNTIFS(U4,"<="&$C$1)*20%) -> 1 | H4: =G4-E4 -> 0 | I4: 0.2 | J4: 46115 | K4: =J4 -> 46115 | L4: 46115 | M4: =J4+42 -> 46157 | N4: =M4 -> 46157 | O4: 46191 | P4: =M4+42 -> 46199 | Q4: =P4 -> 46199 | R4: 46219 | S4: =P4+14 -> 46213 | T4: =S4 -> 46213 | U4: 46262 | X4: =IF(OR(L4<>""),"Completed", IF(K4="","",IF(K4<TODAY(),"Overdue", IF(AND(K4>=TODAY()-WEEKDAY(TODAY(),2)+1,K4<=TODAY()-WEEKDAY(TODAY(),2)+7),"Follow-This Week", IF(AND(K4>=TODAY()-WEEKDAY(TODAY(),2)+8,K4<=TODAY()-WEEKDAY(TODAY(),2)+14),"Follow-Next Week",""))))) -> Completed | Y4: =IF(OR(O4<>""),"Completed",IF(N4="","", IF(N4<TODAY(),"Overdue", IF(AND(N4>=TODAY()-WEEKDAY(TODAY(),2)+1,N4<=TODAY()-WEEKDAY(TODAY(),2)+7),"Follow-This Week", IF(AND(N4>=TODAY()-WEEKDAY(TODAY(),2)+8,N4<=TODAY()-WEEKDAY(TODAY(),2)+14),"Follow-Next Week",""))))) -> Completed | Z4: =IF(OR(R4<>""),"Completed",IF(Q4="","", IF(Q4<TODAY(),"Overdue", IF(AND(Q4>=TODAY()-WEEKDAY(TODAY(),2)+1,Q4<=TODAY()-WEEKDAY(TODAY(),2)+7),"Follow-This Week", IF(AND(Q4>=TODAY()-WEEKDAY(TODAY(),2)+8,Q4<=TODAY()-WEEKDAY(TODAY(),2)+14),"Follow-Next Week",""))))) -> Completed | AA4: =IF(OR(U4<>""),"Completed",IF(T4="","", IF(T4<TODAY(),"Overdue", IF(AND(T4>=TODAY()-WEEKDAY(TODAY(),2)+1,T4<=TODAY()-WEEKDAY(TODAY(),2)+7),"Follow-This Week", IF(AND(T4>=TODAY()-WEEKDAY(TODAY(),2)+8,T4<=TODAY()-WEEKDAY(TODAY(),2)+14),"Follow-Next Week",""))))) -> Completed
A5: ZWP-21 | B5: Report / Documents | C5: MM-ZTK-1F-GEN-STR-SPE-2002 | D5: SPECIFICATION FOR STAINLESS STEEL BUNDLES | E5: =(COUNTIFS(J5,"<="&$C$1)*50%)+(COUNTIFS(M5,"<="&$C$1)*20%)+(COUNTIFS(P5,"<="&$C$1)*10%)+(COUNTIFS(S5,"<="&$C$1)*20%) -> 1 | F5: =(COUNTIFS(K5,"<="&$C$1)*50%)+(COUNTIFS(N5,"<="&$C$1)*20%)+(COUNTIFS(Q5,"<="&$C$1)*10%)+(COUNTIFS(T5,"<="&$C$1)*20%) -> 1 | G5: =(COUNTIFS(L5,"<="&$C$1)*50%)+(COUNTIFS(O5,"<="&$C$1)*20%)+(COUNTIFS(R5,"<="&$C$1)*10%)+(COUNTIFS(U5,"<="&$C$1)*20%) -> 1 | H5: =G5-E5 -> 0 | I5: 0.2 | J5: 46115 | K5: =J5 -> 46115 | L5: 46115 | M5: =J5+42 -> 46157 | N5: =M5 -> 46157 | O5: 46171 | P5: =M5+42 -> 46199 | Q5: =P5 -> 46199 | R5: 46199 | S5: =P5+14 -> 46213 | T5: =S5 -> 46213 | U5: 46204 | X5: =IF(OR(L5<>""),"Completed", IF(K5="","",IF(K5<TODAY(),"Overdue", IF(AND(K5>=TODAY()-WEEKDAY(TODAY(),2)+1,K5<=TODAY()-WEEKDAY(TODAY(),2)+7),"Follow-This Week", IF(AND(K5>=TODAY()-WEEKDAY(TODAY(),2)+8,K5<=TODAY()-WEEKDAY(TODAY(),2)+14),"Follow-Next Week",""))))) -> Completed | Y5: =IF(OR(O5<>""),"Completed",IF(N5="","", IF(N5<TODAY(),"Overdue", IF(AND(N5>=TODAY()-WEEKDAY(TODAY(),2)+1,N5<=TODAY()-WEEKDAY(TODAY(),2)+7),"Follow-This Week", IF(AND(N5>=TODAY()-WEEKDAY(TODAY(),2)+8,N5<=TODAY()-WEEKDAY(TODAY(),2)+14),"Follow-Next Week",""))))) -> Completed | Z5: =IF(OR(R5<>""),"Completed",IF(Q5="","", IF(Q5<TODAY(),"Overdue", IF(AND(Q5>=TODAY()-WEEKDAY(TODAY(),2)+1,Q5<=TODAY()-WEEKDAY(TODAY(),2)+7),"Follow-This Week", IF(AND(Q5>=TODAY()-WEEKDAY(TODAY(),2)+8,Q5<=TODAY()-WEEKDAY(TODAY(),2)+14),"Follow-Next Week",""))))) -> Completed | AA5: =IF(OR(U5<>""),"Completed",IF(T5="","", IF(T5<TODAY(),"Overdue", IF(AND(T5>=TODAY()-WEEKDAY(TODAY(),2)+1,T5<=TODAY()-WEEKDAY(TODAY(),2)+7),"Follow-This Week", IF(AND(T5>=TODAY()-WEEKDAY(TODAY(),2)+8,T5<=TODAY()-WEEKDAY(TODAY(),2)+14),"Follow-Next Week",""))))) -> Completed
A6: ZWP-21 | B6: Report / Documents | C6: MM-ZTK-1F-GEN-STR-SPE-2003 | D6: SPECIFICATIONS FOR GRIPPER PERFORMANCE | E6: =(COUNTIFS(J6,"<="&$C$1)*50%)+(COUNTIFS(M6,"<="&$C$1)*20%)+(COUNTIFS(P6,"<="&$C$1)*10%)+(COUNTIFS(S6,"<="&$C$1)*20%) -> 1 | F6: =(COUNTIFS(K6,"<="&$C$1)*50%)+(COUNTIFS(N6,"<="&$C$1)*20%)+(COUNTIFS(Q6,"<="&$C$1)*10%)+(COUNTIFS(T6,"<="&$C$1)*20%) -> 1 | G6: =(COUNTIFS(L6,"<="&$C$1)*50%)+(COUNTIFS(O6,"<="&$C$1)*20%)+(COUNTIFS(R6,"<="&$C$1)*10%)+(COUNTIFS(U6,"<="&$C$1)*20%) -> 1 | H6: =G6-E6 -> 0 | I6: 0.2 | J6: 46115 | K6: =J6 -> 46115 | L6: 46115 | M6: =J6+42 -> 46157 | N6: =M6 -> 46157 | O6: 46171 | P6: =M6+42 -> 46199 | Q6: =P6 -> 46199 | R6: 46219 | S6: =P6+14 -> 46213 | T6: =S6 -> 46213 | U6: 46233 | X6: =IF(OR(L6<>""),"Completed", IF(K6="","",IF(K6<TODAY(),"Overdue", IF(AND(K6>=TODAY()-WEEKDAY(TODAY(),2)+1,K6<=TODAY()-WEEKDAY(TODAY(),2)+7),"Follow-This Week", IF(AND(K6>=TODAY()-WEEKDAY(TODAY(),2)+8,K6<=TODAY()-WEEKDAY(TODAY(),2)+14),"Follow-Next Week",""))))) -> Completed | Y6: =IF(OR(O6<>""),"Completed",IF(N6="","", IF(N6<TODAY(),"Overdue", IF(AND(N6>=TODAY()-WEEKDAY(TODAY(),2)+1,N6<=TODAY()-WEEKDAY(TODAY(),2)+7),"Follow-This Week", IF(AND(N6>=TODAY()-WEEKDAY(TODAY(),2)+8,N6<=TODAY()-WEEKDAY(TODAY(),2)+14),"Follow-Next Week",""))))) -> Completed | Z6: =IF(OR(R6<>""),"Completed",IF(Q6="","", IF(Q6<TODAY(),"Overdue", IF(AND(Q6>=TODAY()-WEEKDAY(TODAY(),2)+1,Q6<=TODAY()-WEEKDAY(TODAY(),2)+7),"Follow-This Week", IF(AND(Q6>=TODAY()-WEEKDAY(TODAY(),2)+8,Q6<=TODAY()-WEEKDAY(TODAY(),2)+14),"Follow-Next Week",""))))) -> Completed | AA6: =IF(OR(U6<>""),"Completed",IF(T6="","", IF(T6<TODAY(),"Overdue", IF(AND(T6>=TODAY()-WEEKDAY(TODAY(),2)+1,T6<=TODAY()-WEEKDAY(TODAY(),2)+7),"Follow-This Week", IF(AND(T6>=TODAY()-WEEKDAY(TODAY(),2)+8,T6<=TODAY()-WEEKDAY(TODAY(),2)+14),"Follow-Next Week",""))))) -> Completed
A7: ZWP-21 | B7: Report / Documents | C7: MM-ZTK-1F-GEN-STR-SPE-2004 | D7: SPECIFICATION FOR GROUTING AND INSTALLATION | E7: =(COUNTIFS(J7,"<="&$C$1)*50%)+(COUNTIFS(M7,"<="&$C$1)*20%)+(COUNTIFS(P7,"<="&$C$1)*10%)+(COUNTIFS(S7,"<="&$C$1)*20%) -> 1 | F7: =(COUNTIFS(K7,"<="&$C$1)*50%)+(COUNTIFS(N7,"<="&$C$1)*20%)+(COUNTIFS(Q7,"<="&$C$1)*10%)+(COUNTIFS(T7,"<="&$C$1)*20%) -> 1 | G7: =(COUNTIFS(L7,"<="&$C$1)*50%)+(COUNTIFS(O7,"<="&$C$1)*20%)+(COUNTIFS(R7,"<="&$C$1)*10%)+(COUNTIFS(U7,"<="&$C$1)*20%) -> 1 | H7: =G7-E7 -> 0 | I7: 0.2 | J7: 46115 | K7: =J7 -> 46115 | L7: 46115 | M7: =J7+42 -> 46157 | N7: =M7 -> 46157 | O7: 46171 | P7: =M7+42 -> 46199 | Q7: =P7 -> 46199 | R7: 46274 | S7: =P7+14 -> 46213 | T7: =S7 -> 46213 | U7: 46288 | X7: =IF(OR(L7<>""),"Completed", IF(K7="","",IF(K7<TODAY(),"Overdue", IF(AND(K7>=TODAY()-WEEKDAY(TODAY(),2)+1,K7<=TODAY()-WEEKDAY(TODAY(),2)+7),"Follow-This Week", IF(AND(K7>=TODAY()-WEEKDAY(TODAY(),2)+8,K7<=TODAY()-WEEKDAY(TODAY(),2)+14),"Follow-Next Week",""))))) -> Completed | Y7: =IF(OR(O7<>""),"Completed",IF(N7="","", IF(N7<TODAY(),"Overdue", IF(AND(N7>=TODAY()-WEEKDAY(TODAY(),2)+1,N7<=TODAY()-WEEKDAY(TODAY(),2)+7),"Follow-This Week", IF(AND(N7>=TODAY()-WEEKDAY(TODAY(),2)+8,N7<=TODAY()-WEEKDAY(TODAY(),2)+14),"Follow-Next Week",""))))) -> Completed | Z7: =IF(OR(R7<>""),"Completed",IF(Q7="","", IF(Q7<TODAY(),"Overdue", IF(AND(Q7>=TODAY()-WEEKDAY(TODAY(),2)+1,Q7<=TODAY()-WEEKDAY(TODAY(),2)+7),"Follow-This Week", IF(AND(Q7>=TODAY()-WEEKDAY(TODAY(),2)+8,Q7<=TODAY()-WEEKDAY(TODAY(),2)+14),"Follow-Next Week",""))))) -> Completed | AA7: =IF(OR(U7<>""),"Completed",IF(T7="","", IF(T7<TODAY(),"Overdue", IF(AND(T7>=TODAY()-WEEKDAY(TODAY(),2)+1,T7<=TODAY()-WEEKDAY(TODAY(),2)+7),"Follow-This Week", IF(AND(T7>=TODAY()-WEEKDAY(TODAY(),2)+8,T7<=TODAY()-WEEKDAY(TODAY(),2)+14),"Follow-Next Week",""))))) -> Completed
